Workbook

Sheet Dashboard
B1: FIRST ATLANTIC BANK LIMITED
B4: All amounts in thousands of GHS unless stated otherwise
B6: Recommendations
B8: Weighted Average | D8: Multiples Approach | H8: Dividend Discount Model Approach | L8: Residual Income Valuation Approach
B9: =IF($B$16<=-15%,"SELL",IF($B$16<=15%,"HOLD","BUY")) -> BUY | D9: =IF($F$16<=-15%,"SELL",IF($F$16<=15%,"HOLD","BUY")) -> BUY | H9: =IF($J$16<=-15%,"SELL",IF($J$16<=15%,"HOLD","BUY")) -> BUY | L9: =IF($N$16<=-15%,"SELL",IF($N$16<=15%,"HOLD","BUY")) -> BUY
B13: Valuation
B15: =Valuation!G88&" (GHS)" -> Weighted Price (GHS) | D15: =Valuation!B29&" (GHS)" -> Comparable Company Analysis (GHS) | H15: =Valuation!B56&" (GHS)" -> Dividend Discount Model (GHS) | L15: =Valuation!B71&" (GHS)" -> Residual Income Valuation (GHS)
B16: =Valuation!G93 -> 2.2779827 | F16: =Valuation!$F$89/Valuation!$D$10-1 -> 0.78270731 | J16: =Valuation!D68 -> 0.88857877 | N16: =Valuation!D84 -> 4.9641757
B24: Financial Highlights
F25: Income Statement | H25: =I25-1 -> 2024 | I25: =YEAR(Valuation!AB4) -> 2025 | J25: =YEAR(Valuation!AC4) -> 2026 | K25: =YEAR(Valuation!AD4) -> 2027 | L25: =YEAR(Valuation!AE4) -> 2028 | M25: =YEAR(Valuation!AF4) -> 2029 | N25: =YEAR(Valuation!AG4) -> 2030
F26: Net Interest Income | H26: ='Quarterly Historical Financials'!AI11 -> 576088 | I26: ='Quarterly Historical Financials'!AJ11+'Quarterly Financial Projections'!F10 -> 1542039.1 | J26: ='Quarterly Financial Projections'!AC10 -> 1209362.7 | K26: ='Quarterly Financial Projections'!AD10 -> 1470586.6 | L26: ='Quarterly Financial Projections'!AE10 -> 1779440.5 | M26: ='Quarterly Financial Projections'!AF10 -> 2144024.6 | N26: ='Quarterly Financial Projections'!AG10 -> 2573822.2
F27: Net Fees and Commission Income | H27: ='Quarterly Historical Financials'!AI14 -> 180198 | I27: ='Quarterly Historical Financials'!AJ14+'Quarterly Financial Projections'!F13 -> 223370.3 | J27: ='Quarterly Financial Projections'!AC13 -> 215487.73 | K27: ='Quarterly Financial Projections'!AD13 -> 245172.87 | L27: ='Quarterly Financial Projections'!AE13 -> 282278.94 | M27: ='Quarterly Financial Projections'!AF13 -> 325000.88 | N27: ='Quarterly Financial Projections'!AG13 -> 374188.64
F28: Net trading income | H28: ='Quarterly Historical Financials'!AI15 -> 335653 | I28: ='Quarterly Historical Financials'!AJ15+'Quarterly Financial Projections'!F14 -> 207164.61 | J28: ='Quarterly Financial Projections'!AC14 -> 94249.439 | K28: ='Quarterly Financial Projections'!AD14 -> 108513.77 | L28: ='Quarterly Financial Projections'!AE14 -> 124936.95 | M28: ='Quarterly Financial Projections'!AF14 -> 143845.73 | N28: ='Quarterly Financial Projections'!AG14 -> 165616.28
F29: Other income | H29: ='Quarterly Historical Financials'!AI16+'Quarterly Historical Financials'!AI26 -> 1240 | I29: ='Quarterly Historical Financials'!AJ16+'Quarterly Financial Projections'!F15+'Quarterly Historical Financials'!AJ26+'Quarterly Financial Projections'!F23 -> 4476.008 | J29: ='Quarterly Financial Projections'!AC15 -> 1758.4746 | K29: ='Quarterly Financial Projections'!AD15 -> 2088.663 | L29: ='Quarterly Financial Projections'!AE15 -> 2479.2579 | M29: ='Quarterly Financial Projections'!AF15 -> 2936.725 | N29: ='Quarterly Financial Projections'!AG15 -> 3472.0905
F30: Operating Income | H30: =SUM(H26:H29) -> 1093179 | I30: =SUM(I26:I29) -> 1977050 | J30: =SUM(J26:J29) -> 1520858.4 | K30: =SUM(K26:K29) -> 1826361.9 | L30: =SUM(L26:L29) -> 2189135.7 | M30: =SUM(M26:M29) -> 2615807.9 | N30: =SUM(N26:N29) -> 3117099.2
F31: Total Operating Expenses | H31: ='Quarterly Historical Financials'!AI25 -> -553877 | I31: ='Quarterly Historical Financials'!AJ25+'Quarterly Financial Projections'!F22 -> -942766.1 | J31: ='Quarterly Financial Projections'!AC22 -> -634559.42 | K31: ='Quarterly Financial Projections'!AD22 -> -764813.95 | L31: ='Quarterly Financial Projections'!AE22 -> -905564.61 | M31: ='Quarterly Financial Projections'!AF22 -> -1071996.2 | N31: ='Quarterly Financial Projections'!AG22 -> -1269078.9
F32: Profit before income tax | H32: =SUM(H30:H31) -> 539302 | I32: =SUM(I30:I31) -> 1034283.9 | J32: =SUM(J30:J31) -> 886298.96 | K32: =SUM(K30:K31) -> 1061547.9 | L32: =SUM(L30:L31) -> 1283571.1 | M32: =SUM(M30:M31) -> 1543811.7 | N32: =SUM(N30:N31) -> 1848020.3
F33: Total Taxes | H33: =SUM('Quarterly Historical Financials'!AI28:AI31) -> -202623 | I33: =SUM('Quarterly Historical Financials'!AJ28:AJ31)+'Quarterly Financial Projections'!F25 -> -321301.78 | J33: ='Quarterly Financial Projections'!AC25 -> -183038.96 | K33: ='Quarterly Financial Projections'!AD25 -> -219231.47 | L33: ='Quarterly Financial Projections'!AE25 -> -265083.81 | M33: ='Quarterly Financial Projections'!AF25 -> -318828.85 | N33: ='Quarterly Financial Projections'!AG25 -> -381654.19
F34: Profit for the period | H34: =SUM(H32:H33) -> 336679 | I34: =SUM(I32:I33) -> 712982.13 | J34: =SUM(J32:J33) -> 703260 | K34: =SUM(K32:K33) -> 842316.45 | L34: =SUM(L32:L33) -> 1018487.2 | M34: =SUM(M32:M33) -> 1224982.8 | N34: =SUM(N32:N33) -> 1466366.1
F35: Shares Outstanding | H35: ='Quarterly Historical Financials'!AI34 -> 334173.89 | I35: ='Quarterly Historical Financials'!AJ34 -> 349617.46 | J35: ='Quarterly Financial Projections'!AC28 -> 349617.46 | K35: ='Quarterly Financial Projections'!AD28 -> 349617.46 | L35: ='Quarterly Financial Projections'!AE28 -> 349617.46 | M35: ='Quarterly Financial Projections'!AF28 -> 349617.46 | N35: ='Quarterly Financial Projections'!AG28 -> 349617.46
F36: EPS | H36: =H34/H35 -> 1.0074964 | I36: =I34/I35 -> 2.0393207 | J36: =J34/J35 -> 2.0115128 | K36: =K34/K35 -> 2.4092517 | L36: =L34/L35 -> 2.9131475 | M36: =M34/M35 -> 3.5037804 | N36: =N34/N35 -> 4.1942016
F38: Operating Income Growth Rate | H38: =H30/'Quarterly Historical Financials'!AH17-1 -> 0.04607928 | I38: =I30/H30-1 -> 0.80853273 | J38: =J30/I30-1 -> -0.2307436 | K38: =K30/J30-1 -> 0.2008757 | L38: =L30/K30-1 -> 0.19863194 | M38: =M30/L30-1 -> 0.19490443 | N38: =N30/M30-1 -> 0.1916392
F39: Cost-to-Income Ratio | H39: =-H31/H30 -> 0.50666634 | I39: =-I31/I30 -> 0.47685496 | J39: =-J31/J30 -> 0.41723768 | K39: =-K31/K30 -> 0.41876364 | L39: =-L31/L30 -> 0.41366308 | M39: =-M31/M30 -> 0.40981458 | N39: =-N31/N30 -> 0.40713459
F40: Profit Margin | H40: =H34/H30 -> 0.30798158 | I40: =I34/I30 -> 0.36062928 | J40: =J34/J30 -> 0.46240992 | K40: =K34/K30 -> 0.4611991 | L40: =L34/L30 -> 0.46524629 | M40: =M34/M30 -> 0.46829999 | N40: =N34/N30 -> 0.47042651
F64: Statement of Financial Position | H64: =H25 -> 2024 | I64: =I25 -> 2025 | J64: =J25 -> 2026 | K64: =K25 -> 2027 | L64: =L25 -> 2028 | M64: =M25 -> 2029 | N64: =N25 -> 2030
F65: Cash and cash equivalents | H65: ='Quarterly Historical Financials'!AI41 -> 4600045 | I65: ='Quarterly Financial Projections'!AB33 -> 8162460.5 | J65: ='Quarterly Financial Projections'!AC33 -> 8156889.4 | K65: ='Quarterly Financial Projections'!AD33 -> 10125376 | L65: ='Quarterly Financial Projections'!AE33 -> 12467879 | M65: ='Quarterly Financial Projections'!AF33 -> 15249551 | N65: ='Quarterly Financial Projections'!AG33 -> 18546972
F66: Trading assets (Investment securities) | H66: ='Quarterly Historical Financials'!AI43 -> 2647258 | I66: ='Quarterly Financial Projections'!AB34 -> 3178870.4 | J66: ='Quarterly Financial Projections'!AC34 -> 4541640.6 | K66: ='Quarterly Financial Projections'!AD34 -> 5229002.2 | L66: ='Quarterly Financial Projections'!AE34 -> 6020393.7 | M66: ='Quarterly Financial Projections'!AF34 -> 6931559.6 | N66: ='Quarterly Financial Projections'!AG34 -> 7980627.2
F67: Loans and advances to customers | H67: ='Quarterly Historical Financials'!AI44 -> 1927368 | I67: ='Quarterly Financial Projections'!AB35 -> 1947024.8 | J67: ='Quarterly Financial Projections'!AC35 -> 3263912.3 | K67: ='Quarterly Financial Projections'!AD35 -> 3757894.1 | L67: ='Quarterly Financial Projections'!AE35 -> 4326638.5 | M67: ='Quarterly Financial Projections'!AF35 -> 4981460.3 | N67: ='Quarterly Financial Projections'!AG35 -> 5735387.1
F68: Other assets | H68: =SUM('Quarterly Historical Financials'!AI45:AI55) -> 4148654 | I68: =SUM('Quarterly Financial Projections'!AB36:AB44) -> 5904635.8 | J68: =SUM('Quarterly Financial Projections'!AC36:AC44) -> 6299904.1 | K68: =SUM('Quarterly Financial Projections'!AD36:AD44) -> 6725854.9 | L68: =SUM('Quarterly Financial Projections'!AE36:AE44) -> 7184882.8 | M68: =SUM('Quarterly Financial Projections'!AF36:AF44) -> 7679569.6 | N68: =SUM('Quarterly Financial Projections'!AG36:AG44) -> 8212699
F69: Total Assets | H69: =SUM(H65:H68) -> 13323325 | I69: =SUM(I65:I68) -> 19192992 | J69: =SUM(J65:J68) -> 22262346 | K69: =SUM(K65:K68) -> 25838127 | L69: =SUM(L65:L68) -> 29999794 | M69: =SUM(M65:M68) -> 34842141 | N69: =SUM(N65:N68) -> 40475685
F71: Total Deposits | H71: ='Quarterly Historical Financials'!AI59+'Quarterly Historical Financials'!AI60 -> 11611039 | I71: ='Quarterly Financial Projections'!AB48 -> 16642450 | J71: ='Quarterly Financial Projections'!AC48 -> 19161227 | K71: ='Quarterly Financial Projections'!AD48 -> 22061213 | L71: ='Quarterly Financial Projections'!AE48 -> 25400101 | M71: ='Quarterly Financial Projections'!AF48 -> 29244319 | N71: ='Quarterly Financial Projections'!AG48 -> 33670346
F72: Other liabilities | H72: =SUM('Quarterly Historical Financials'!AI61:AI64) -> 91644 | I72: =SUM('Quarterly Financial Projections'!AB49:AB51) -> 303306.12 | J72: =SUM('Quarterly Financial Projections'!AC49:AC51) -> 320819.02 | K72: =SUM('Quarterly Financial Projections'!AD49:AD51) -> 352380.3 | L72: =SUM('Quarterly Financial Projections'!AE49:AE51) -> 390686.15 | M72: =SUM('Quarterly Financial Projections'!AF49:AF51) -> 437177.86 | N72: =SUM('Quarterly Financial Projections'!AG49:AG51) -> 493604.73
F73: Lease liabilities | H73: ='Quarterly Historical Financials'!AI65 -> 23808 | I73: ='Quarterly Financial Projections'!AB52 -> 38841.151 | J73: ='Quarterly Financial Projections'!AC52 -> 55757.328 | K73: ='Quarterly Financial Projections'!AD52 -> 80040.874 | L73: ='Quarterly Financial Projections'!AE52 -> 114900.44 | M73: ='Quarterly Financial Projections'!AF52 -> 164942.11 | N73: ='Quarterly Financial Projections'!AG52 -> 236778.04
F74: Total Liabilities | H74: =SUM(H71:H73) -> 11726491 | I74: =SUM(I71:I73) -> 16984597 | J74: =SUM(J71:J73) -> 19537803 | K74: =SUM(K71:K73) -> 22493634 | L74: =SUM(L71:L73) -> 25905688 | M74: =SUM(M71:M73) -> 29846439 | N74: =SUM(N71:N73) -> 34400729
F76: Stated capital | H76: ='Quarterly Historical Financials'!AI69 -> 404570 | I76: ='Quarterly Financial Projections'!AB56 -> 727506.62 | J76: ='Quarterly Financial Projections'!AC56 -> 726051.15 | K76: ='Quarterly Financial Projections'!AD56 -> 726051.15 | L76: ='Quarterly Financial Projections'!AE56 -> 726051.15 | M76: ='Quarterly Financial Projections'!AF56 -> 726051.15 | N76: ='Quarterly Financial Projections'!AG56 -> 726051.15
F77: Retained earnings | H77: ='Quarterly Historical Financials'!AI70 -> 291090 | I77: ='Quarterly Financial Projections'!AB57 -> 454973.95 | J77: ='Quarterly Financial Projections'!AC57 -> 972577.78 | K77: ='Quarterly Financial Projections'!AD57 -> 1592528.1 | L77: ='Quarterly Financial Projections'!AE57 -> 2342141.1 | M77: ='Quarterly Financial Projections'!AF57 -> 3243736.3 | N77: ='Quarterly Financial Projections'!AG57 -> 4322991.1
F78: Reserves | H78: =SUM('Quarterly Historical Financials'!AI71:AI75) -> 901174 | I78: =SUM('Quarterly Financial Projections'!AB58:AB61) -> 1025914.1 | J78: =SUM('Quarterly Financial Projections'!AC58:AC61) -> 1025914.1 | K78: =SUM('Quarterly Financial Projections'!AD58:AD61) -> 1025914.1 | L78: =SUM('Quarterly Financial Projections'!AE58:AE61) -> 1025914.1 | M78: =SUM('Quarterly Financial Projections'!AF58:AF61) -> 1025914.1 | N78: =SUM('Quarterly Financial Projections'!AG58:AG61) -> 1025914.1
F79: Total Equity | H79: =SUM(H76:H78) -> 1596834 | I79: =SUM(I76:I78) -> 2208394.7 | J79: =SUM(J76:J78) -> 2724543 | K79: =SUM(K76:K78) -> 3344493.3 | L79: =SUM(L76:L78) -> 4094106.4 | M79: =SUM(M76:M78) -> 4995701.5 | N79: =SUM(N76:N78) -> 6074956.3
F81: Total Equity and Liabilities | H81: =H74+H79 -> 13323325 | I81: =I74+I79 -> 19192992 | J81: =J74+J79 -> 22262346 | K81: =K74+K79 -> 25838127 | L81: =L74+L79 -> 29999794 | M81: =M74+M79 -> 34842141 | N81: =N74+N79 -> 40475685
F82: Check | H82: =H69-H81 -> 0 | I82: =I69-I81 -> -0.001000002 | J82: =J69-J81 -> 0 | K82: =K69-K81 -> 0 | L82: =L69-L81 -> 0 | M82: =M69-M81 -> 0 | N82: =N69-N81 -> 0
...

Sheet Valuation
B1: FIRST ATLANTIC BANK LIMITED
D2: Year | E2: =YEAR(E4) -> 2025 | F2: =YEAR(F4) -> 2025 | G2: =YEAR(G4) -> 2026 | H2: =YEAR(H4) -> 2026 | I2: =YEAR(I4) -> 2026 | J2: =YEAR(J4) -> 2026 | K2: =YEAR(K4) -> 2027 | L2: =YEAR(L4) -> 2027 | ... Z2: =YEAR(Z4) -> 2030 | AB2: =YEAR(AB4) -> 2025 | AC2: =YEAR(AC4) -> 2026 | AD2: =YEAR(AD4) -> 2027 | AE2: =YEAR(AE4) -> 2028 | AF2: =YEAR(AF4) -> 2029 | AG2: =YEAR(AG4) -> 2030
D3: Start Date | E3: ='Quarterly Historical Financials'!AB3 -> 45839 | F3: =E4+1 -> 45931 | G3: =F4+1 -> 46023 | H3: =G4+1 -> 46113 | I3: =H4+1 -> 46204 | J3: =I4+1 -> 46296 | K3: =J4+1 -> 46388 | L3: =K4+1 -> 46478 | M3: =L4+1 -> 46569 | ... Z3: =Y4+1 -> 47757 | AB3: =F3 -> 45931 | AC3: =AB4+1 -> 46023 | AD3: =AC4+1 -> 46388 | AE3: =AD4+1 -> 46753 | AF3: =AE4+1 -> 47119 | AG3: =AF4+1 -> 47484
D4: End Date | E4: =EOMONTH(E3,2) -> 45930 | F4: =EOMONTH(F3,2) -> 46022 | G4: =EOMONTH(G3,2) -> 46112 | H4: =EOMONTH(H3,2) -> 46203 | I4: =EOMONTH(I3,2) -> 46295 | J4: =EOMONTH(J3,2) -> 46387 | K4: =EOMONTH(K3,2) -> 46477 | L4: =EOMONTH(L3,2) -> 46568 | ... Z4: =EOMONTH(Z3,2) -> 47848 | AB4: =EOMONTH(AB3,2) -> 46022 | AC4: =EOMONTH(AC3,11) -> 46387 | AD4: =EOMONTH(AD3,11) -> 46752 | AE4: =EOMONTH(AE3,11) -> 47118 | AF4: =EOMONTH(AF3,11) -> 47483 | AG4: =EOMONTH(AG3,11) -> 47848
B5: All amounts in thousands of GHS unless stated otherwise | D5: Period | E5: =E4-E3+1 -> 92 | F5: =F4-F3+1 -> 92 | G5: =G4-G3+1 -> 90 | H5: =H4-H3+1 -> 91 | I5: =I4-I3+1 -> 92 | J5: =J4-J3+1 -> 92 | K5: =K4-K3+1 -> 90 | L5: =L4-L3+1 -> 91 | ... Z5: =Z4-Z3+1 -> 92 | AB5: =AB4-AB3+1 -> 92 | AC5: =AC4-AC3+1 -> 365 | AD5: =AD4-AD3+1 -> 365 | AE5: =AE4-AE3+1 -> 366 | AF5: =AF4-AF3+1 -> 365 | AG5: =AG4-AG3+1 -> 365
B7: Cost of Equity Calculation
B9: Date
B10: Current Share Price (GHS) | D10: =Comps!C61 -> 7.97
B11: Shares Outstanding | D11: ='Quarterly Financial Projections'!$F$28 -> 349617.46
B12: Market Capitalisation | D12: =D10*D11 -> 2786451.2
B14: Risk-free Rate | D14: 0.152
B15: Unlevered Beta | D15: 0.45
B16: Debt-to-Equity Ratio | D16: 0
B17: Levered Beta | D17: =D15*(1+((1+Assumptions!$I$115)*Valuation!D16)) -> 0.45
B18: Market Risk Premium | D18: 0.2665
B19: Country Risk Premium | D19: 0.0892
B20: Cost of Equity | D20: =D14+(D17*D18)+D19 -> 0.361125
B21: Quarterlized Cost of Equity | D21: =(1+D20)^(1/4)-1 -> 0.080126205
B24: Yearfrac | G24: =YEARFRAC(F4,G4) -> 0.25 | H24: =YEARFRAC(G4,H4) -> 0.25 | I24: =YEARFRAC(H4,I4) -> 0.25 | J24: =YEARFRAC(I4,J4) -> 0.25 | K24: =YEARFRAC(J4,K4) -> 0.25 | L24: =YEARFRAC(K4,L4) -> 0.25 | M24: =YEARFRAC(L4,M4) -> 0.25 | N24: =YEARFRAC(M4,N4) -> 0.25 | ... Z24: =YEARFRAC(Y4,Z4) -> 0.25 | AB24: =YEARFRAC(AB3,AB4) -> 0.25 | AC24: =YEARFRAC(AB4,AC4) -> 1 | AD24: =YEARFRAC(AC4,AD4) -> 1 | AE24: =YEARFRAC(AD4,AE4) -> 1 | AF24: =YEARFRAC(AE4,AF4) -> 1 | AG24: =YEARFRAC(AF4,AG4) -> 1
B25: Year | G25: =F25+G24 -> 0.25 | H25: =G25+H24 -> 0.5 | I25: =H25+I24 -> 0.75 | J25: =I25+J24 -> 1 | K25: =J25+K24 -> 1.25 | L25: =K25+L24 -> 1.5 | M25: =L25+M24 -> 1.75 | N25: =M25+N24 -> 2 | ... Z25: =Y25+Z24 -> 5 | AB25: =AB24 -> 0.25 | AC25: =AB25+AC24 -> 1.25 | AD25: =AC25+AD24 -> 2.25 | AE25: =AD25+AE24 -> 3.25 | AF25: =AE25+AF24 -> 4.25 | AG25: =AF25+AG24 -> 5.25
B26: Discount Factor | G26: =1/((1+$D$21)^(G25)) -> 0.980915 | H26: =1/((1+$D$21)^(H25)) -> 0.96219423 | I26: =1/((1+$D$21)^(I25)) -> 0.94383075 | J26: =1/((1+$D$21)^(J25)) -> 0.92581774 | K26: =1/((1+$D$21)^(K25)) -> 0.9081485 | L26: =1/((1+$D$21)^(L25)) -> 0.89081649 | M26: =1/((1+$D$21)^(M25)) -> 0.87381525 | N26: =1/((1+$D$21)^(N25)) -> 0.85713848 | ... Z26: =1/((1+$D$21)^(Z25)) -> 0.68018568 | AB26: =1/((1+$D$21)^(AB25)) -> 0.980915 | AC26: =1/((1+$D$21)^(AC25)) -> 0.9081485 | AD26: =1/((1+$D$21)^(AD25)) -> 0.84077999 | AE26: =1/((1+$D$21)^(AE25)) -> 0.77840903 | AF26: =1/((1+$D$21)^(AF25)) -> 0.72066489 | AG26: =1/((1+$D$21)^(AG25)) -> 0.66720434
B29: Comparable Company Analysis
B30: Industry Multiples | D30: AVG
B31: P/E | D31: =SUMIF(Comps!$C$15:$C$18,Valuation!$D$30,Comps!$AG$15:$AG$18) -> 8.8546999
B32: P/D | D32: =SUMIF(Comps!$C$15:$C$18,Valuation!$D$30,Comps!$AK$15:$AK$18) -> 0.28106015
B33: P/B | D33: =SUMIF(Comps!$C$15:$C$18,Valuation!$D$30,Comps!$AM$15:$AM$18) -> 1.712748
B35: Net Profit | F35: ='Quarterly Financial Projections'!F26 -> 230111.06 | G35: ='Quarterly Financial Projections'!G26 -> 171189.53 | H35: ='Quarterly Financial Projections'!H26 -> 168620.22 | I35: ='Quarterly Financial Projections'!I26 -> 177236.64 | J35: ='Quarterly Financial Projections'!J26 -> 186213.61 | K35: ='Quarterly Financial Projections'!K26 -> 195564.63 | L35: ='Quarterly Financial Projections'!L26 -> 205303.59 | M35: ='Quarterly Financial Projections'!M26 -> 215444.89 | ... Z35: ='Quarterly Financial Projections'!Z26 -> 391315.79 | AB35: =SUMIF($F$2:$Z$2,AB$2,$F35:$Z35) -> 230111.06 | AC35: =SUMIF($F$2:$Z$2,AC$2,$F35:$Z35) -> 703260 | AD35: =SUMIF($F$2:$Z$2,AD$2,$F35:$Z35) -> 842316.45 | AE35: =SUMIF($F$2:$Z$2,AE$2,$F35:$Z35) -> 1018487.2 | AF35: =SUMIF($F$2:$Z$2,AF$2,$F35:$Z35) -> 1224982.8 | AG35: =SUMIF($F$2:$Z$2,AG$2,$F35:$Z35) -> 1466366.1
B36: Total Deposits | F36: ='Quarterly Financial Projections'!F48 -> 16642450 | G36: ='Quarterly Financial Projections'!G48 -> 17239266 | H36: ='Quarterly Financial Projections'!H48 -> 17857485 | I36: ='Quarterly Financial Projections'!I48 -> 18497873 | J36: ='Quarterly Financial Projections'!J48 -> 19161227 | K36: ='Quarterly Financial Projections'!K48 -> 19848369 | L36: ='Quarterly Financial Projections'!L48 -> 20560153 | M36: ='Quarterly Financial Projections'!M48 -> 21297463 | ... Z36: ='Quarterly Financial Projections'!Z48 -> 33670346 | AB36: =SUMIF($F$4:$Z$4,AB$4,$F36:$Z36) -> 16642450 | AC36: =SUMIF($F$4:$Z$4,AC$4,$F36:$Z36) -> 19161227 | AD36: =SUMIF($F$4:$Z$4,AD$4,$F36:$Z36) -> 22061213 | AE36: =SUMIF($F$4:$Z$4,AE$4,$F36:$Z36) -> 25400101 | AF36: =SUMIF($F$4:$Z$4,AF$4,$F36:$Z36) -> 29244319 | AG36: =SUMIF($F$4:$Z$4,AG$4,$F36:$Z36) -> 33670346
B37: Total Equity | F37: ='Quarterly Financial Projections'!F62 -> 2208394.7 | G37: ='Quarterly Financial Projections'!G62 -> 2332935.8 | H37: ='Quarterly Financial Projections'!H62 -> 2457041.3 | I37: ='Quarterly Financial Projections'!I62 -> 2587488.6 | J37: ='Quarterly Financial Projections'!J62 -> 2724543 | K37: ='Quarterly Financial Projections'!K62 -> 2868479.8 | L37: ='Quarterly Financial Projections'!L62 -> 3019584.6 | M37: ='Quarterly Financial Projections'!M62 -> 3178153.4 | ... Z37: ='Quarterly Financial Projections'!Z62 -> 6074956.3 | AB37: =SUMIF($F$4:$Z$4,AB$4,$F37:$Z37) -> 2208394.7 | AC37: =SUMIF($F$4:$Z$4,AC$4,$F37:$Z37) -> 2724543 | AD37: =SUMIF($F$4:$Z$4,AD$4,$F37:$Z37) -> 3344493.3 | AE37: =SUMIF($F$4:$Z$4,AE$4,$F37:$Z37) -> 4094106.4 | AF37: =SUMIF($F$4:$Z$4,AF$4,$F37:$Z37) -> 4995701.5 | AG37: =SUMIF($F$4:$Z$4,AG$4,$F37:$Z37) -> 6074956.3
B38: Shares Outstanding | F38: ='Quarterly Financial Projections'!F28 -> 349617.46 | G38: ='Quarterly Financial Projections'!G28 -> 349617.46 | H38: ='Quarterly Financial Projections'!H28 -> 349617.46 | I38: ='Quarterly Financial Projections'!I28 -> 349617.46 | J38: ='Quarterly Financial Projections'!J28 -> 349617.46 | K38: ='Quarterly Financial Projections'!K28 -> 349617.46 | L38: ='Quarterly Financial Projections'!L28 -> 349617.46 | M38: ='Quarterly Financial Projections'!M28 -> 349617.46 | ... Z38: ='Quarterly Financial Projections'!Z28 -> 349617.46 | AB38: =SUMIF($F$4:$Z$4,AB$4,$F38:$Z38) -> 349617.46 | AC38: =SUMIF($F$4:$Z$4,AC$4,$F38:$Z38) -> 349617.46 | AD38: =SUMIF($F$4:$Z$4,AD$4,$F38:$Z38) -> 349617.46 | AE38: =SUMIF($F$4:$Z$4,AE$4,$F38:$Z38) -> 349617.46 | AF38: =SUMIF($F$4:$Z$4,AF$4,$F38:$Z38) -> 349617.46 | AG38: =SUMIF($F$4:$Z$4,AG$4,$F38:$Z38) -> 349617.46
B40: Discounted EPS | F40: =(F35/F$38) -> 0.65817955 | G40: =(G35/G$38)*G26 -> 0.48030319 | H40: =(H35/H$38)*H26 -> 0.46406549 | I40: =(I35/I$38)*I26 -> 0.47846977 | J40: =(J35/J$38)*J26 -> 0.49311 | K40: =(K35/K$38)*K26 -> 0.50798871 | L40: =(L35/L$38)*L26 -> 0.52310838 | M40: =(M35/M$38)*M26 -> 0.53847147 | N40: =(N35/N$38)*N26 -> 0.55408034 | ... Z40: =(Z35/Z$38)*Z26 -> 0.76131036 | AB40: =SUMIF($F$2:$Z$2,AB$2,$F40:$Z40) -> 0.65817955 | AC40: =SUMIF($F$2:$Z$2,AC$2,$F40:$Z40) -> 1.9159484 | AD40: =SUMIF($F$2:$Z$2,AD$2,$F40:$Z40) -> 2.1236489 | AE40: =SUMIF($F$2:$Z$2,AE$2,$F40:$Z40) -> 2.3774056 | AF40: =SUMIF($F$2:$Z$2,AF$2,$F40:$Z40) -> 2.6473799 | AG40: =SUMIF($F$2:$Z$2,AG$2,$F40:$Z40) -> 2.9340397
B41: Discounted DPS | F41: =(F36/F$38) -> 47.601883 | G41: =(G36/G$38)*G26 -> 48.367877 | H41: =(H36/H$38)*H26 -> 49.146197 | I41: =(I36/I$38)*I26 -> 49.937041 | J41: =(J36/J$38)*J26 -> 50.740612 | K41: =(K36/K$38)*K26 -> 51.557113 | L41: =(L36/L$38)*L26 -> 52.386753 | M41: =(M36/M$38)*M26 -> 53.229743 | N41: =(N36/N$38)*N26 -> 54.086299 | ... Z41: =(Z36/Z$38)*Z26 -> 65.506131 | AB41: =SUMIF($F$4:$Z$4,AB$4,$F41:$Z41) -> 47.601883 | AC41: =SUMIF($F$4:$Z$4,AC$4,$F41:$Z41) -> 50.740612 | AD41: =SUMIF($F$4:$Z$4,AD$4,$F41:$Z41) -> 54.086299 | AE41: =SUMIF($F$4:$Z$4,AE$4,$F41:$Z41) -> 57.65259 | AF41: =SUMIF($F$4:$Z$4,AF$4,$F41:$Z41) -> 61.454033 | AG41: =SUMIF($F$4:$Z$4,AG$4,$F41:$Z41) -> 65.506131
B42: Discounted BPS | F42: =(F37/F$38) -> 6.3166029 | G42: =(G37/G$38)*G26 -> 6.5454731 | H42: =(H37/H$38)*H26 -> 6.7621079 | I42: =(I37/I$38)*I26 -> 6.9852098 | J42: =(J37/J$38)*J26 -> 7.2148292 | K42: =(K37/K$38)*K26 -> 7.4510171 | L42: =(L37/L$38)*L26 -> 7.6938255 | M42: =(M37/M$38)*M26 -> 7.9433072 | N42: =(N37/N$38)*N26 -> 8.1995158 | ... Z42: =(Z37/Z$38)*Z26 -> 11.818913 | AB42: =SUMIF($F$4:$Z$4,AB$4,$F42:$Z42) -> 6.3166029 | AC42: =SUMIF($F$4:$Z$4,AC$4,$F42:$Z42) -> 7.2148292 | AD42: =SUMIF($F$4:$Z$4,AD$4,$F42:$Z42) -> 8.1995158 | AE42: =SUMIF($F$4:$Z$4,AE$4,$F42:$Z42) -> 9.2927125 | AF42: =SUMIF($F$4:$Z$4,AF$4,$F42:$Z42) -> 10.497971 | AG42: =SUMIF($F$4:$Z$4,AG$4,$F42:$Z42) -> 11.818913
B44: Rolling NTM Discounted EPS | F44: =SUM(F40:I40) -> 2.081018 | G44: =SUM(G40:J40) -> 1.9159484 | H44: =SUM(H40:K40) -> 1.943634 | I44: =SUM(I40:L40) -> 2.0026769 | J44: =SUM(J40:M40) -> 2.0626786 | K44: =SUM(K40:N40) -> 2.1236489 | L44: =SUM(L40:O40) -> 2.1855975 | M44: =SUM(M40:P40) -> 2.2485338 | ... W44: =SUM(W40:Z40) -> 2.9340397 | X44: =SUM(W40:Z40) -> 2.9340397 | Y44: =SUM(W40:Z40) -> 2.9340397 | Z44: =SUM(W40:Z40) -> 2.9340397 | AB44: =F44 -> 2.081018 | AC44: =AC40 -> 1.9159484 | AD44: =AD40 -> 2.1236489 | AE44: =AE40 -> 2.3774056 | AF44: =AF40 -> 2.6473799 | AG44: =AG40 -> 2.9340397
B45: Rolling NTM Discounted DPS | F45: =F41 -> 47.601883 | G45: =G41 -> 48.367877 | H45: =H41 -> 49.146197 | I45: =I41 -> 49.937041 | J45: =J41 -> 50.740612 | K45: =K41 -> 51.557113 | L45: =L41 -> 52.386753 | M45: =M41 -> 53.229743 | ... Z45: =Z41 -> 65.506131 | AB45: =AB41 -> 47.601883 | AC45: =AC41 -> 50.740612 | AD45: =AD41 -> 54.086299 | AE45: =AE41 -> 57.65259 | AF45: =AF41 -> 61.454033 | AG45: =AG41 -> 65.506131
B46: Rolling NTM Discounted BPS | F46: =F42 -> 6.3166029 | G46: =G42 -> 6.5454731 | H46: =H42 -> 6.7621079 | I46: =I42 -> 6.9852098 | J46: =J42 -> 7.2148292 | K46: =K42 -> 7.4510171 | L46: =L42 -> 7.6938255 | M46: =M42 -> 7.9433072 | ... Z46: =Z42 -> 11.818913 | AB46: =AB42 -> 6.3166029 | AC46: =AC42 -> 7.2148292 | AD46: =AD42 -> 8.1995158 | AE46: =AE42 -> 9.2927125 | AF46: =AF42 -> 10.497971 | AG46: =AG42 -> 11.818913
B49: Share Price
B50: P/E Approach | F50: =F44*$D31 -> 18.42679 | G50: =G44*$D31 -> 16.965148 | H50: =H44*$D31 -> 17.210295 | I50: =I44*$D31 -> 17.733103 | J50: =J44*$D31 -> 18.2644 | K50: =K44*$D31 -> 18.804274 | L50: =L44*$D31 -> 19.35281 | M50: =M44*$D31 -> 19.910092 | ... Z50: =Z44*$D31 -> 25.980041 | AB50: =AB44*$D31 -> 18.42679 | AC50: =AC44*$D31 -> 16.965148 | AD50: =AD44*$D31 -> 18.804274 | AE50: =AE44*$D31 -> 21.051213 | AF50: =AF44*$D31 -> 23.441755 | AG50: =AG44*$D31 -> 25.980041
B51: P/D Approach | F51: =F45*$D32 -> 13.378993 | G51: =G45*$D32 -> 13.594283 | H51: =H45*$D32 -> 13.813038 | I51: =I45*$D32 -> 14.035313 | J51: =J45*$D32 -> 14.261164 | K51: =K45*$D32 -> 14.49065 | L51: =L45*$D32 -> 14.723829 | M51: =M45*$D32 -> 14.96076 | ... Z51: =Z45*$D32 -> 18.411163 | AB51: =AB45*$D32 -> 13.378993 | AC51: =AC45*$D32 -> 14.261164 | AD51: =AD45*$D32 -> 15.201503 | AE51: =AE45*$D32 -> 16.203846 | AF51: =AF45*$D32 -> 17.27228 | AG51: =AG45*$D32 -> 18.411163
B52: P/B Approach | F52: =F46*$D33 -> 10.818749 | G52: =G46*$D33 -> 11.210746 | H52: =H46*$D33 -> 11.581787 | I52: =I46*$D33 -> 11.963904 | J52: =J46*$D33 -> 12.357185 | K52: =K46*$D33 -> 12.761715 | L52: =L46*$D33 -> 13.177585 | M52: =M46*$D33 -> 13.604884 | ... Z52: =Z46*$D33 -> 20.24282 | AB52: =AB46*$D33 -> 10.818749 | AC52: =AC46*$D33 -> 12.357185 | AD52: =AD46*$D33 -> 14.043705 | AE52: =AE46*$D33 -> 15.916075 | AF52: =AF46*$D33 -> 17.980379 | AG52: =AG46*$D33 -> 20.24282
...

Sheet Quarterly Financial Projections
B1: FIRST ATLANTIC BANK LIMITED
D2: Year | E2: =YEAR(E4) -> 2025 | F2: =YEAR(F4) -> 2025 | G2: =YEAR(G4) -> 2026 | H2: =YEAR(H4) -> 2026 | I2: =YEAR(I4) -> 2026 | J2: =YEAR(J4) -> 2026 | K2: =YEAR(K4) -> 2027 | L2: =YEAR(L4) -> 2027 | ... Z2: =YEAR(Z4) -> 2030 | AB2: =YEAR(AB4) -> 2025 | AC2: =YEAR(AC4) -> 2026 | AD2: =YEAR(AD4) -> 2027 | AE2: =YEAR(AE4) -> 2028 | AF2: =YEAR(AF4) -> 2029 | AG2: =YEAR(AG4) -> 2030
D3: Start Date | E3: ='Quarterly Historical Financials'!AB3 -> 45839 | F3: =E4+1 -> 45931 | G3: =F4+1 -> 46023 | H3: =G4+1 -> 46113 | I3: =H4+1 -> 46204 | J3: =I4+1 -> 46296 | K3: =J4+1 -> 46388 | L3: =K4+1 -> 46478 | M3: =L4+1 -> 46569 | ... Z3: =Y4+1 -> 47757 | AB3: =E3 -> 45839 | AC3: =AB4+1 -> 46023 | AD3: =AC4+1 -> 46388 | AE3: =AD4+1 -> 46753 | AF3: =AE4+1 -> 47119 | AG3: =AF4+1 -> 47484
D4: End Date | E4: =EOMONTH(E3,2) -> 45930 | F4: =EOMONTH(F3,2) -> 46022 | G4: =EOMONTH(G3,2) -> 46112 | H4: =EOMONTH(H3,2) -> 46203 | I4: =EOMONTH(I3,2) -> 46295 | J4: =EOMONTH(J3,2) -> 46387 | K4: =EOMONTH(K3,2) -> 46477 | L4: =EOMONTH(L3,2) -> 46568 | ... Z4: =EOMONTH(Z3,2) -> 47848 | AB4: =EOMONTH(AB3,5) -> 46022 | AC4: =EOMONTH(AC3,11) -> 46387 | AD4: =EOMONTH(AD3,11) -> 46752 | AE4: =EOMONTH(AE3,11) -> 47118 | AF4: =EOMONTH(AF3,11) -> 47483 | AG4: =EOMONTH(AG3,11) -> 47848
B5: All amounts in thousands of GHS unless stated otherwise | D5: Period | E5: =E4-E3+1 -> 92 | F5: =F4-F3+1 -> 92 | G5: =G4-G3+1 -> 90 | H5: =H4-H3+1 -> 91 | I5: =I4-I3+1 -> 92 | J5: =J4-J3+1 -> 92 | K5: =K4-K3+1 -> 90 | L5: =L4-L3+1 -> 91 | ... Z5: =Z4-Z3+1 -> 92 | AB5: =AB4-AB3+1 -> 184 | AC5: =AC4-AC3+1 -> 365 | AD5: =AD4-AD3+1 -> 365 | AE5: =AE4-AE3+1 -> 366 | AF5: =AF4-AF3+1 -> 365 | AG5: =AG4-AG3+1 -> 365
B7: Income Statement
B8: Interest Income | E8: ='Quarterly Historical Financials'!AB9 -> 276147 | F8: ='Quarterly Historical Financials'!AC9 -> 681759.57 | G8: =Assumptions!N21 -> 384375.91 | H8: =Assumptions!O21 -> 402463.86 | I8: =Assumptions!P21 -> 421307.6 | J8: =Assumptions!Q21 -> 440936.87 | K8: =Assumptions!R21 -> 461382.59 | L8: =Assumptions!S21 -> 482676.87 | M8: =Assumptions!T21 -> 504853.07 | N8: =Assumptions!U21 -> 527945.88 | ... Z8: =Assumptions!AG21 -> 891213.25 | AB8: =SUMIF($E$2:$Z$2,AB$2,$E8:$Z8) -> 957906.57 | AC8: =SUMIF($E$2:$Z$2,AC$2,$E8:$Z8) -> 1649084.2 | AD8: =SUMIF($E$2:$Z$2,AD$2,$E8:$Z8) -> 1976858.4 | AE8: =SUMIF($E$2:$Z$2,AE$2,$E8:$Z8) -> 2362334.8 | AF8: =SUMIF($E$2:$Z$2,AF$2,$E8:$Z8) -> 2815137.9 | AG8: =SUMIF($E$2:$Z$2,AG$2,$E8:$Z8) -> 3346506.3
B9: Interest Expense | E9: ='Quarterly Historical Financials'!AB10 -> -138688 | F9: ='Quarterly Historical Financials'!AC10 -> -102371.52 | G9: =Assumptions!N29 -> -104190.6 | H9: =Assumptions!O29 -> -107926.99 | I9: =Assumptions!P29 -> -111797.37 | J9: =Assumptions!Q29 -> -115806.54 | K9: =Assumptions!R29 -> -119959.49 | L9: =Assumptions!S29 -> -124261.37 | M9: =Assumptions!T29 -> -128717.51 | N9: =Assumptions!U29 -> -133333.46 | ... Z9: =Assumptions!AG29 -> -203496.69 | AB9: =SUMIF($E$2:$Z$2,AB$2,$E9:$Z9) -> -241059.52 | AC9: =SUMIF($E$2:$Z$2,AC$2,$E9:$Z9) -> -439721.5 | AD9: =SUMIF($E$2:$Z$2,AD$2,$E9:$Z9) -> -506271.83 | AE9: =SUMIF($E$2:$Z$2,AE$2,$E9:$Z9) -> -582894.33 | AF9: =SUMIF($E$2:$Z$2,AF$2,$E9:$Z9) -> -671113.38 | AG9: =SUMIF($E$2:$Z$2,AG$2,$E9:$Z9) -> -772684.07
B10: Net Interest Income | E10: =SUM(E8:E9) -> 137459 | F10: =SUM(F8:F9) -> 579388.04 | G10: =SUM(G8:G9) -> 280185.31 | H10: =SUM(H8:H9) -> 294536.87 | I10: =SUM(I8:I9) -> 309510.23 | J10: =SUM(J8:J9) -> 325130.33 | K10: =SUM(K8:K9) -> 341423.1 | L10: =SUM(L8:L9) -> 358415.5 | ... Z10: =SUM(Z8:Z9) -> 687716.56 | AB10: =SUM(AB8:AB9) -> 716847.04 | AC10: =SUM(AC8:AC9) -> 1209362.7 | AD10: =SUM(AD8:AD9) -> 1470586.6 | AE10: =SUM(AE8:AE9) -> 1779440.5 | AF10: =SUM(AF8:AF9) -> 2144024.6 | AG10: =SUM(AG8:AG9) -> 2573822.2
B11: Fee and commission income | E11: ='Quarterly Historical Financials'!AB12 -> 80299 | F11: ='Quarterly Historical Financials'!AC12 -> 76446.237 | G11: =Assumptions!N39 -> 72259.202 | H11: =Assumptions!O39 -> 71258.687 | I11: =Assumptions!P39 -> 73814.101 | J11: =Assumptions!Q39 -> 76461.154 | K11: =Assumptions!R39 -> 79203.134 | L11: =Assumptions!S39 -> 82043.444 | M11: =Assumptions!T39 -> 84985.61 | N11: =Assumptions!U39 -> 88033.286 | ... Z11: =Assumptions!AG39 -> 134358.49 | AB11: =SUMIF($E$2:$Z$2,AB$2,$E11:$Z11) -> 156745.24 | AC11: =SUMIF($E$2:$Z$2,AC$2,$E11:$Z11) -> 293793.14 | AD11: =SUMIF($E$2:$Z$2,AD$2,$E11:$Z11) -> 334265.47 | AE11: =SUMIF($E$2:$Z$2,AE$2,$E11:$Z11) -> 384855.4 | AF11: =SUMIF($E$2:$Z$2,AF$2,$E11:$Z11) -> 443101.94 | AG11: =SUMIF($E$2:$Z$2,AG$2,$E11:$Z11) -> 510163.89
B12: Fee and commission expense | E12: ='Quarterly Historical Financials'!AB13 -> -22529 | F12: ='Quarterly Historical Financials'!AC13 -> -29426.085 | G12: =Assumptions!N44 -> -19259.425 | H12: =Assumptions!O44 -> -18992.755 | I12: =Assumptions!P44 -> -19673.856 | J12: =Assumptions!Q44 -> -20379.381 | K12: =Assumptions!R44 -> -21110.208 | L12: =Assumptions!S44 -> -21867.243 | M12: =Assumptions!T44 -> -22651.426 | N12: =Assumptions!U44 -> -23463.73 | ... Z12: =Assumptions!AG44 -> -35810.902 | AB12: =SUMIF($E$2:$Z$2,AB$2,$E12:$Z12) -> -51955.085 | AC12: =SUMIF($E$2:$Z$2,AC$2,$E12:$Z12) -> -78305.416 | AD12: =SUMIF($E$2:$Z$2,AD$2,$E12:$Z12) -> -89092.607 | AE12: =SUMIF($E$2:$Z$2,AE$2,$E12:$Z12) -> -102576.47 | AF12: =SUMIF($E$2:$Z$2,AF$2,$E12:$Z12) -> -118101.06 | AG12: =SUMIF($E$2:$Z$2,AG$2,$E12:$Z12) -> -135975.25
B13: Net Fees and Commission Income | E13: =SUM(E11:E12) -> 57770 | F13: =SUM(F11:F12) -> 47020.152 | G13: =SUM(G11:G12) -> 52999.777 | H13: =SUM(H11:H12) -> 52265.932 | I13: =SUM(I11:I12) -> 54140.245 | J13: =SUM(J11:J12) -> 56081.773 | K13: =SUM(K11:K12) -> 58092.926 | L13: =SUM(L11:L12) -> 60176.201 | ... Z13: =SUM(Z11:Z12) -> 98547.587 | AB13: =SUM(AB11:AB12) -> 104790.15 | AC13: =SUM(AC11:AC12) -> 215487.73 | AD13: =SUM(AD11:AD12) -> 245172.87 | AE13: =SUM(AE11:AE12) -> 282278.94 | AF13: =SUM(AF11:AF12) -> 325000.88 | AG13: =SUM(AG11:AG12) -> 374188.64
B14: Net trading income | E14: ='Quarterly Historical Financials'!AB15 -> 27893 | F14: ='Quarterly Historical Financials'!AC15 -> 46887.804 | G14: =Assumptions!N55 -> 22332.103 | H14: =Assumptions!O55 -> 23132.956 | I14: =Assumptions!P55 -> 23962.529 | J14: =Assumptions!Q55 -> 24821.851 | K14: =Assumptions!R55 -> 25711.99 | L14: =Assumptions!S55 -> 26634.049 | M14: =Assumptions!T55 -> 27589.175 | N14: =Assumptions!U55 -> 28578.553 | ... Z14: =Assumptions!AG55 -> 43617.265 | AB14: =SUMIF($E$2:$Z$2,AB$2,$E14:$Z14) -> 74780.804 | AC14: =SUMIF($E$2:$Z$2,AC$2,$E14:$Z14) -> 94249.439 | AD14: =SUMIF($E$2:$Z$2,AD$2,$E14:$Z14) -> 108513.77 | AE14: =SUMIF($E$2:$Z$2,AE$2,$E14:$Z14) -> 124936.95 | AF14: =SUMIF($E$2:$Z$2,AF$2,$E14:$Z14) -> 143845.73 | AG14: =SUMIF($E$2:$Z$2,AG$2,$E14:$Z14) -> 165616.28
B15: Other income | E15: ='Quarterly Historical Financials'!AB16 -> 673 | F15: ='Quarterly Historical Financials'!AC16 -> 326.388 | G15: =Assumptions!N64 -> 413.45079 | H15: =Assumptions!O64 -> 428.8922 | I15: =Assumptions!P64 -> 448.08032 | J15: =Assumptions!Q64 -> 468.05132 | K15: =Assumptions!R64 -> 488.83563 | L15: =Assumptions!S64 -> 510.46485 | M15: =Assumptions!T64 -> 532.97184 | N15: =Assumptions!U64 -> 556.39069 | ... Z15: =Assumptions!AG64 -> 922.938 | AB15: =SUMIF($E$2:$Z$2,AB$2,$E15:$Z15) -> 999.388 | AC15: =SUMIF($E$2:$Z$2,AC$2,$E15:$Z15) -> 1758.4746 | AD15: =SUMIF($E$2:$Z$2,AD$2,$E15:$Z15) -> 2088.663 | AE15: =SUMIF($E$2:$Z$2,AE$2,$E15:$Z15) -> 2479.2579 | AF15: =SUMIF($E$2:$Z$2,AF$2,$E15:$Z15) -> 2936.725 | AG15: =SUMIF($E$2:$Z$2,AG$2,$E15:$Z15) -> 3472.0905
B16: Operating Income | E16: =SUM(E10,E13:E15) -> 223795 | F16: =SUM(F10,F13:F15) -> 673622.39 | G16: =SUM(G10,G13:G15) -> 355930.64 | H16: =SUM(H10,H13:H15) -> 370364.65 | I16: =SUM(I10,I13:I15) -> 388061.08 | J16: =SUM(J10,J13:J15) -> 406502 | K16: =SUM(K10,K13:K15) -> 425716.85 | L16: =SUM(L10,L13:L15) -> 445736.22 | ... Z16: =SUM(Z10,Z13:Z15) -> 830804.35 | AB16: =SUM(AB10,AB13:AB15) -> 897417.39 | AC16: =SUM(AC10,AC13:AC15) -> 1520858.4 | AD16: =SUM(AD10,AD13:AD15) -> 1826361.9 | AE16: =SUM(AE10,AE13:AE15) -> 2189135.7 | AF16: =SUM(AF10,AF13:AF15) -> 2615807.9 | AG16: =SUM(AG10,AG13:AG15) -> 3117099.2
B17: Impairment losses on loans and advances | E17: ='Quarterly Historical Financials'!AB18 -> 46660 | F17: ='Quarterly Historical Financials'!AC18 -> -178305.4 | G17: =Assumptions!N91 -> -26006.504 | H17: =Assumptions!O91 -> -39223.326 | I17: =Assumptions!P91 -> -40629.917 | J17: =Assumptions!Q91 -> -42086.949 | K17: =Assumptions!R91 -> -43596.233 | L17: =Assumptions!S91 -> -45159.641 | M17: =Assumptions!T91 -> -46779.114 | N17: =Assumptions!U91 -> -48456.664 | ... Z17: =Assumptions!AG91 -> -73955.71 | AB17: =SUMIF($E$2:$Z$2,AB$2,$E17:$Z17) -> -131645.4 | AC17: =SUMIF($E$2:$Z$2,AC$2,$E17:$Z17) -> -147946.7 | AD17: =SUMIF($E$2:$Z$2,AD$2,$E17:$Z17) -> -183991.65 | AE17: =SUMIF($E$2:$Z$2,AE$2,$E17:$Z17) -> -211838.15 | AF17: =SUMIF($E$2:$Z$2,AF$2,$E17:$Z17) -> -243899.13 | AG17: =SUMIF($E$2:$Z$2,AG$2,$E17:$Z17) -> -280812.42
B18: Personnel expenses | E18: ='Quarterly Historical Financials'!AB20 -> -46163 | F18: ='Quarterly Historical Financials'!AC20 -> -119879.86 | G18: =Assumptions!N76 -> -57328.043 | H18: =Assumptions!O76 -> -59652.86 | I18: =Assumptions!P76 -> -62503.14 | J18: =Assumptions!Q76 -> -65473.331 | K18: =Assumptions!R76 -> -68568.174 | L18: =Assumptions!S76 -> -71792.597 | M18: =Assumptions!T76 -> -75151.721 | N18: =Assumptions!U76 -> -78650.866 | ... Z18: =Assumptions!AG76 -> -133813.68 | AB18: =SUMIF($E$2:$Z$2,AB$2,$E18:$Z18) -> -166042.86 | AC18: =SUMIF($E$2:$Z$2,AC$2,$E18:$Z18) -> -244957.37 | AD18: =SUMIF($E$2:$Z$2,AD$2,$E18:$Z18) -> -294163.36 | AE18: =SUMIF($E$2:$Z$2,AE$2,$E18:$Z18) -> -352593.6 | AF18: =SUMIF($E$2:$Z$2,AF$2,$E18:$Z18) -> -421315.65 | AG18: =SUMIF($E$2:$Z$2,AG$2,$E18:$Z18) -> -502056.24
B19: Depreciation and amortisation | E19: ='Quarterly Historical Financials'!AB21 -> -15613 | F19: ='Quarterly Historical Financials'!AC21 -> -18327.089 | G19: =Assumptions!N144+Assumptions!N153+Assumptions!N162 -> -7706.1292 | H19: =Assumptions!O144+Assumptions!O153+Assumptions!O162 -> -7725.7472 | I19: =Assumptions!P144+Assumptions!P153+Assumptions!P162 -> -7745.5043 | J19: =Assumptions!Q144+Assumptions!Q153+Assumptions!Q162 -> -7765.4018 | K19: =Assumptions!R144+Assumptions!R153+Assumptions!R162 -> -7785.441 | L19: =Assumptions!S144+Assumptions!S153+Assumptions!S162 -> -7805.6233 | M19: =Assumptions!T144+Assumptions!T153+Assumptions!T162 -> -7825.9499 | N19: =Assumptions!U144+Assumptions!U153+Assumptions!U162 -> -7846.4222 | ... Z19: =Assumptions!AG144+Assumptions!AG153+Assumptions!AG162 -> -8103.9576 | AB19: =SUMIF($E$2:$Z$2,AB$2,$E19:$Z19) -> -33940.089 | AC19: =SUMIF($E$2:$Z$2,AC$2,$E19:$Z19) -> -30942.782 | AD19: =SUMIF($E$2:$Z$2,AD$2,$E19:$Z19) -> -31263.436 | AE19: =SUMIF($E$2:$Z$2,AE$2,$E19:$Z19) -> -31593.373 | AF19: =SUMIF($E$2:$Z$2,AF$2,$E19:$Z19) -> -31932.941 | AG19: =SUMIF($E$2:$Z$2,AG$2,$E19:$Z19) -> -32282.503
B20: Other expenses | E20: ='Quarterly Historical Financials'!AB22 -> -51147 | F20: ='Quarterly Historical Financials'!AC22 -> -25698.955 | G20: =Assumptions!N79 -> -46963.9 | H20: =Assumptions!O79 -> -48868.422 | I20: =Assumptions!P79 -> -51203.409 | J20: =Assumptions!Q79 -> -53636.629 | K20: =Assumptions!R79 -> -56171.966 | L20: =Assumptions!S79 -> -58813.457 | M20: =Assumptions!T79 -> -61565.295 | N20: =Assumptions!U79 -> -64431.842 | ... Z20: =Assumptions!AG79 -> -109621.96 | AB20: =SUMIF($E$2:$Z$2,AB$2,$E20:$Z20) -> -76845.955 | AC20: =SUMIF($E$2:$Z$2,AC$2,$E20:$Z20) -> -200672.36 | AD20: =SUMIF($E$2:$Z$2,AD$2,$E20:$Z20) -> -240982.56 | AE20: =SUMIF($E$2:$Z$2,AE$2,$E20:$Z20) -> -288849.39 | AF20: =SUMIF($E$2:$Z$2,AF$2,$E20:$Z20) -> -345147.42 | AG20: =SUMIF($E$2:$Z$2,AG$2,$E20:$Z20) -> -411291.2
B21: Finance cost on lease liability | E21: ='Quarterly Historical Financials'!AB23 -> -3166 | F21: ='Quarterly Historical Financials'!AC23 -> -416.745 | G21: =Assumptions!N203 -> -2180.6666 | H21: =Assumptions!O203 -> -2386.9413 | I21: =Assumptions!P203 -> -2612.728 | J21: =Assumptions!Q203 -> -2859.8725 | K21: =Assumptions!R203 -> -3130.395 | L21: =Assumptions!S203 -> -3426.5069 | M21: =Assumptions!T203 -> -3750.6287 | N21: =Assumptions!U203 -> -4105.41 | ... Z21: =Assumptions!AG203 -> -12144.682 | AB21: =SUMIF($E$2:$Z$2,AB$2,$E21:$Z21) -> -3582.745 | AC21: =SUMIF($E$2:$Z$2,AC$2,$E21:$Z21) -> -10040.208 | AD21: =SUMIF($E$2:$Z$2,AD$2,$E21:$Z21) -> -14412.941 | AE21: =SUMIF($E$2:$Z$2,AE$2,$E21:$Z21) -> -20690.094 | AF21: =SUMIF($E$2:$Z$2,AF$2,$E21:$Z21) -> -29701.086 | AG21: =SUMIF($E$2:$Z$2,AG$2,$E21:$Z21) -> -42636.563
B22: Total Operating Expenses | E22: =SUM(E17:E21) -> -69429 | F22: =SUM(F17:F21) -> -342628.05 | G22: =SUM(G17:G21) -> -140185.24 | H22: =SUM(H17:H21) -> -157857.3 | I22: =SUM(I17:I21) -> -164694.7 | J22: =SUM(J17:J21) -> -171822.18 | K22: =SUM(K17:K21) -> -179252.21 | L22: =SUM(L17:L21) -> -186997.82 | ... Z22: =SUM(Z17:Z21) -> -337639.98 | AB22: =SUM(AB17:AB21) -> -412057.05 | AC22: =SUM(AC17:AC21) -> -634559.42 | AD22: =SUM(AD17:AD21) -> -764813.95 | AE22: =SUM(AE17:AE21) -> -905564.61 | AF22: =SUM(AF17:AF21) -> -1071996.2 | AG22: =SUM(AG17:AG21) -> -1269078.9
B23: Share of profit from associate company | E23: ='Quarterly Historical Financials'!AB26 -> 422 | F23: ='Quarterly Historical Financials'!AC26 -> 295.116 | G23: 0 | H23: 0 | I23: 0 | J23: 0 | K23: 0 | L23: 0 | M23: 0 | N23: 0 | O23: 0 | P23: 0 | Q23: 0 | R23: 0 | S23: 0 | T23: 0 | U23: 0 | V23: 0 | W23: 0 | X23: 0 | Y23: 0 | Z23: 0 | AB23: =SUMIF($E$2:$Z$2,AB$2,$E23:$Z23) -> 717.116 | AC23: =SUMIF($E$2:$Z$2,AC$2,$E23:$Z23) -> 0 | AD23: =SUMIF($E$2:$Z$2,AD$2,$E23:$Z23) -> 0 | AE23: =SUMIF($E$2:$Z$2,AE$2,$E23:$Z23) -> 0 | AF23: =SUMIF($E$2:$Z$2,AF$2,$E23:$Z23) -> 0 | AG23: =SUMIF($E$2:$Z$2,AG$2,$E23:$Z23) -> 0
B24: Profit before income tax | E24: =SUM(E16,E22:E23) -> 154788 | F24: =SUM(F16,F22:F23) -> 331289.45 | G24: =SUM(G16,G22:G23) -> 215745.39 | H24: =SUM(H16,H22:H23) -> 212507.36 | I24: =SUM(I16,I22:I23) -> 223366.39 | J24: =SUM(J16,J22:J23) -> 234679.82 | K24: =SUM(K16,K22:K23) -> 246464.64 | L24: =SUM(L16,L22:L23) -> 258738.39 | ... Z24: =SUM(Z16,Z22:Z23) -> 493164.37 | AB24: =SUM(AB16,AB22:AB23) -> 486077.45 | AC24: =SUM(AC16,AC22:AC23) -> 886298.96 | AD24: =SUM(AD16,AD22:AD23) -> 1061547.9 | AE24: =SUM(AE16,AE22:AE23) -> 1283571.1 | AF24: =SUM(AF16,AF22:AF23) -> 1543811.7 | AG24: =SUM(AG16,AG22:AG23) -> 1848020.3
B25: Total Taxes | E25: =SUM('Quarterly Historical Financials'!AB28:AB31) -> -43024 | F25: =SUM('Quarterly Historical Financials'!AC28:AC31) -> -101178.39 | G25: =Assumptions!N117 -> -44555.86 | H25: =Assumptions!O117 -> -43887.138 | I25: =Assumptions!P117 -> -46129.751 | J25: =Assumptions!Q117 -> -48466.208 | K25: =Assumptions!R117 -> -50900.016 | L25: =Assumptions!S117 -> -53434.798 | M25: =Assumptions!T117 -> -56074.293 | N25: =Assumptions!U117 -> -58822.365 | ... Z25: =Assumptions!AG117 -> -101848.58 | AB25: =SUMIF($E$2:$Z$2,AB$2,$E25:$Z25) -> -144202.39 | AC25: =SUMIF($E$2:$Z$2,AC$2,$E25:$Z25) -> -183038.96 | AD25: =SUMIF($E$2:$Z$2,AD$2,$E25:$Z25) -> -219231.47 | AE25: =SUMIF($E$2:$Z$2,AE$2,$E25:$Z25) -> -265083.81 | AF25: =SUMIF($E$2:$Z$2,AF$2,$E25:$Z25) -> -318828.85 | AG25: =SUMIF($E$2:$Z$2,AG$2,$E25:$Z25) -> -381654.19
B26: Profit for the period | E26: =SUM(E24:E25) -> 111764 | F26: =SUM(F24:F25) -> 230111.06 | G26: =SUM(G24:G25) -> 171189.53 | H26: =SUM(H24:H25) -> 168620.22 | I26: =SUM(I24:I25) -> 177236.64 | J26: =SUM(J24:J25) -> 186213.61 | K26: =SUM(K24:K25) -> 195564.63 | L26: =SUM(L24:L25) -> 205303.59 | ... Z26: =SUM(Z24:Z25) -> 391315.79 | AB26: =SUM(AB24:AB25) -> 341875.06 | AC26: =SUM(AC24:AC25) -> 703260 | AD26: =SUM(AD24:AD25) -> 842316.45 | AE26: =SUM(AE24:AE25) -> 1018487.2 | AF26: =SUM(AF24:AF25) -> 1224982.8 | AG26: =SUM(AG24:AG25) -> 1466366.1
B28: Shares Outstanding | E28: ='Quarterly Historical Financials'!AB34 -> 349617.46 | F28: =E28 -> 349617.46 | G28: =F28 -> 349617.46 | H28: =G28 -> 349617.46 | I28: =H28 -> 349617.46 | J28: =I28 -> 349617.46 | K28: =J28 -> 349617.46 | L28: =K28 -> 349617.46 | M28: =L28 -> 349617.46 | ... Z28: =Y28 -> 349617.46 | AB28: =SUMIF($E$4:$Z$4,AB$4,$E28:$Z28) -> 349617.46 | AC28: =SUMIF($E$4:$Z$4,AC$4,$E28:$Z28) -> 349617.46 | AD28: =SUMIF($E$4:$Z$4,AD$4,$E28:$Z28) -> 349617.46 | AE28: =SUMIF($E$4:$Z$4,AE$4,$E28:$Z28) -> 349617.46 | AF28: =SUMIF($E$4:$Z$4,AF$4,$E28:$Z28) -> 349617.46 | AG28: =SUMIF($E$4:$Z$4,AG$4,$E28:$Z28) -> 349617.46
B29: EPS | E29: =E26/E28 -> 0.31967511 | F29: =F26/F28 -> 0.65817955 | G29: =G26/G28 -> 0.48964813 | H29: =H26/H28 -> 0.48229918 | I29: =I26/I28 -> 0.50694446 | J29: =J26/J28 -> 0.53262103 | K29: =K26/K28 -> 0.55936744 | L29: =L26/L28 -> 0.58722351 | ... Z29: =Z26/Z28 -> 1.1192684 | AB29: =AB26/AB28 -> 0.97785466 | AC29: =AC26/AC28 -> 2.0115128 | AD29: =AD26/AD28 -> 2.4092517 | AE29: =AE26/AE28 -> 2.9131475 | AF29: =AF26/AF28 -> 3.5037804 | AG29: =AG26/AG28 -> 4.1942016
B31: Statement of Financial Position
B32: Assets
B33: Cash and cash equivalents | E33: ='Quarterly Historical Financials'!AB41+'Quarterly Historical Financials'!AB42 -> 3312929 | F33: ='Quarterly Historical Financials'!AC41+'Quarterly Historical Financials'!AC42 -> 8162460.5 | G33: =G111 -> 6892248.5 | H33: =H111 -> 7295215.3 | I33: =I111 -> 7716511.2 | J33: =J111 -> 8156889.4 | K33: =K111 -> 8617133.3 | L33: =L111 -> 9098058 | M33: =M111 -> 9600511.4 | N33: =N111 -> 10125376 | ... Z33: =Z111 -> 18546972 | AB33: =SUMIF($E$4:$Z$4,AB$4,$E33:$Z33) -> 8162460.5 | AC33: =SUMIF($E$4:$Z$4,AC$4,$E33:$Z33) -> 8156889.4 | AD33: =SUMIF($E$4:$Z$4,AD$4,$E33:$Z33) -> 10125376 | AE33: =SUMIF($E$4:$Z$4,AE$4,$E33:$Z33) -> 12467879 | AF33: =SUMIF($E$4:$Z$4,AF$4,$E33:$Z33) -> 15249551 | AG33: =SUMIF($E$4:$Z$4,AG$4,$E33:$Z33) -> 18546972
B34: Trading assets (Investment securities) | E34: ='Quarterly Historical Financials'!AB43 -> 3580300 | F34: ='Quarterly Historical Financials'!AC43 -> 3178870.4 | G34: =Assumptions!N99 -> 4086092.7 | H34: =Assumptions!O99 -> 4232624.4 | I34: =Assumptions!P99 -> 4384410.9 | J34: =Assumptions!Q99 -> 4541640.6 | K34: =Assumptions!R99 -> 4704508.7 | L34: =Assumptions!S99 -> 4873217.5 | M34: =Assumptions!T99 -> 5047976.3 | N34: =Assumptions!U99 -> 5229002.2 | ... Z34: =Assumptions!AG99 -> 7980627.2 | AB34: =SUMIF($E$4:$Z$4,AB$4,$E34:$Z34) -> 3178870.4 | AC34: =SUMIF($E$4:$Z$4,AC$4,$E34:$Z34) -> 4541640.6 | AD34: =SUMIF($E$4:$Z$4,AD$4,$E34:$Z34) -> 5229002.2 | AE34: =SUMIF($E$4:$Z$4,AE$4,$E34:$Z34) -> 6020393.7 | AF34: =SUMIF($E$4:$Z$4,AF$4,$E34:$Z34) -> 6931559.6 | AG34: =SUMIF($E$4:$Z$4,AG$4,$E34:$Z34) -> 7980627.2
B35: Loans and advances to customers | E35: ='Quarterly Historical Financials'!AB44 -> 1516490 | F35: ='Quarterly Historical Financials'!AC44 -> 1947024.8 | G35: =Assumptions!N94 -> 2936526.5 | H35: =Assumptions!O94 -> 3041833.5 | I35: =Assumptions!P94 -> 3150917 | J35: =Assumptions!Q94 -> 3263912.3 | K35: =Assumptions!R94 -> 3380959.7 | L35: =Assumptions!S94 -> 3502204.6 | M35: =Assumptions!T94 -> 3627797.4 | N35: =Assumptions!U94 -> 3757894.1 | ... Z35: =Assumptions!AG94 -> 5735387.1 | AB35: =SUMIF($E$4:$Z$4,AB$4,$E35:$Z35) -> 1947024.8 | AC35: =SUMIF($E$4:$Z$4,AC$4,$E35:$Z35) -> 3263912.3 | AD35: =SUMIF($E$4:$Z$4,AD$4,$E35:$Z35) -> 3757894.1 | AE35: =SUMIF($E$4:$Z$4,AE$4,$E35:$Z35) -> 4326638.5 | AF35: =SUMIF($E$4:$Z$4,AF$4,$E35:$Z35) -> 4981460.3 | AG35: =SUMIF($E$4:$Z$4,AG$4,$E35:$Z35) -> 5735387.1
B36: Investment in associates | E36: ='Quarterly Historical Financials'!AB47 -> 2505 | F36: ='Quarterly Historical Financials'!AC47 -> 2799.382 | G36: =Assumptions!N105 -> 2799.382 | H36: =Assumptions!O105 -> 2799.382 | I36: =Assumptions!P105 -> 2799.382 | J36: =Assumptions!Q105 -> 2799.382 | K36: =Assumptions!R105 -> 2799.382 | L36: =Assumptions!S105 -> 2799.382 | M36: =Assumptions!T105 -> 2799.382 | N36: =Assumptions!U105 -> 2799.382 | ... Z36: =Assumptions!AG105 -> 2799.382 | AB36: =SUMIF($E$4:$Z$4,AB$4,$E36:$Z36) -> 2799.382 | AC36: =SUMIF($E$4:$Z$4,AC$4,$E36:$Z36) -> 2799.382 | AD36: =SUMIF($E$4:$Z$4,AD$4,$E36:$Z36) -> 2799.382 | AE36: =SUMIF($E$4:$Z$4,AE$4,$E36:$Z36) -> 2799.382 | AF36: =SUMIF($E$4:$Z$4,AF$4,$E36:$Z36) -> 2799.382 | AG36: =SUMIF($E$4:$Z$4,AG$4,$E36:$Z36) -> 2799.382
B37: Investment in subsidiary | E37: ='Quarterly Historical Financials'!AB48 -> 3025 | F37: ='Quarterly Historical Financials'!AC48 -> 0 | G37: =Assumptions!N111 -> 0 | H37: =Assumptions!O111 -> 0 | I37: =Assumptions!P111 -> 0 | J37: =Assumptions!Q111 -> 0 | K37: =Assumptions!R111 -> 0 | L37: =Assumptions!S111 -> 0 | M37: =Assumptions!T111 -> 0 | N37: =Assumptions!U111 -> 0 | ... Z37: =Assumptions!AG111 -> 0 | AB37: =SUMIF($E$4:$Z$4,AB$4,$E37:$Z37) -> 0 | AC37: =SUMIF($E$4:$Z$4,AC$4,$E37:$Z37) -> 0 | AD37: =SUMIF($E$4:$Z$4,AD$4,$E37:$Z37) -> 0 | AE37: =SUMIF($E$4:$Z$4,AE$4,$E37:$Z37) -> 0 | AF37: =SUMIF($E$4:$Z$4,AF$4,$E37:$Z37) -> 0 | AG37: =SUMIF($E$4:$Z$4,AG$4,$E37:$Z37) -> 0
B38: Current tax assets | E38: ='Quarterly Historical Financials'!AB49 -> 191807 | F38: ='Quarterly Historical Financials'!AC49 -> 244879.81 | G38: =Assumptions!N124 -> 244879.81 | H38: =Assumptions!O124 -> 244879.81 | I38: =Assumptions!P124 -> 244879.81 | J38: =Assumptions!Q124 -> 244879.81 | K38: =Assumptions!R124 -> 244879.81 | L38: =Assumptions!S124 -> 244879.81 | M38: =Assumptions!T124 -> 244879.81 | N38: =Assumptions!U124 -> 244879.81 | ... Z38: =Assumptions!AG124 -> 244879.81 | AB38: =SUMIF($E$4:$Z$4,AB$4,$E38:$Z38) -> 244879.81 | AC38: =SUMIF($E$4:$Z$4,AC$4,$E38:$Z38) -> 244879.81 | AD38: =SUMIF($E$4:$Z$4,AD$4,$E38:$Z38) -> 244879.81 | AE38: =SUMIF($E$4:$Z$4,AE$4,$E38:$Z38) -> 244879.81 | AF38: =SUMIF($E$4:$Z$4,AF$4,$E38:$Z38) -> 244879.81 | AG38: =SUMIF($E$4:$Z$4,AG$4,$E38:$Z38) -> 244879.81
B39: Deferred tax asset | E39: ='Quarterly Historical Financials'!AB50 -> 8827 | F39: ='Quarterly Historical Financials'!AC50 -> 0 | G39: =Assumptions!N130 -> 0 | H39: =Assumptions!O130 -> 0 | I39: =Assumptions!P130 -> 0 | J39: =Assumptions!Q130 -> 0 | K39: =Assumptions!R130 -> 0 | L39: =Assumptions!S130 -> 0 | M39: =Assumptions!T130 -> 0 | N39: =Assumptions!U130 -> 0 | ... Z39: =Assumptions!AG130 -> 0 | AB39: =SUMIF($E$4:$Z$4,AB$4,$E39:$Z39) -> 0 | AC39: =SUMIF($E$4:$Z$4,AC$4,$E39:$Z39) -> 0 | AD39: =SUMIF($E$4:$Z$4,AD$4,$E39:$Z39) -> 0 | AE39: =SUMIF($E$4:$Z$4,AE$4,$E39:$Z39) -> 0 | AF39: =SUMIF($E$4:$Z$4,AF$4,$E39:$Z39) -> 0 | AG39: =SUMIF($E$4:$Z$4,AG$4,$E39:$Z39) -> 0
B40: Growth and Fiscal levies | E40: ='Quarterly Historical Financials'!AB51 -> 37747 | F40: ='Quarterly Historical Financials'!AC51 -> 0 | G40: =Assumptions!N136 -> 0 | H40: =Assumptions!O136 -> 0 | I40: =Assumptions!P136 -> 0 | J40: =Assumptions!Q136 -> 0 | K40: =Assumptions!R136 -> 0 | L40: =Assumptions!S136 -> 0 | M40: =Assumptions!T136 -> 0 | N40: =Assumptions!U136 -> 0 | ... Z40: =Assumptions!AG136 -> 0 | AB40: =SUMIF($E$4:$Z$4,AB$4,$E40:$Z40) -> 0 | AC40: =SUMIF($E$4:$Z$4,AC$4,$E40:$Z40) -> 0 | AD40: =SUMIF($E$4:$Z$4,AD$4,$E40:$Z40) -> 0 | AE40: =SUMIF($E$4:$Z$4,AE$4,$E40:$Z40) -> 0 | AF40: =SUMIF($E$4:$Z$4,AF$4,$E40:$Z40) -> 0 | AG40: =SUMIF($E$4:$Z$4,AG$4,$E40:$Z40) -> 0
B41: Intangible assets | E41: ='Quarterly Historical Financials'!AB52 -> 33244 | F41: ='Quarterly Historical Financials'!AC52 -> 31109.297 | G41: =Assumptions!N145 -> 31406.565 | H41: =Assumptions!O145 -> 31706.674 | I41: =Assumptions!P145 -> 32009.65 | J41: =Assumptions!Q145 -> 32315.522 | K41: =Assumptions!R145 -> 32624.316 | L41: =Assumptions!S145 -> 32936.061 | M41: =Assumptions!T145 -> 33250.785 | N41: =Assumptions!U145 -> 33568.516 | ... Z41: =Assumptions!AG145 -> 37626.608 | AB41: =SUMIF($E$4:$Z$4,AB$4,$E41:$Z41) -> 31109.297 | AC41: =SUMIF($E$4:$Z$4,AC$4,$E41:$Z41) -> 32315.522 | AD41: =SUMIF($E$4:$Z$4,AD$4,$E41:$Z41) -> 33568.516 | AE41: =SUMIF($E$4:$Z$4,AE$4,$E41:$Z41) -> 34870.094 | AF41: =SUMIF($E$4:$Z$4,AF$4,$E41:$Z41) -> 36222.139 | AG41: =SUMIF($E$4:$Z$4,AG$4,$E41:$Z41) -> 37626.608
B42: Other assets | E42: ='Quarterly Historical Financials'!AB53 -> 6363787 | F42: ='Quarterly Historical Financials'!AC53 -> 5017670.6 | G42: =Assumptions!N171 -> 5112929.4 | H42: =Assumptions!O171 -> 5209996.7 | I42: =Assumptions!P171 -> 5308906.7 | J42: =Assumptions!Q171 -> 5409694.6 | K42: =Assumptions!R171 -> 5512395.8 | L42: =Assumptions!S171 -> 5617046.8 | M42: =Assumptions!T171 -> 5723684.6 | N42: =Assumptions!U171 -> 5832346.8 | ... Z42: =Assumptions!AG171 -> 7308952.5 | AB42: =SUMIF($E$4:$Z$4,AB$4,$E42:$Z42) -> 5017670.6 | AC42: =SUMIF($E$4:$Z$4,AC$4,$E42:$Z42) -> 5409694.6 | AD42: =SUMIF($E$4:$Z$4,AD$4,$E42:$Z42) -> 5832346.8 | AE42: =SUMIF($E$4:$Z$4,AE$4,$E42:$Z42) -> 6288020.4 | AF42: =SUMIF($E$4:$Z$4,AF$4,$E42:$Z42) -> 6779295.1 | AG42: =SUMIF($E$4:$Z$4,AG$4,$E42:$Z42) -> 7308952.5
B43: Property and equipment | E43: ='Quarterly Historical Financials'!AB54 -> 583596 | F43: ='Quarterly Historical Financials'!AC54 -> 568767.64 | G43: =Assumptions!N154 -> 569276.49 | H43: =Assumptions!O154 -> 569785.8 | I43: =Assumptions!P154 -> 570295.56 | J43: =Assumptions!Q154 -> 570805.78 | K43: =Assumptions!R154 -> 571316.45 | L43: =Assumptions!S154 -> 571827.58 | M43: =Assumptions!T154 -> 572339.17 | N43: =Assumptions!U154 -> 572851.22 | ... Z43: =Assumptions!AG154 -> 579031.63 | AB43: =SUMIF($E$4:$Z$4,AB$4,$E43:$Z43) -> 568767.64 | AC43: =SUMIF($E$4:$Z$4,AC$4,$E43:$Z43) -> 570805.78 | AD43: =SUMIF($E$4:$Z$4,AD$4,$E43:$Z43) -> 572851.22 | AE43: =SUMIF($E$4:$Z$4,AE$4,$E43:$Z43) -> 574903.99 | AF43: =SUMIF($E$4:$Z$4,AF$4,$E43:$Z43) -> 576964.12 | AG43: =SUMIF($E$4:$Z$4,AG$4,$E43:$Z43) -> 579031.63
...

Sheet Assumptions
D1: FIRST ATLANTIC BANK LIMITED
D2: Scenario>>>>> | E2: All amounts in thousands of GHS unless stated otherwise | J2: Year | M2: =YEAR(M4) -> 2025 | N2: =YEAR(N4) -> 2026 | O2: =YEAR(O4) -> 2026 | P2: =YEAR(P4) -> 2026 | Q2: =YEAR(Q4) -> 2026 | R2: =YEAR(R4) -> 2027 | S2: =YEAR(S4) -> 2027 | T2: =YEAR(T4) -> 2027 | ... AG2: =YEAR(AG4) -> 2030 | AI2: =YEAR(AI4) -> 2025 | AJ2: =YEAR(AJ4) -> 2026 | AK2: =YEAR(AK4) -> 2027 | AL2: =YEAR(AL4) -> 2028 | AM2: =YEAR(AM4) -> 2029 | AN2: =YEAR(AN4) -> 2030
D3: Conservative | F3: 1 | J3: Start Date | M3: =H8 -> 45931 | N3: =M4+1 -> 46023 | O3: =N4+1 -> 46113 | P3: =O4+1 -> 46204 | Q3: =P4+1 -> 46296 | R3: =Q4+1 -> 46388 | S3: =R4+1 -> 46478 | T3: =S4+1 -> 46569 | U3: =T4+1 -> 46661 | ... AG3: =AF4+1 -> 47757 | AI3: =M3 -> 45931 | AJ3: =AI4+1 -> 46023 | AK3: =AJ4+1 -> 46388 | AL3: =AK4+1 -> 46753 | AM3: =AL4+1 -> 47119 | AN3: =AM4+1 -> 47484
D4: Moderate | F4: 2 | G4: 1 | J4: End Date | M4: =EOMONTH(M3,2) -> 46022 | N4: =EOMONTH(N3,2) -> 46112 | O4: =EOMONTH(O3,2) -> 46203 | P4: =EOMONTH(P3,2) -> 46295 | Q4: =EOMONTH(Q3,2) -> 46387 | R4: =EOMONTH(R3,2) -> 46477 | S4: =EOMONTH(S3,2) -> 46568 | T4: =EOMONTH(T3,2) -> 46660 | ... AG4: =EOMONTH(AG3,2) -> 47848 | AI4: =EOMONTH(AI3,2) -> 46022 | AJ4: =EOMONTH(AJ3,11) -> 46387 | AK4: =EOMONTH(AK3,11) -> 46752 | AL4: =EOMONTH(AL3,11) -> 47118 | AM4: =EOMONTH(AM3,11) -> 47483 | AN4: =EOMONTH(AN3,11) -> 47848
D5: Optimistic | F5: 3 | J5: Period | M5: =M4-M3+1 -> 92 | N5: =N4-N3+1 -> 90 | O5: =O4-O3+1 -> 91 | P5: =P4-P3+1 -> 92 | Q5: =Q4-Q3+1 -> 92 | R5: =R4-R3+1 -> 90 | S5: =S4-S3+1 -> 91 | T5: =T4-T3+1 -> 92 | ... AG5: =AG4-AG3+1 -> 92 | AI5: =AI4-AI3+1 -> 92 | AJ5: =AJ4-AJ3+1 -> 365 | AK5: =AK4-AK3+1 -> 365 | AL5: =AL4-AL3+1 -> 366 | AM5: =AM4-AM3+1 -> 365 | AN5: =AN4-AN3+1 -> 365
B7: 1 | D7: General Model Assumptions
D8: Start Date | H8: ='Quarterly Historical Financials'!AB4+1 -> 45931
B13: 2 | D13: Interest Assumptions
D14: Interest Income | E14: Unit | F14: Conservative | G14: Moderate | H14: Optimistic | I14: Live
D15: Interest Rate | E15: % of gen. assets | F15: =AVERAGE('Quarterly Historical Financials'!$D94:$D95) -> 0.027623396 | G15: =AVERAGE('Quarterly Historical Financials'!$D93:$D95) -> 0.029276024 | H15: =AVERAGE('Quarterly Historical Financials'!$D92:$D95) -> 0.034839546 | I15: =CHOOSE($G$4,F15,G15,H15) -> 0.027623396
K16: Cash and cash equivalents | M16: ='Quarterly Financial Projections'!F33 -> 8162460.5 | N16: ='Quarterly Financial Projections'!G33 -> 6892248.5 | O16: ='Quarterly Financial Projections'!H33 -> 7295215.3 | P16: ='Quarterly Financial Projections'!I33 -> 7716511.2 | Q16: ='Quarterly Financial Projections'!J33 -> 8156889.4 | R16: ='Quarterly Financial Projections'!K33 -> 8617133.3 | S16: ='Quarterly Financial Projections'!L33 -> 9098058 | T16: ='Quarterly Financial Projections'!M33 -> 9600511.4 | ... AG16: ='Quarterly Financial Projections'!Z33 -> 18546972 | AI16: =SUMIF($M$4:$AG$4,AI$4,$M16:$AG16) -> 8162460.5 | AJ16: =SUMIF($M$4:$AG$4,AJ$4,$M16:$AG16) -> 8156889.4 | AK16: =SUMIF($M$4:$AG$4,AK$4,$M16:$AG16) -> 10125376 | AL16: =SUMIF($M$4:$AG$4,AL$4,$M16:$AG16) -> 12467879 | AM16: =SUMIF($M$4:$AG$4,AM$4,$M16:$AG16) -> 15249551 | AN16: =SUMIF($M$4:$AG$4,AN$4,$M16:$AG16) -> 18546972
K17: Trading assets (Investment securities) | M17: =M99 -> 3178870.4 | N17: =N99 -> 4086092.7 | O17: =O99 -> 4232624.4 | P17: =P99 -> 4384410.9 | Q17: =Q99 -> 4541640.6 | R17: =R99 -> 4704508.7 | S17: =S99 -> 4873217.5 | T17: =T99 -> 5047976.3 | ... AG17: =AG99 -> 7980627.2 | AI17: =SUMIF($M$4:$AG$4,AI$4,$M17:$AG17) -> 3178870.4 | AJ17: =SUMIF($M$4:$AG$4,AJ$4,$M17:$AG17) -> 4541640.6 | AK17: =SUMIF($M$4:$AG$4,AK$4,$M17:$AG17) -> 5229002.2 | AL17: =SUMIF($M$4:$AG$4,AL$4,$M17:$AG17) -> 6020393.7 | AM17: =SUMIF($M$4:$AG$4,AM$4,$M17:$AG17) -> 6931559.6 | AN17: =SUMIF($M$4:$AG$4,AN$4,$M17:$AG17) -> 7980627.2
K18: Loans and advances to customers | M18: =M94 -> 1947024.8 | N18: =N94 -> 2936526.5 | O18: =O94 -> 3041833.5 | P18: =P94 -> 3150917 | Q18: =Q94 -> 3263912.3 | R18: =R94 -> 3380959.7 | S18: =S94 -> 3502204.6 | T18: =T94 -> 3627797.4 | ... AG18: =AG94 -> 5735387.1 | AI18: =SUMIF($M$4:$AG$4,AI$4,$M18:$AG18) -> 1947024.8 | AJ18: =SUMIF($M$4:$AG$4,AJ$4,$M18:$AG18) -> 3263912.3 | AK18: =SUMIF($M$4:$AG$4,AK$4,$M18:$AG18) -> 3757894.1 | AL18: =SUMIF($M$4:$AG$4,AL$4,$M18:$AG18) -> 4326638.5 | AM18: =SUMIF($M$4:$AG$4,AM$4,$M18:$AG18) -> 4981460.3 | AN18: =SUMIF($M$4:$AG$4,AN$4,$M18:$AG18) -> 5735387.1
K19: Total Income generating assets | M19: =SUM(M16:M18) -> 13288356 | N19: =SUM(N16:N18) -> 13914868 | O19: =SUM(O16:O18) -> 14569673 | P19: =SUM(P16:P18) -> 15251839 | Q19: =SUM(Q16:Q18) -> 15962442 | R19: =SUM(R16:R18) -> 16702602 | S19: =SUM(S16:S18) -> 17473480 | T19: =SUM(T16:T18) -> 18276285 | ... AG19: =SUM(AG16:AG18) -> 32262986 | AI19: =SUM(AI16:AI18) -> 13288356 | AJ19: =SUM(AJ16:AJ18) -> 15962442 | AK19: =SUM(AK16:AK18) -> 19112272 | AL19: =SUM(AL16:AL18) -> 22814911 | AM19: =SUM(AM16:AM18) -> 27162571 | AN19: =SUM(AN16:AN18) -> 32262986
K21: Interest Income | M21: ='Quarterly Historical Financials'!AC9 -> 681759.57 | N21: =N19*$I$15 -> 384375.91 | O21: =O19*$I$15 -> 402463.86 | P21: =P19*$I$15 -> 421307.6 | Q21: =Q19*$I$15 -> 440936.87 | R21: =R19*$I$15 -> 461382.59 | S21: =S19*$I$15 -> 482676.87 | T21: =T19*$I$15 -> 504853.07 | U21: =U19*$I$15 -> 527945.88 | ... AG21: =AG19*$I$15 -> 891213.25 | AI21: =SUMIF($M$2:$AG$2,AI$2,$M21:$AG21) -> 681759.57 | AJ21: =SUMIF($M$2:$AG$2,AJ$2,$M21:$AG21) -> 1649084.2 | AK21: =SUMIF($M$2:$AG$2,AK$2,$M21:$AG21) -> 1976858.4 | AL21: =SUMIF($M$2:$AG$2,AL$2,$M21:$AG21) -> 2362334.8 | AM21: =SUMIF($M$2:$AG$2,AM$2,$M21:$AG21) -> 2815137.9 | AN21: =SUMIF($M$2:$AG$2,AN$2,$M21:$AG21) -> 3346506.3
D24: Interest Expense | E24: Unit | F24: Conservative | G24: Moderate | H24: Optimistic | I24: Live
D25: Interest Rate | E25: % of incur. liab. | F25: =AVERAGE('Quarterly Historical Financials'!$D107:$D108) -> -0.0060437957 | G25: =AVERAGE('Quarterly Historical Financials'!$D106:$D107)/1.2 -> -0.0061649646 | H25: =AVERAGE('Quarterly Historical Financials'!$D105:$D106)/1.3 -> -0.0069636484 | I25: =CHOOSE($G$4,F25,G25,H25) -> -0.0060437957
K26: Total Deposits | M26: =M85 -> 16642450 | N26: =N85 -> 17239266 | O26: =O85 -> 17857485 | P26: =P85 -> 18497873 | Q26: =Q85 -> 19161227 | R26: =R85 -> 19848369 | S26: =S85 -> 20560153 | T26: =T85 -> 21297463 | ... AG26: =AG85 -> 33670346 | AI26: =SUMIF($M$4:$AG$4,AI$4,$M26:$AG26) -> 16642450 | AJ26: =SUMIF($M$4:$AG$4,AJ$4,$M26:$AG26) -> 19161227 | AK26: =SUMIF($M$4:$AG$4,AK$4,$M26:$AG26) -> 22061213 | AL26: =SUMIF($M$4:$AG$4,AL$4,$M26:$AG26) -> 25400101 | AM26: =SUMIF($M$4:$AG$4,AM$4,$M26:$AG26) -> 29244319 | AN26: =SUMIF($M$4:$AG$4,AN$4,$M26:$AG26) -> 33670346
K27: Total expense incurring liabilities | M27: =SUM(M26:M26) -> 16642450 | N27: =SUM(N26:N26) -> 17239266 | O27: =SUM(O26:O26) -> 17857485 | P27: =SUM(P26:P26) -> 18497873 | Q27: =SUM(Q26:Q26) -> 19161227 | R27: =SUM(R26:R26) -> 19848369 | S27: =SUM(S26:S26) -> 20560153 | T27: =SUM(T26:T26) -> 21297463 | ... AG27: =SUM(AG26:AG26) -> 33670346 | AI27: =SUM(AI26:AI26) -> 16642450 | AJ27: =SUM(AJ26:AJ26) -> 19161227 | AK27: =SUM(AK26:AK26) -> 22061213 | AL27: =SUM(AL26:AL26) -> 25400101 | AM27: =SUM(AM26:AM26) -> 29244319 | AN27: =SUM(AN26:AN26) -> 33670346
K29: Interest Expense | M29: ='Quarterly Historical Financials'!AC10 -> -102371.52 | N29: =N27*$I25 -> -104190.6 | O29: =O27*$I25 -> -107926.99 | P29: =P27*$I25 -> -111797.37 | Q29: =Q27*$I25 -> -115806.54 | R29: =R27*$I25 -> -119959.49 | S29: =S27*$I25 -> -124261.37 | T29: =T27*$I25 -> -128717.51 | U29: =U27*$I25 -> -133333.46 | ... AG29: =AG27*$I25 -> -203496.69 | AI29: =SUMIF($M$2:$AG$2,AI$2,$M29:$AG29) -> -102371.52 | AJ29: =SUMIF($M$2:$AG$2,AJ$2,$M29:$AG29) -> -439721.5 | AK29: =SUMIF($M$2:$AG$2,AK$2,$M29:$AG29) -> -506271.83 | AL29: =SUMIF($M$2:$AG$2,AL$2,$M29:$AG29) -> -582894.33 | AM29: =SUMIF($M$2:$AG$2,AM$2,$M29:$AG29) -> -671113.38 | AN29: =SUMIF($M$2:$AG$2,AN$2,$M29:$AG29) -> -772684.07
B32: 3 | D32: Fees & Commissions Assumptions
D33: Fees & Commission Income | E33: Unit | F33: Conservative | G33: Moderate | H33: Optimistic | I33: Live
D34: Income rate | E34: % of gen. assets | F34: =AVERAGE('Quarterly Historical Financials'!$D124:$D125) -> 0.0039583729 | G34: =AVERAGE('Quarterly Historical Financials'!$D123:$D124) -> 0.0055470728 | H34: =AVERAGE('Quarterly Historical Financials'!$D122:$D123)/1.2 -> 0.0072811603 | I34: =CHOOSE($G$4,F34,G34,H34) -> 0.0039583729
K35: Loan Disbursement | M35: =M90 -> 608840.22 | N35: =N90 -> 1015508.2 | O35: =O90 -> 144530.34 | P35: =P90 -> 149713.36 | Q35: =Q90 -> 155082.24 | R35: =R90 -> 160643.66 | S35: =S90 -> 166404.51 | T35: =T90 -> 172371.96 | ... AG35: =AG90 -> 272512.44 | AI35: =SUMIF($M$2:$AG$2,AI$2,$M35:$AG35) -> 608840.22 | AJ35: =SUMIF($M$2:$AG$2,AJ$2,$M35:$AG35) -> 1464834.1 | AK35: =SUMIF($M$2:$AG$2,AK$2,$M35:$AG35) -> 677973.53 | AL35: =SUMIF($M$2:$AG$2,AL$2,$M35:$AG35) -> 780582.48 | AM35: =SUMIF($M$2:$AG$2,AM$2,$M35:$AG35) -> 898720.95 | AN35: =SUMIF($M$2:$AG$2,AN$2,$M35:$AG35) -> 1034739.3
