Workbook
Name Share_Price: [1]EV!$E$2

Sheet FS
B1: TOTALENERGIES
B2: Income Statement | C2: 2020 | D2: 2021 | E2: 2022 | F2: 2023 | G2: 2024
B3: Revenue | C3: 2384158 | D3: 3218179 | E3: 5672210 | F3: 6041455 | G3: 6995488
B4: Cost of sales | C4: -2039837 | D4: -2896838 | E4: -5188233 | F4: -5429160 | G4: -6213947 | I4: =C5/C58 -> 0.97593059
B5: Gross profit | C5: 344321 | D5: 321341 | E5: 483977 | F5: =SUM(F3:F4) -> 612295 | G5: =SUM(G3:G4) -> 781541
B6: Other income | C6: 22009 | D6: 27275 | E6: 43031 | F6: 41571 | G6: 67184
B7: Impairment (charge)/release on trade receivables | C7: -20615 | D7: 5274 | E7: -10694 | F7: 7180 | G7: -2591
B8: General, administrative and selling expense | C8: -187631 | D8: -202765 | E8: -275137 | F8: -338826 | G8: -365377
B9: Operating profit before finance income/(costs) | C9: =SUM(C5:C8) -> 158084 | D9: =SUM(D5:D8) -> 151125 | E9: =SUM(E5:E8) -> 241177 | F9: =SUM(F5:F8) -> 322220 | G9: =SUM(G5:G8) -> 480757
B10: Finance income | C10: 1895 | D10: 5601 | E10: 2693 | F10: 3301 | G10: 665
B11: Finance costs | C11: -6783 | D11: -4503 | E11: -25304 | F11: -86257 | G11: -58584
B12: Profit before income tax | C12: =SUM(C9:C11) -> 153196 | D12: =SUM(D9:D11) -> 152223 | E12: =SUM(E9:E11) -> 218566 | F12: =SUM(F9:F11) -> 239264 | G12: =SUM(G9:G11) -> 422838 | I12: =C12/C9 -> 0.96907973 | J12: =D12/D9 -> 1.0072655 | K12: =E12/E9 -> 0.90624728 | L12: =F12/F9 -> 0.74254857
B13: Income tax expense | C13: -39512 | D13: -39479 | E13: -56892 | F13: -69331 | G13: -132202
B14: Profit for the year | C14: =SUM(C12:C13) -> 113684 | D14: =SUM(D12:D13) -> 112744 | E14: =SUM(E12:E13) -> 161674 | F14: 169933 | G14: 290636
B16: Other comprehensive loss: | G16: =G14/G3 -> 0.041546208
B17: Items that may be reclassified subsequently to P/L:
B18: Exchange difference on translation of foreign operation
B19: Related income tax
B21: Items that will not be reclassified to profit or loss:
B22: Remeasurement loss on employee benefit | C22: -3508 | D22: -2141 | E22: -5218 | F22: -2388 | G22: -5673
B23: Related income tax | C23: 877 | D23: 535 | E23: 1305 | F23: 597 | G23: 1418
B24: Comprehensive loss for the year-net tax | C24: =SUM(C22:C23) -> -2631 | D24: =SUM(D22:D23) -> -1606 | E24: =SUM(E22:E23) -> -3913 | F24: =SUM(F22:F23) -> -1791 | G24: =SUM(G22:G23) -> -4255
B25: Total comprehensive income | C25: =SUM(C14,C22:C23) -> 111053 | D25: =SUM(D14,D22:D23) -> 111138 | E25: =SUM(E14,E22:E23) -> 157761 | F25: =SUM(F14,F24) -> 168142 | G25: =SUM(G14,G24) -> 286381
B27: WASO | C27: 112000 | D27: 112000 | E27: 112000 | F27: 112000 | G27: 112000
B28: Earnings per share:
B29: Basic earnings per share | C29: 1.0162 | D29: 1.0078 | E29: 1.4451 | F29: 1.519 | G29: 2.5979
B30: Diluted earnings per share | C30: 1.0162 | D30: 1.0078 | E30: 1.4451 | F30: 1.519 | G30: 2.5979
B33: Balance Sheet
B34: Assets
B35: Property, plant and equipment | C35: 286613 | D35: 306310 | E35: 363721 | F35: 403572 | G35: 445981
B36: Right-of-use-assets | C36: 74217 | D36: 88518 | E36: 104049 | F36: 113168 | G36: 125042
B37: Intangible assets and goodwill | C37: 13374 | D37: 12852 | E37: 12447 | F37: 12229 | G37: 12144
B38: Investment in associates | C38: 12 | D38: 12 | E38: 12 | F38: 12 | G38: 12
B39: Deferred tax assets | C39: 4791 | D39: 4098 | E39: 5087 | F39: 4505
B40: Long term prepayments | C40: 671 | D40: 671 | E40: 671 | F40: 671 | G40: 1300
B41: Investment in subsidiary | C41: 274 | D41: 274 | E41: 274 | F41: 274 | G41: 274
B42: Related party loan | C42: 1639 | D42: 1774 | E42: 2972 | F42: 3308 | G42: 4084
B43: Total Non Current Assets | C43: =SUM(C35:C42) -> 381591 | D43: =SUM(D35:D42) -> 414509 | E43: =SUM(E35:E42) -> 489233 | F43: =SUM(F35:F42) -> 537739 | G43: =SUM(G35:G42) -> 588837
B44: Inventories | C44: 108337 | D44: 182581 | E44: 358529 | F44: 413334 | G44: 362069
B45: Current tax asset | C45: 15335 | D45: 18091 | E45: 24168 | F45: 22904 | G45: 8868 | H45: =G3/AVERAGE(F46,G46) -> 11.306305
...

Sheet Common Size
A1: Income Statement | B1: 2020 | C1: 2021 | D1: 2022 | E1: 2023 | F1: 2024
A2: Revenue | B2: =FS!C3/FS!C3 -> 1 | C2: =FS!D3/FS!D3 -> 1 | D2: =FS!E3/FS!E3 -> 1 | E2: =FS!F3/FS!F3 -> 1 | F2: =FS!G3/FS!G3 -> 1
A3: Cost of sales | B3: =FS!C4/FS!C$3 -> -0.85557962 | C3: =FS!D4/FS!D$3 -> -0.90014819 | D3: =FS!E4/FS!E$3 -> -0.91467576 | E3: =FS!F4/FS!F$3 -> -0.89865107 | F3: =FS!G4/FS!G$3 -> -0.88827927
A4: Gross profit | B4: =FS!C5/FS!C$3 -> 0.14442038 | C4: =FS!D5/FS!D$3 -> 0.099851811 | D4: =FS!E5/FS!E$3 -> 0.085324239 | E4: =FS!F5/FS!F$3 -> 0.10134893 | F4: =FS!G5/FS!G$3 -> 0.11172073
A5: Other income | B5: =FS!C6/FS!C$3 -> 0.0092313513 | C5: =FS!D6/FS!D$3 -> 0.0084752899 | D5: =FS!E6/FS!E$3 -> 0.0075862847 | E5: =FS!F6/FS!F$3 -> 0.0068809583 | F5: =FS!G6/FS!G$3 -> 0.0096039047
A6: Impairment (charge)/release on trade receivables | B6: =FS!C7/FS!C$3 -> -0.0086466585 | C6: =FS!D7/FS!D$3 -> 0.001638815 | D6: =FS!E7/FS!E$3 -> -0.0018853322 | E6: =FS!F7/FS!F$3 -> 0.0011884554 | F6: =FS!G7/FS!G$3 -> -0.00037038159
A7: General, administrative and selling expense | B7: =FS!C8/FS!C$3 -> -0.078699063 | C7: =FS!D8/FS!D$3 -> -0.063006129 | D7: =FS!E8/FS!E$3 -> -0.048506138 | E7: =FS!F8/FS!F$3 -> -0.05608351 | F7: =FS!G8/FS!G$3 -> -0.05223038
A8: Operating profit before finance income/(costs) | B8: =FS!C9/FS!C$3 -> 0.066306008 | C8: =FS!D9/FS!D$3 -> 0.046959787 | D8: =FS!E9/FS!E$3 -> 0.042519053 | E8: =FS!F9/FS!F$3 -> 0.053334834 | F8: =FS!G9/FS!G$3 -> 0.068723869
A9: Finance income | B9: =FS!C10/FS!C$3 -> 0.00079482987 | C9: =FS!D10/FS!D$3 -> 0.0017404253 | D9: =FS!E10/FS!E$3 -> 0.00047477086 | E9: =FS!F10/FS!F$3 -> 0.00054639156 | F9: =FS!G10/FS!G$3 -> 9.5061274e-05
A10: Finance costs | B10: =FS!C11/FS!C$3 -> -0.0028450296 | C10: =FS!D11/FS!D$3 -> -0.0013992385 | D10: =FS!E11/FS!E$3 -> -0.0044610478 | E10: =FS!F11/FS!F$3 -> -0.014277521 | F10: =FS!G11/FS!G$3 -> -0.0083745408
A11: Profit before income tax | B11: =FS!C12/FS!C$3 -> 0.064255809 | C11: =FS!D12/FS!D$3 -> 0.047300974 | D11: =FS!E12/FS!E$3 -> 0.038532776 | E11: =FS!F12/FS!F$3 -> 0.039603705 | F11: =FS!G12/FS!G$3 -> 0.060444389
A12: Income tax expense | B12: =FS!C13/FS!C$3 -> -0.016572727 | C12: =FS!D13/FS!D$3 -> -0.012267497 | D12: =FS!E13/FS!E$3 -> -0.010029953 | E12: =FS!F13/FS!F$3 -> -0.011475878 | F12: =FS!G13/FS!G$3 -> -0.018898181
A13: Profit for the year | B13: =FS!C14/FS!C$3 -> 0.047683081 | C13: =FS!D14/FS!D$3 -> 0.035033477 | D13: =FS!E14/FS!E$3 -> 0.028502823 | E13: =FS!F14/FS!F$3 -> 0.028127827 | F13: =FS!G14/FS!G$3 -> 0.041546208
A15: Other comprehensive loss:
A16: Items that may be reclassified subsequently to P/L:
A17: Exchange difference on translation of foreign operation
A18: Related income tax
A20: Items that will not be reclassified to profit or loss:
A21: Remeasurement loss on employee benefit | B21: =FS!C22/FS!C$3 -> -0.001471379 | C21: =FS!D22/FS!D$3 -> -0.00066528307 | D21: =FS!E22/FS!E$3 -> -0.00091992363 | E21: =FS!F22/FS!F$3 -> -0.00039526902 | F21: =FS!G22/FS!G$3 -> -0.00081095129
A22: Related income tax | B22: =FS!C23/FS!C$3 -> 0.00036784475 | C22: =FS!D23/FS!D$3 -> 0.00016624308 | D22: =FS!E23/FS!E$3 -> 0.00023006906 | E22: =FS!F23/FS!F$3 -> 9.8817255e-05 | F22: =FS!G23/FS!G$3 -> 0.00020270208
A23: Comprehensive loss for the year-net tax | B23: =FS!C24/FS!C$3 -> -0.0011035342 | C23: =FS!D24/FS!D$3 -> -0.00049903999 | D23: =FS!E24/FS!E$3 -> -0.00068985457 | E23: =FS!F24/FS!F$3 -> -0.00029645177 | F23: =FS!G24/FS!G$3 -> -0.0006082492
A24: Total comprehensive income | B24: =FS!C25/FS!C$3 -> 0.046579547 | C24: =FS!D25/FS!D$3 -> 0.034534437 | D24: =FS!E25/FS!E$3 -> 0.027812969 | E24: =FS!F25/FS!F$3 -> 0.027831375 | F24: =FS!G25/FS!G$3 -> 0.040937959
A26: WASO | B26: 112000 | C26: 112000 | D26: 112000 | E26: 112000 | F26: 112000
A27: Earnings per share:
A28: Basic earnings per share | B28: 1.0162 | C28: 1.0078 | D28: 1.4451 | E28: 1.519 | F28: 2.5979
A29: Diluted earnings per share | B29: 1.0162 | C29: 1.0078 | D29: 1.4451 | E29: 1.519 | F29: 2.5979
A32: Balance Sheet
A33: Assets
A34: Property, plant and equipment | B34: =FS!C35/FS!C$51 -> 0.341005 | C34: =FS!D35/FS!D$51 -> 0.28823886 | D34: =FS!E35/FS!E$51 -> 0.21898095 | E34: =FS!F35/FS!F$51 -> 0.21987465 | F34: =FS!G35/FS!G$51 -> 0.24982593
A35: Right-of-use-assets | B35: =FS!C36/FS!C$51 -> 0.088301537 | C35: =FS!D36/FS!D$51 -> 0.083295772 | D35: =FS!E36/FS!E$51 -> 0.062643478 | E35: =FS!F36/FS!F$51 -> 0.061656344 | F35: =FS!G36/FS!G$51 -> 0.070044987
A36: Intangible assets and goodwill | B36: =FS!C37/FS!C$51 -> 0.015912052 | C36: =FS!D37/FS!D$51 -> 0.01209378 | D36: =FS!E37/FS!E$51 -> 0.0074938093 | E36: =FS!F37/FS!F$51 -> 0.0066626205 | F36: =FS!G37/FS!G$51 -> 0.0068027249
A37: Investment in associates | B37: =FS!C38/FS!C$51 -> 1.4277301e-05 | C37: =FS!D38/FS!D$51 -> 1.1292045e-05 | D37: =FS!E38/FS!E$51 -> 7.2246897e-06 | E37: =FS!F38/FS!F$51 -> 6.5378564e-06 | F37: =FS!G38/FS!G$51 -> 6.7220602e-06
A38: Deferred tax assets | B38: =FS!C39/FS!C$51 -> 0.0057002124 | C38: =FS!D39/FS!D$51 -> 0.0038562334 | D38: =FS!E39/FS!E$51 -> 0.0030626664 | E38: =FS!F39/FS!F$51 -> 0.0024544202 | F38: =FS!G39/FS!G$51 -> 0
A39: Long term prepayments | B39: =FS!C40/FS!C$51 -> 0.00079833907 | C39: =FS!D40/FS!D$51 -> 0.00063141353 | D39: =FS!E40/FS!E$51 -> 0.00040398056 | E39: =FS!F40/FS!F$51 -> 0.00036557514 | F39: =FS!G40/FS!G$51 -> 0.00072822319
A40: Investment in subsidiary | B40: =FS!C41/FS!C$51 -> 0.00032599837 | C40: =FS!D41/FS!D$51 -> 0.00025783503 | D40: =FS!E41/FS!E$51 -> 0.00016496375 | E40: =FS!F41/FS!F$51 -> 0.00014928105 | F40: =FS!G41/FS!G$51 -> 0.00015348704
A41: Related party loan | B41: =FS!C42/FS!C$51 -> 0.0019500413 | C41: =FS!D42/FS!D$51 -> 0.0016693407 | D41: =FS!E42/FS!E$51 -> 0.0017893148 | E41: =FS!F42/FS!F$51 -> 0.0018022691 | F41: =FS!G42/FS!G$51 -> 0.0022877411
A42: Total Non Current Assets | B42: =FS!C43/FS!C$51 -> 0.45400746 | C42: =FS!D43/FS!D$51 -> 0.39005453 | D42: =FS!E43/FS!E$51 -> 0.29454638 | E42: =FS!F43/FS!F$51 -> 0.2929717 | F42: =FS!G43/FS!G$51 -> 0.32984981
A43: Inventories | B43: =FS!C44/FS!C$51 -> 0.12889666 | C43: =FS!D44/FS!D$51 -> 0.17180941 | D43: =FS!E44/FS!E$51 -> 0.21585506 | E43: =FS!F44/FS!F$51 -> 0.22519319 | F43: =FS!G44/FS!G$51 -> 0.2028208
A44: Current tax asset | B44: =FS!C45/FS!C$51 -> 0.018245201 | C44: =FS!D45/FS!D$51 -> 0.017023699 | D44: =FS!E45/FS!E$51 -> 0.014550525 | E44: =FS!F45/FS!F$51 -> 0.012478589 | F44: =FS!G45/FS!G$51 -> 0.0049676025
A45: Trade and other receivables | B45: =FS!C46/FS!C$51 -> 0.27548409 | C45: =FS!D46/FS!D$51 -> 0.27634646 | D45: =FS!E46/FS!E$51 -> 0.34647143 | E45: =FS!F46/FS!F$51 -> 0.32308452 | F45: =FS!G46/FS!G$51 -> 0.36099648
...

Sheet Ratios
A1: Financial Ratios
A2: Days In Year | B2: 365
B4: 2020 | C4: 2021 | D4: 2022 | E4: 2023 | F4: 2024 | G4: Average
A5: Profitability Ratios
A6: Gross Profit Margin | B6: =FS!C5/FS!C$3 -> 0.14442038 | C6: =FS!D5/FS!D$3 -> 0.099851811 | D6: =FS!E5/FS!E$3 -> 0.085324239 | E6: =FS!F5/FS!F$3 -> 0.10134893 | F6: =FS!G5/FS!G$3 -> 0.11172073 | G6: =AVERAGE(B6:F6) -> 0.10853322
A7: Operating Profit Margin | B7: =FS!C9/FS!C3 -> 0.066306008 | C7: =FS!D9/FS!D3 -> 0.046959787 | D7: =FS!E9/FS!E3 -> 0.042519053 | E7: =FS!F9/FS!F3 -> 0.053334834 | F7: =FS!G9/FS!G3 -> 0.068723869 | G7: =AVERAGE(B7:F7) -> 0.05556871
A8: Return on Assets | B8: =FS!C14/FS!C51 -> 0.13525839 | C8: =FS!D14/FS!D51 -> 0.10609253 | D8: =FS!E14/FS!E51 -> 0.09733704 | E8: =FS!F14/FS!F51 -> 0.092583129 | F8: =FS!G14/FS!G51 -> 0.16280606 | G8: =AVERAGE(B8:F8) -> 0.11881543
A9: Return on Assets(Operating profit) | B9: =FS!C9/FS!C51 -> 0.1880844 | C9: =FS!D9/FS!D51 -> 0.14220919 | D9: =FS!E9/FS!E51 -> 0.14520241 | E9: =FS!F9/FS!F51 -> 0.17555234 | F9: =FS!G9/FS!G51 -> 0.26930646 | G9: =AVERAGE(B9:F9) -> 0.18407096
A10: Return on Equity | B10: =FS!C14/FS!C58 -> 0.32222169 | C10: =FS!D14/FS!D58 -> 0.25812064 | D10: =FS!E14/FS!E58 -> 0.3373233 | E10: =FS!F14/FS!F58 -> 0.32351491 | F10: =FS!G14/FS!G58 -> 0.44235488 | G10: =AVERAGE(B10:F10) -> 0.33670708
A11: Return on Equity(Operating profit) | B11: =FS!C9/FS!C58 -> 0.44806739 | C11: =FS!D9/FS!D58 -> 0.34599165 | D11: =FS!E9/FS!E58 -> 0.50320164 | E11: =FS!F9/FS!F58 -> 0.61343573 | F11: =FS!G9/FS!G58 -> 0.73172354 | G11: =AVERAGE(B11:F11) -> 0.52848399
A13: Liquidity Ratios
A14: Current Ratio | B14: =FS!C50/FS!C66 -> 0.97590146 | C14: =FS!D50/FS!D66 -> 1.0841896 | D14: =FS!E50/FS!E66 -> 1.0147325 | E14: =FS!F50/FS!F66 -> 1.0112437 | F14: =FS!G50/FS!G66 -> 1.0901425 | G14: =AVERAGE(B14:F14) -> 1.0352419
A15: Quick Ratio | B15: =(FS!C50-FS!C44)/FS!C66 -> 0.74551289 | C15: =(FS!D50-FS!D44)/FS!D66 -> 0.77879512 | D15: =(FS!E50-FS!E44)/FS!E66 -> 0.70424412 | E15: =(FS!F50-FS!F44)/FS!F66 -> 0.68915589 | F15: =(FS!G50-FS!G44)/FS!G66 -> 0.76021112 | G15: =AVERAGE(B15:F15) -> 0.73558383
A16: Cash Ratio | B16: =FS!C48/FS!C66 -> 0.19103812 | C16: =FS!D48/FS!D66 -> 0.2376989 | D16: =FS!E48/FS!E66 -> 0.17274747 | E16: =FS!F48/FS!F66 -> 0.19984088 | F16: =FS!G48/FS!G66 -> 0.15208578 | G16: =AVERAGE(B16:F16) -> 0.19068223
A18: Efficiency Ratios
A19: Inventory Turnover | B19: =-(FS!C4/FS!C44) -> 18.828627 | C19: =-(FS!D4/AVERAGE(FS!C44,FS!D44)) -> 19.915151 | D19: =-(FS!E4/AVERAGE(FS!D44,FS!E44)) -> 19.17626 | E19: =-(FS!F4/AVERAGE(FS!E44,FS!F44)) -> 14.067678 | F19: =-(FS!G4/AVERAGE(FS!F44,FS!G44)) -> 16.027658 | G19: =AVERAGE(B19:F19) -> 17.603075
A20: Inventory Days | B20: =$B$2/B19 -> 19.385375 | C20: =$B$2/C19 -> 18.327754 | D20: =$B$2/D19 -> 19.033951 | E20: =$B$2/E19 -> 25.946002 | F20: =$B$2/F19 -> 22.773134 | G20: =AVERAGE(B20:F20) -> 21.093243
A21: Receivables Turnover | B21: =FS!C3/FS!C46 -> 10.296826 | C21: =FS!D3/AVERAGE(FS!C46,FS!D46) -> 12.254711 | D21: =FS!E3/AVERAGE(FS!D46,FS!E46) -> 13.0523 | E21: =FS!F3/AVERAGE(FS!E46,FS!F46) -> 10.340628 | F21: =FS!G3/AVERAGE(FS!F46,FS!G46) -> 11.306305 | G21: =AVERAGE(B21:F21) -> 11.450154
A22: Receivables Days | B22: =$B$2/B21 -> 35.447816 | C22: =$B$2/C21 -> 29.784464 | D22: =$B$2/D21 -> 27.964419 | E22: =$B$2/E21 -> 35.297663 | F22: =$B$2/F21 -> 32.282872 | G22: =AVERAGE(B22:F22) -> 32.155447
A23: Asset Turnover | B23: =FS!C14/FS!C51 -> 0.13525839 | C23: =FS!D14/AVEDEV(FS!C51,FS!D51) -> 1.0147975 | D23: =FS!E14/AVEDEV(FS!D51,FS!E51) -> 0.54046627 | E23: =FS!F14/AVEDEV(FS!E51,FS!F51) -> 1.9477343 | F23: =FS!G14/AVEDEV(FS!F51,FS!G51) -> 11.556793 | G23: =AVERAGE(B23:F23) -> 3.0390098
A24: Payable Turnover | B24: =FS!C3/FS!C46 -> 10.296826 | C24: =FS!D3/FS!D46 -> 10.958413 | D24: =FS!E3/FS!E46 -> 9.8565021 | E24: =FS!F3/FS!F46 -> 10.187779 | F24: =FS!G3/FS!G46 -> 10.855159 | G24: =AVERAGE(B24:F24) -> 10.430936
A25: Payable Days | B25: =$B$2/B24 -> 35.447816 | C25: =$B$2/C24 -> 33.307743 | D25: =$B$2/D24 -> 37.031393 | E25: =$B$2/E24 -> 35.827239 | F25: =$B$2/F24 -> 33.624564 | G25: =AVERAGE(B25:F25) -> 35.047751
A26: Cash Conversion Cycle | B26: =SUM(B20,B22)-B25 -> 19.385375 | C26: =SUM(C20,C22)-C25 -> 14.804475 | D26: =SUM(D20,D22)-D25 -> 9.966978 | E26: =SUM(E20,E22)-E25 -> 25.416427 | F26: =SUM(F20,F22)-F25 -> 21.431442 | G26: =AVERAGE(B26:F26) -> 18.200939
A28: Leverage Ratios
A29: Debt-to-equity | B29: =FS!C73/FS!C58 -> 1.3822677 | C29: =FS!D73/FS!D58 -> 1.4329766 | D29: =FS!E73/FS!E58 -> 2.4666201 | E29: =FS!F73/FS!F58 -> 2.4943182 | F29: =FS!G73/FS!G58 -> 1.7170665 | G29: =AVERAGE(B29:F29) -> 1.8986498
A30: Long-term debt-to-equity | B30: =FS!C72/FS!C58 -> 0.049448291 | C30: =FS!D72/FS!D58 -> 0.064227955 | D30: =FS!E72/FS!E58 -> 0.057352097 | E30: =FS!F72/FS!F58 -> 0.051205949 | F30: =FS!G72/FS!G58 -> 0.046787008 | G30: =AVERAGE(B30:F30) -> 0.05380426
A31: Interest Coverage Ratio | B31: =(-FS!C9/FS!C11) -> 23.305912 | C31: =(-FS!D9/FS!D11) -> 33.560959 | D31: =(-FS!E9/FS!E11) -> 9.5311808 | E31: =(-FS!F9/FS!F11) -> 3.7355809 | F31: =(-FS!G9/FS!G11) -> 8.206285 | G31: =AVERAGE(B31:F31) -> 15.667984
A33: Investment Ratios
A34: Dividend Yield | B34: =B35/29.52 -> 0.005207426 | C34: =C35/29.52 -> 0.008215677 | D34: =D35/29.52 -> 0.034862563 | E34: =E35/29.52 -> 0.036947106 | F34: =F35/29.52 -> 0.046769744 | G34: =AVERAGE(B34:F34) -> 0.026400503
A35: Dividend per share | B35: =-(FS!C116/FS!C27) -> 0.15372321 | C35: =-(FS!D116/FS!D27) -> 0.24252679 | D35: =-(FS!E116/FS!E27) -> 1.0291429 | E35: =-(FS!F116/FS!F27) -> 1.0906786 | F35: =-(FS!G116/FS!G27) -> 1.3806429 | G35: =AVERAGE(B35:F35) -> 0.77934286
A36: Earnings per share | B36: =FS!C14/FS!C27 -> 1.0150357 | C36: =FS!D14/FS!D27 -> 1.0066429 | D36: =FS!E14/FS!E27 -> 1.4435179 | E36: =FS!F14/FS!F27 -> 1.5172589 | F36: =FS!G14/FS!G27 -> 2.5949643 | G36: =AVERAGE(B36:F36) -> 1.5154839
A37: Price to Earning | B37: =24.92/B36 -> 24.55086 | C37: =24.92/C36 -> 24.755552 | D37: =24.92/D36 -> 17.263382 | E37: =24.92/E36 -> 16.424355 | F37: =24.92/F36 -> 9.603215 | G37: =AVERAGE(B37:F37) -> 18.519473
A39: Earnings Volatility
A40: STANDARD DEVIATION | F40: 72580.575
A41: MEAN | F41: =AVERAGE(FS!C14:G14) -> 169734.2
A42: CO-EFFICIENT OF VARIATION | F42: =F40/F41 -> 0.42761314
A44: Sales Volatility
A45: STANDARD DEVIATION | F45: 1964762.9
A46: MEAN | F46: =AVERAGE(FS!C3:G3) -> 4862298
A47: CO-EFFICIENT OF VARIATION | F47: =F45/F46 -> 0.40408114

Sheet Adjustment
B1: 2020 | C1: 2021 | D1: 2022 | E1: 2023 | F1: 2024
A2: Revenue | B2: 2384158 | C2: 3218179 | D2: 5672210 | E2: 6041455 | F2: 6995488
A3: Operating Expense | B3: =(FS!C4+Adjustment!B24)+FS!C8 -> -2179401 | C3: =(FS!D4+Adjustment!C24)+FS!D8 -> -3044997 | D3: =(FS!E4+Adjustment!D24)+FS!E8 -> -5403558 | E3: =(FS!F4+Adjustment!E24)+FS!F8 -> -5700083 | F3: =(FS!G4+Adjustment!F24)+FS!G8 -> -6541043
A4: EBITDA | B4: =SUM(B2:B3) -> 204757 | C4: =SUM(C2:C3) -> 173182 | D4: =SUM(D2:D3) -> 268652 | E4: =SUM(E2:E3) -> 341372 | F4: =SUM(F2:F3) -> 454445
A5: Depreciation & Amortization | B5: =SUM(B20:B21) -> 47890 | C5: =SUM(C20:C21) -> 50448 | D5: =SUM(D20:D21) -> 60067 | E5: =SUM(E20:E21) -> 67762 | F5: =SUM(F20:F21) -> 72760
A6: EBIT | B6: =B4-B5 -> 156867 | C6: =C4-C5 -> 122734 | D6: =D4-D5 -> 208585 | E6: =E4-E5 -> 273610 | F6: =F4-F5 -> 381685
A7: Net Interest Expense | B7: =SUM(FS!C10:C11) -> -4888 | C7: =SUM(FS!D10:D11) -> 1098 | D7: =SUM(FS!E10:E11) -> -22611 | E7: =SUM(FS!F10:F11) -> -82956 | F7: =SUM(FS!G10:G11) -> -57919
A8: EBT | B8: =SUM(B6:B7) -> 151979 | C8: =SUM(C6:C7) -> 123832 | D8: =SUM(D6:D7) -> 185974 | E8: =SUM(E6:E7) -> 190654 | F8: =SUM(F6:F7) -> 323766
A9: Tax | B9: -39512 | C9: -39479 | D9: -56892 | E9: -69331 | F9: -132202
A10: NOPAT | B10: =SUM(B8:B9) -> 112467 | C10: =SUM(C8:C9) -> 84353 | D10: =SUM(D8:D9) -> 129082 | E10: =SUM(E8:E9) -> 121323 | F10: =SUM(F8:F9) -> 191564
A19: Adjustments:
A20: Depreciation | B20: =SUM(FS!C84:C85) -> 47391 | C20: =SUM(FS!D84:D85) -> 49890 | D20: =SUM(FS!E84:E85) -> 59548 | E20: =SUM(FS!F84:F85) -> 67544 | F20: =SUM(FS!G84:G85) -> 72675
A21: Amortization | B21: 499 | C21: 558 | D21: 519 | E21: 218 | F21: 85
A22: Proceeds from PPE | B22: 177 | C22: -212 | D22: -255 | E22: 141 | F22: -34479
A23: Write offs | B23: 0 | C23: 4370 | D23: 0 | E23: 0 | F23: 0
B24: =SUM(B20:B23) -> 48067 | C24: =SUM(C20:C23) -> 54606 | D24: =SUM(D20:D23) -> 59812 | E24: =SUM(E20:E23) -> 67903 | F24: =SUM(F20:F23) -> 38281

Sheet EV
A1: Equity Value Calculations
A2: Share price @ 23/05/2025 | D2: 24.92
A3: Shares Outstanding | D3: 112000
A4: Market Cap | D4: =D2*D3 -> 2791040
A8: Enterprise Value
A9: Market Cap | D9: =D4 -> 2791040
A10: Net Debt | D10: =F23 -> -68941
A11: Enterprise Value | D11: =SUM(D9:D10) -> 2722099
A16: Net Debt Calculations
B17: 2020 | C17: 2021 | D17: 2022 | E17: 2023 | F17: 2024
A18: Long term lease liability | B18: =FS!C67 -> 8022 | C18: =FS!D67 -> 15376 | D18: =FS!E67 -> 9629 | E18: =FS!F67 -> 6681 | F18: =FS!G67 -> 2430
A19: Bank overdraft | B19: =FS!C62 -> 2406 | C19: =FS!D62 -> 3108 | D19: =FS!E62 -> 122735 | E19: =FS!F62 -> 209820 | F19: =FS!G62 -> 67350
A20: Short term lease liability | B20: =FS!C61 -> 8486 | C20: =FS!D61 -> 10765 | D20: =FS!E61 -> 26813 | E20: =FS!F61 -> 20181 | F20: =FS!G61 -> 28179
A21: Total Interest Bearing Debt | B21: =SUM(B18:B20) -> 18914 | C21: =SUM(C18:C20) -> 29249 | D21: =SUM(D18:D20) -> 159177 | E21: =SUM(E18:E20) -> 236682 | F21: =SUM(F18:F20) -> 97959
A22: Cash and cash equivalents | B22: =FS!C48 -> 89833 | C22: =FS!D48 -> 142109 | D22: =FS!E48 -> 199476 | E22: =FS!F48 -> 256455 | F22: =FS!G48 -> 166900
A23: Net Debt | B23: =B21-B22 -> -70919 | C23: =C21-C22 -> -112860 | D23: =D21-D22 -> -40299 | E23: =E21-E22 -> -19773 | F23: =F21-F22 -> -68941
A27: Valuation Models
A28: Enterprise Value multiples
A29: EV/EBITDA | B29: =IF(($D$11/Adjustment!B4)>0,$D$11/Adjustment!B4,"NOT") -> 13.29429 | C29: =IF(($D$11/Adjustment!C4)>0,$D$11/Adjustment!C4,"NOT") -> 15.71814 | D29: =IF(($D$11/Adjustment!D4)>0,$D$11/Adjustment!D4,"NOT") -> 10.132435 | E29: =IF(($D$11/Adjustment!E4)>0,$D$11/Adjustment!E4,"NOT") -> 7.9739961 | F29: =IF(($D$11/Adjustment!F4)>0,$D$11/Adjustment!F4,"NOT") -> 5.9899416
A30: EV/EBIT | B30: =IF(($D$11/Adjustment!B6)>0,$D$11/Adjustment!B6,"NOT") -> 17.35291 | C30: =IF(($D$11/Adjustment!C6)>0,$D$11/Adjustment!C6,"NOT") -> 22.17885 | D30: =IF(($D$11/Adjustment!D6)>0,$D$11/Adjustment!D6,"NOT") -> 13.05031 | E30: =IF(($D$11/Adjustment!E6)>0,$D$11/Adjustment!E6,"NOT") -> 9.9488286 | F30: =IF(($D$11/Adjustment!F6)>0,$D$11/Adjustment!F6,"NOT") -> 7.1317945
A31: EV/Revenue | B31: =IF(($D$11/FS!C3)>0,$D$11/FS!C3,"NOT") -> 1.1417444 | C31: =IF(($D$11/FS!D3)>0,$D$11/FS!D3,"NOT") -> 0.84585071 | D31: =IF(($D$11/FS!E3)>0,$D$11/FS!E3,"NOT") -> 0.47990096 | E31: =IF(($D$11/FS!F3)>0,$D$11/FS!F3,"NOT") -> 0.4505701 | F31: =IF(($D$11/FS!G3)>0,$D$11/FS!G3,"NOT") -> 0.3891221
A32: EV/OCF | B32: =IF(($D$11/FS!C101)>0,$D$11/FS!C101,"NOT") -> 11.923864 | C32: =IF(($D$11/FS!D101)>0,$D$11/FS!D101,"NOT") -> 13.832085 | D32: =IF(($D$11/FS!E101)>0,$D$11/FS!E101,"NOT") -> 10.883346 | E32: =IF(($D$11/FS!F101)>0,$D$11/FS!F101,"NOT") -> 7.38629 | F32: =IF(($D$11/FS!G101)>0,$D$11/FS!G101,"NOT") -> 5.6807916
A35: Equity Value Multiples
A36: P/E | B36: =IF(($D$4/FS!C14)>0,$D$4/FS!C14,"NOT") -> 24.55086 | C36: =IF(($D$4/FS!D14)>0,$D$4/FS!D14,"NOT") -> 24.755552 | D36: =IF(($D$4/FS!E14)>0,$D$4/FS!E14,"NOT") -> 17.263382 | E36: =IF(($D$4/FS!F14)>0,$D$4/FS!F14,"NOT") -> 16.424355 | F36: =IF(($D$4/FS!G14)>0,$D$4/FS!G14,"NOT") -> 9.603215
A37: P/B | B37: =IF(($D$4/FS!C58)>0,$D$4/FS!C58,"NOT") -> 7.9108196 | C37: =IF(($D$4/FS!D58)>0,$D$4/FS!D58,"NOT") -> 6.3899191 | D37: =IF(($D$4/FS!E58)>0,$D$4/FS!E58,"NOT") -> 5.823341 | E37: =IF(($D$4/FS!F58)>0,$D$4/FS!F58,"NOT") -> 5.3135239 | F37: =IF(($D$4/FS!G58)>0,$D$4/FS!G58,"NOT") -> 4.248029
A38: P/FCF | B38: =IF(($D$4/B45)>0,$D$4/B45,"NOT") -> 14.824824 | C38: =IF(($D$4/C45)>0,$D$4/C45,"NOT") -> 20.778107 | D38: =IF(($D$4/D45)>0,$D$4/D45,"NOT") -> 19.174762 | E38: =IF(($D$4/E45)>0,$D$4/E45,"NOT") -> 10.014855 | F38: =IF(($D$4/F45)>0,$D$4/F45,"NOT") -> 7.6487176
A42: Free Cash Flow Calculation | B42: 2020 | C42: 2021 | D42: 2022 | E42: 2023 | F42: 2024
A43: Operating Cash Flow | B43: =FS!C101 -> 228290 | C43: =FS!D101 -> 196796 | D43: =FS!E101 -> 250116 | E43: =FS!F101 -> 368534 | F43: =FS!G101 -> 479176
A44: Capex | B44: =FS!C109 -> -40022 | C44: =FS!D109 -> -62470 | D44: =FS!E109 -> -104558 | E44: =FS!F109 -> -89844 | F44: =FS!G109 -> -114273
A45: Free Cash Flow | B45: =SUM(B43:B44) -> 188268 | C45: =SUM(C43:C44) -> 134326 | D45: =SUM(D43:D44) -> 145558 | E45: =SUM(E43:E44) -> 278690 | F45: =SUM(F43:F44) -> 364903

Sheet Comparable Valuation
A1: Comparables Valuation | D1: COMPARABLE VALUATION
D4: All figures are Thousands of Cedis and Tullow Oil's figures are converted from Dollars to Cedis as at December 31,2024.
C5: COMPANY | H5: PERFORMANCE | L5: VALUATION
C6: Company Name | D6: Ticker | E6: Share Price | F6: Market Cap | G6: Enterprise Value | H6: Total debt/ Equity | I6: Gross Margin | J6: Operating Margin | K6: ROE | L6: P/E | M6: EV/Revenue | N6: EV/EBITDA
H7: 2024 | I7: 2024 | J7: 2024 | K7: 2024 | L7: 2024 | M7: 2024 | N7: 2024
C8: GOIL | D8: GOIL | E8: 1.8 | F8: =B40 -> 705600 | G8: =B39 -> 789171 | H8: =3400232/564638 -> 6.0219681 | I8: =592313/10583300 -> 0.055966759 | J8: =134796/11599794 -> 0.011620551 | K8: =24681/564638 -> 0.043711192 | L8: =E8/0.063 -> 28.571429 | M8: =B39/11599794 -> 0.068033191 | N8: =B39/B53 -> 4.5343971
C9: Tullow Oil PLC | D9: TLW | E9: 11.92 | F9: =G40 -> 17400 | G9: =G39 -> 42433.877 | H9: =M39/M40 -> 15.856986 | I9: =M42/G51 -> 0.49123721 | J9: =M43/G51 -> 0.38803831 | K9: =M44/M40 -> -0.20022002 | L9: =E9/M45 -> 0.27714781 | M9: =G9/G51 -> 2.378316 | N9: =G39/G53 -> 3.1881897
C13: Industry Multiple | E13: =AVERAGE(E8:E9) -> 6.86 | F13: =AVERAGE(F8:F9) -> 361500 | G13: =AVERAGE(G8:G9) -> 415802.44 | H13: =AVERAGE(H8:H9) -> 10.939477 | I13: =AVERAGEA(I8:I9) -> 0.27360199 | J13: =AVERAGE(J8:J9) -> 0.19982943 | K13: =AVERAGE(K8:K9) -> -0.078254415 | L13: =AVERAGE(L8:L9) -> 14.424288 | M13: =AVERAGE(M8:M9) -> 1.2231746 | N13: =AVERAGE(N8:N9) -> 3.8612934
C14: TotalEnergies | D14: TOTAL | E14: 24.92 | F14: =EV!D4 -> 2791040 | G14: =EV!D11 -> 2722099 | H14: =Ratios!F29 -> 1.7170665 | I14: =Ratios!F6 -> 0.11172073 | J14: =Ratios!F7 -> 0.068723869 | K14: =Ratios!F10 -> 0.44235488 | L14: =Ratios!F37 -> 9.603215 | M14: =EV!F31 -> 0.3891221 | N14: =EV!F29 -> 5.9899416
F17: Price Target
F19: P/E | H19: EV/EBITDA | J19: EV/Sales
H20: Multiple | I20: =N13 -> 3.8612934 | J20: Multiple | K20: 1.22
F21: Multiple | G21: =L13 -> 14.424288 | H21: EBITDA | I21: =Adjustment!F4 -> 454445 | J21: Revenue | K21: =FS!G3 -> 6995488
F22: EPS | G22: 2.6 | H22: EV | I22: =I20*I21 -> 1754745.5 | J22: EV | K22: =K20*K21 -> 8534495.4
H23: Debt | I23: =EV!F21 -> 97959 | J23: Debt | K23: =EV!F21 -> 97959
H24: Cash | I24: =EV!F22 -> 166900 | J24: Cash | K24: =EV!F22 -> 166900
H25: Equity Value | I25: =I22-(I23-I24) -> 1823686.5 | J25: Equity Value | K25: =K22-(K23-K24) -> 8603436.4
H26: S/O | I26: =FS!C27 -> 112000 | J26: S/O | K26: =I26 -> 112000
F27: Implied Price | G27: =G21*G22 -> 37.503149 | H27: Implied Price | I27: =I25/I26 -> 16.282915 | J27: Implied Price | K27: =K25/K26 -> 76.816396
H28: Target Price
I29: =AVERAGE(G27,I27,K27) -> 43.534153
H30: Current Price
H31: =E14 -> 24.92
H32: Implied Upside
I33: =I29/H31-1 -> 0.7469564
E36: NB:USD Rate @23/05/25 | F36: 11.6242
A38: GOIL PLC | E38: TULLOW OIL | F38: USD | G38: GHS | L38: USD | M38: GHS
A39: Enterprise Value | B39: =B40+B47 -> 789171 | E39: Enterprise Value | G39: =G40+G46 -> 42433.877 | J39: Debt | L39: -4324.2 | M39: =L39*F36 -> -50265.366
A40: Market Cap | B40: =E8*392000 -> 705600 | E40: Market Cap | G40: 17400 | J40: Equity | L40: -272.7 | M40: =L40*F36 -> -3169.9193
A41: Net Debt | E41: Net Debt
A42: Non-current term loan | B42: 53098 | E42: Borrowings | F42: 1975.8 | G42: =F42*F36 -> 22967.094 | J42: Gross Profit | L42: 754 | M42: =L42*F36 -> 8764.6468
A43: Current portion of term loan | B43: 86292 | E43: Lease Liabilities | F43: 732.9 | G43: =F43*F36 -> 8519.3762 | J43: Operating Profit | L43: 595.6 | M43: =L43*F36 -> 6923.3735
A44: Lease Liabilities | B44: 2936 | E44: Total Interest Bearing Debt | F44: =SUM(F42:F43) -> 2708.7 | G44: =SUM(G42:G43) -> 31486.471 | J44: Net Profit | L44: 54.6 | M44: =L44*F36 -> 634.68132
A45: Total Interest Bearing Debt | B45: =SUM(B42:B44) -> 142326 | E45: Cash | F45: 555.1 | G45: =F45*F36 -> 6452.5934 | J45: Basic EPS | L45: 3.7 | M45: =L45*F36 -> 43.00954
A46: Cash | B46: 58755 | E46: Net Debt | F46: =F44-F45 -> 2153.6 | G46: =G44-G45 -> 25033.877
A47: Net Debt | B47: =B45-B46 -> 83571
A50: EBITDA Calculation | E50: EBITDA Calculation
A51: Revenue | B51: 11599794 | E51: Revenue | F51: 1534.9 | G51: =F51*F36 -> 17841.985
A52: Operating Expense | B52: =(B55+B59)+B65 -> -11425753 | E52: Operating Expense | G52: =(G55+G57)+G62 -> -4532.2756
A53: EBITDA | B53: =SUM(B51:B52) -> 174041 | E53: EBITDA | G53: =SUM(G51:G52) -> 13309.709
...

Sheet Assumptions
B2: Active Case | C2: 2 | E2: Best | F2: 1
E3: Base | F3: 2
E4: Worst | F4: 3
C6: 2020 | D6: 2021 | E6: 2022 | F6: 2023 | G6: 2024 | H6: 2025 | I6: 2026 | J6: 2027 | K6: 2028 | L6: 2029
B7: Revenue | C7: 2384158 | D7: 3218179 | E7: 5672210 | F7: 6041455 | G7: 6995488 | H7: =(1+H15)*G7 -> 8675901.5 | I7: =(1+I15)*H7 -> 10759974 | J7: =(1+J15)*I7 -> 13344669 | K7: =(1+K15)*J7 -> 16550244 | L7: =(1+L15)*K7 -> 20525843
B8: y-o-y growth | D8: =D7/C7-1 -> 0.34981784 | E8: =E7/D7-1 -> 0.76255267 | F8: =F7/E7-1 -> 0.065097202 | G8: =G7/F7-1 -> 0.15791444
B9: 5 yr CAGR | G9: 0.24021391
F10: AVERAGE | G10: =AVERAGE(D8:G8) -> 0.33384554
B11: Best Case | H11: =H12+3% -> 0.27021391 | I11: =$H$11 -> 0.27021391 | J11: =$H$11 -> 0.27021391 | K11: =$H$11 -> 0.27021391 | L11: =$H$11 -> 0.27021391
B12: Base Case | H12: =$G$9 -> 0.24021391 | I12: =$G$9 -> 0.24021391 | J12: =$G$9 -> 0.24021391 | K12: =$G$9 -> 0.24021391 | L12: =$G$9 -> 0.24021391
B13: Worst Case | H13: =H12-3% -> 0.21021391 | I13: =$H$13 -> 0.21021391 | J13: =$H$13 -> 0.21021391 | K13: =$H$13 -> 0.21021391 | L13: =$H$13 -> 0.21021391
B15: Selected Case | H15: =CHOOSE($C$2,H11,H12,H13) -> 0.24021391 | I15: =CHOOSE($C$2,I11,I12,I13) -> 0.24021391 | J15: =CHOOSE($C$2,J11,J12,J13) -> 0.24021391 | K15: =CHOOSE($C$2,K11,K12,K13) -> 0.24021391 | L15: =CHOOSE($C$2,L11,L12,L13) -> 0.24021391
C18: 2020 | D18: 2021 | E18: 2022 | F18: 2023 | G18: 2024 | H18: 2025 | I18: 2026 | J18: 2027 | K18: 2028 | L18: 2029
B19: COGS | C19: =FS!C4 -> -2039837 | D19: =FS!D4 -> -2896838 | E19: =FS!E4 -> -5188233 | F19: =FS!F4 -> -5429160 | G19: =FS!G4 -> -6213947 | H19: =(H29*H$7)-H63 -> -7588684 | I19: =(I29*I$7)-I63 -> -9411591.5 | J19: =(J29*J$7)-J63 -> -11672387 | K19: =(K29*K$7)-K63 -> -14476256 | L19: =(L29*L$7)-L63 -> -17953654
B20: y-o-y growth | D20: =D19/C19-1 -> 0.4201321 | E20: =E19/D19-1 -> 0.79099867 | F20: =F19/E19-1 -> 0.046437197 | G20: =G19/F19-1 -> 0.14455035
B21: % of Revenue | C21: =C19/C7 -> -0.85557962 | D21: =D19/D7 -> -0.90014819 | E21: =E19/E7 -> -0.91467576 | F21: =F19/F7 -> -0.89865107 | G21: =G19/G7 -> -0.88827927 | H21: =G21 -> -0.88827927 | I21: =H21 -> -0.88827927 | J21: =I21 -> -0.88827927 | K21: =J21 -> -0.88827927 | L21: =K21 -> -0.88827927
B22: 5 yr CAGR | G22: 0.24955224
B23: 5 yr Average | G23: =AVERAGE(C21:G21) -> -0.89146678
F24: =AVERAGE(D20:G20) -> 0.35052958
B25: Best Case | H25: =H26+3% -> -0.85827927 | I25: =I26+3% -> -0.85827927 | J25: =J26+3% -> -0.85827927 | K25: =K26+3% -> -0.85827927 | L25: =L26+3% -> -0.85827927
B26: Base Case | H26: =$H$21 -> -0.88827927 | I26: =$H$21 -> -0.88827927 | J26: =$H$21 -> -0.88827927 | K26: =$H$21 -> -0.88827927 | L26: =$H$21 -> -0.88827927
B27: Worst Case | H27: =H26-3% -> -0.91827927 | I27: =I26-3% -> -0.91827927 | J27: =J26-3% -> -0.91827927 | K27: =K26-3% -> -0.91827927 | L27: =L26-3% -> -0.91827927
B29: Selected Case | H29: =CHOOSE($C$2,H25,H26,H27) -> -0.88827927 | I29: =CHOOSE($C$2,I25,I26,I27) -> -0.88827927 | J29: =CHOOSE($C$2,J25,J26,J27) -> -0.88827927 | K29: =CHOOSE($C$2,K25,K26,K27) -> -0.88827927 | L29: =CHOOSE($C$2,L25,L26,L27) -> -0.88827927
C34: 2020 | D34: 2021 | E34: 2022 | F34: 2023 | G34: 2024 | H34: 2025 | I34: 2026 | J34: 2027 | K34: 2028 | L34: 2029
B35: Gen, Admin & Selling Expense | C35: -187631 | D35: -202765 | E35: -275137 | F35: -338826 | G35: -365377 | H35: =H45*H$7 -> -517995.08 | I35: =I45*I$7 -> -642424.7 | J35: =J45*J$7 -> -796744.05 | K35: =K45*K$7 -> -988133.05 | L35: =L45*L$7 -> -1225496.3
B36: y-o-y growth | D36: =D35/C35-1 -> 0.080658313 | E36: =E35/D35-1 -> 0.3569255 | F36: =F35/E35-1 -> 0.23148104 | G36: =G35/F35-1 -> 0.078361755
B37: % of Revenue | C37: =C35/C7 -> -0.078699063 | D37: =D35/D7 -> -0.063006129 | E37: =E35/E7 -> -0.048506138 | F37: =F35/F7 -> -0.05608351 | G37: =G35/G7 -> -0.05223038 | H37: =G39 -> -0.059705044 | I37: =H37 -> -0.059705044 | J37: =I37 -> -0.059705044 | K37: =J37 -> -0.059705044 | L37: =K37 -> -0.059705044
B38: 5 yr CAGR | G38: 0.14258185
B39: 5 yr Average | G39: =AVERAGE(C37:G37) -> -0.059705044
B41: Best Case | H41: =H42+3% -> -0.029705044 | I41: =I42+3% -> -0.029705044 | J41: =J42+3% -> -0.029705044 | K41: =K42+3% -> -0.029705044 | L41: =L42+3% -> -0.029705044
B42: Base Case | H42: =$H$37 -> -0.059705044 | I42: =$H$37 -> -0.059705044 | J42: =$H$37 -> -0.059705044 | K42: =$H$37 -> -0.059705044 | L42: =$H$37 -> -0.059705044
B43: Worst Case | H43: =H42-3% -> -0.089705044 | I43: =I42-3% -> -0.089705044 | J43: =J42-3% -> -0.089705044 | K43: =K42-3% -> -0.089705044 | L43: =L42-3% -> -0.089705044
B45: Selected Case | H45: =CHOOSE($C$2,H41,H42,H43) -> -0.059705044 | I45: =CHOOSE($C$2,I41,I42,I43) -> -0.059705044 | J45: =CHOOSE($C$2,J41,J42,J43) -> -0.059705044 | K45: =CHOOSE($C$2,K41,K42,K43) -> -0.059705044 | L45: =CHOOSE($C$2,L41,L42,L43) -> -0.059705044
C48: 2020 | D48: 2021 | E48: 2022 | F48: 2023 | G48: 2024 | H48: 2025 | I48: 2026 | J48: 2027 | K48: 2028 | L48: 2029
B49: Other Income | C49: 22009 | D49: 27275 | E49: 43031 | F49: 41571 | G49: 67184 | H49: =H59*H$7 -> 83322.531 | I49: =I59*I$7 -> 103337.76 | J49: =J59*J$7 -> 128160.93 | K49: =K59*K$7 -> 158946.97 | L49: =L59*L$7 -> 197128.24
B50: y-o-y growth | D50: =D49/C49-1 -> 0.23926575 | E50: =E49/D49-1 -> 0.57767186 | F50: =F49/E49-1 -> -0.033929028 | G50: =G49/F49-1 -> 0.61612663
B51: % of Revenue | C51: =C49/C7 -> 0.0092313513 | D51: =D49/D7 -> 0.0084752899 | E51: =E49/E7 -> 0.0075862847 | F51: =F49/F7 -> 0.0068809583 | G51: =G49/G7 -> 0.0096039047 | H51: =G51 -> 0.0096039047 | I51: =H51 -> 0.0096039047 | J51: =I51 -> 0.0096039047 | K51: =J51 -> 0.0096039047 | L51: =K51 -> 0.0096039047
B52: 5 yr CAGR | G52: 0.25006648
B53: 5 yr Average | G53: =AVERAGE(C51:G51) -> 0.0083555578
B55: Best Case | H55: =H56+3% -> 0.039603905 | I55: =I56+3% -> 0.039603905 | J55: =J56+3% -> 0.039603905 | K55: =K56+3% -> 0.039603905 | L55: =L56+3% -> 0.039603905
...

Sheet WACC
B1: CAPM | G1: Beta
B2: Risk Free Rate (5 year US Bond Yield; Moody Rtaings: Aaa) | D2: =[2]WACC!$D$3 -> 0.0379 | G2: Year | H2: EPS
B3: Beta | D3: =F7 -> 0.65 | G3: 2015 | H3: 0.4041
B4: Expected Market Return | D4: =[2]WACC!$D$5 -> 0.2782 | G4: 2016 | H4: 0.3421
B5: Market Risk Premium | D5: =D4-D2 -> 0.2403 | F5: Other BETAs | G5: 2017 | H5: 0.3235
B6: Equity Risk Premium | D6: =D5*D3 -> 0.156195 | F6: 0.72310843 | G6: 2018 | H6: 0.4502
B7: Country Risk Premium | D7: =[2]WACC!$D$8 -> 0.1202 | F7: =0.65 -> 0.65 | G7: 2019 | H7: 0.6198
B8: Cost of Equity | D8: =D7+D6+D2 -> 0.314295 | F8: =0.5 -> 0.5 | G8: 2020 | H8: 1.0162
F9: =0.4 -> 0.4 | G9: 2021 | H9: 1.0078
F10: =AVERAGE(F6:F7) -> 0.68655421 | G10: 2022 | H10: 1.4451
G11: 2023 | H11: 1.519
G12: 2024 | H12: 2.5979
G13: Average | H13: =AVERAGE(H3:H12) -> 0.97257
B20: Cost of Debt
B21: GHS '000 | C21: 2020 | D21: 2021 | E21: 2022 | F21: 2023 | G21: 2024
B22: Finance Cost | C22: =FS!C11 -> -6783 | D22: =FS!D11 -> -4503 | E22: =FS!E11 -> -25304 | F22: =FS!F11 -> -86257 | G22: =FS!G11 -> -58584
B23: Interest Bearing Debt | C23: =EV!B21 -> 18914 | D23: =EV!C21 -> 29249 | E23: =EV!D21 -> 159177 | F23: =EV!E21 -> 236682 | G23: =EV!F21 -> 97959
B24: COD | C24: =C22/C23 -> -0.35862324 | D24: =D22/D23 -> -0.15395398 | E24: =E22/E23 -> -0.15896769 | F24: =F22/F23 -> -0.36444259 | G24: =G22/G23 -> -0.59804612
B25: 5 Year Average COD | G25: =-AVERAGE(C24:G24) -> 0.32680672
B26: Marginal tax rate | G26: =25% -> 0.25
B27: After Tax COD | G27: =G25*(1-G26) -> 0.24510504
B31: Weighted Average Cost of Capital
B33: Total Assets | C33: =FS!C51/FS!C51 -> 1 | D33: =FS!D51/FS!D51 -> 1 | E33: =FS!E51/FS!E51 -> 1 | F33: =FS!F51/FS!F51 -> 1 | G33: =FS!G51/FS!G51 -> 1
B34: Proportion of Equity | C34: =FS!C58/FS!C51 -> 0.41976811 | D34: =FS!D58/FS!D51 -> 0.41101915 | E34: =FS!E58/FS!E51 -> 0.28855712 | F34: =FS!F58/FS!F51 -> 0.28617886 | G34: =FS!G58/FS!G51 -> 0.368044
B35: Proportion of Debt | C35: =FS!C73/FS!C51 -> 0.58023189 | D35: =FS!D73/FS!D51 -> 0.58898085 | E35: =FS!E73/FS!E51 -> 0.71176077 | F35: =FS!F73/FS!F51 -> 0.71382114 | G35: =FS!G73/FS!G51 -> 0.631956
B36: WACC | G36: =(G34*D8)+(G35*G27) -> 0.27056999
B39: Sustainable Growth Rate
C40: 2020 | D40: 2021 | E40: 2022 | F40: 2023 | G40: 2024
B41: ROE | C41: =Ratios!B10 -> 0.32222169 | D41: =Ratios!C10 -> 0.25812064 | E41: =Ratios!D10 -> 0.3373233 | F41: =Ratios!E10 -> 0.32351491 | G41: =Ratios!F10 -> 0.44235488
B42: Dividend Payout Ratio | C42: =DDM!C20 -> 0.1789988 | D42: =DDM!D20 -> 0.49544012 | E42: =DDM!E20 -> 0.73172807 | F42: =DDM!F20 -> 0.46820466 | G42: =DDM!G20 -> 0.45979691
G43: =1-G42 -> 0.54020309
B44: SGR | G44: =G43*G41 -> 0.23896147

Sheet DCF
B1: Discounted Cashflow Model
C2: 2020 | D2: 2021 | E2: 2022 | F2: 2023 | G2: 2024 | H2: 2025 | I2: 2026 | J2: 2027 | K2: 2028 | L2: 2029
B3: Revenue | C3: =Assumptions!C7 -> 2384158 | D3: =Assumptions!D7 -> 3218179 | E3: =Assumptions!E7 -> 5672210 | F3: =Assumptions!F7 -> 6041455 | G3: =Assumptions!G7 -> 6995488 | H3: =Assumptions!H7 -> 8675901.5 | I3: =Assumptions!I7 -> 10759974 | J3: =Assumptions!J7 -> 13344669 | ... L3: =Assumptions!L7 -> 20525843
B4: COGS | C4: =Assumptions!C19 -> -2039837 | D4: =Assumptions!D19 -> -2896838 | E4: =Assumptions!E19 -> -5188233 | F4: =Assumptions!F19 -> -5429160 | G4: =Assumptions!G19 -> -6213947 | H4: =Assumptions!H19 -> -7588684 | I4: =Assumptions!I19 -> -9411591.5 | J4: =Assumptions!J19 -> -11672387 | ... L4: =Assumptions!L19 -> -17953654
B5: Gross Profit | C5: =SUM(C3:C4) -> 344321 | D5: =SUM(D3:D4) -> 321341 | E5: =SUM(E3:E4) -> 483977 | F5: =SUM(F3:F4) -> 612295 | G5: =SUM(G3:G4) -> 781541 | H5: =SUM(H3:H4) -> 1087217.5 | I5: =SUM(I3:I4) -> 1348382.2 | J5: =SUM(J3:J4) -> 1672282.4 | ... L5: =SUM(L3:L4) -> 2572188.6
B6: =Assumptions!B35 -> Gen, Admin & Selling Expense | C6: =Assumptions!C35 -> -187631 | D6: =Assumptions!D35 -> -202765 | E6: =Assumptions!E35 -> -275137 | F6: =Assumptions!F35 -> -338826 | G6: =Assumptions!G35 -> -365377 | H6: =Assumptions!H35 -> -517995.08 | I6: =Assumptions!I35 -> -642424.7 | ... L6: =Assumptions!L35 -> -1225496.3
B7: =Assumptions!B49 -> Other Income | C7: =Assumptions!C49 -> 22009 | D7: =Assumptions!D49 -> 27275 | E7: =Assumptions!E49 -> 43031 | F7: =Assumptions!F49 -> 41571 | G7: =Assumptions!G49 -> 67184 | H7: =Assumptions!H49 -> 83322.531 | I7: =Assumptions!I49 -> 103337.76 | ... L7: =Assumptions!L49 -> 197128.24
B8: EBITDA | C8: =SUM(C5:C7) -> 178699 | D8: =SUM(D5:D7) -> 145851 | E8: =SUM(E5:E7) -> 251871 | F8: =SUM(F5:F7) -> 315040 | G8: =SUM(G5:G7) -> 483348 | H8: =SUM(H5:H7) -> 652544.92 | I8: =SUM(I5:I7) -> 809295.28 | J8: =SUM(J5:J7) -> 1003699.3 | ... L8: =SUM(L5:L7) -> 1543820.5
B9: =Assumptions!B63 -> Depreciation and Amortization | C9: =-Assumptions!C63 -> -47890 | D9: =-Assumptions!D63 -> -50448 | E9: =-Assumptions!E63 -> -60067 | F9: =-Assumptions!F63 -> -67762 | G9: =-Assumptions!G63 -> -72760 | H9: =Assumptions!H63 -> -117939.45 | I9: =Assumptions!I63 -> -146270.14 | J9: =Assumptions!J63 -> -181406.27 | K9: =Assumptions!K63 -> -224982.57 | L9: =Assumptions!L63 -> -279026.52
B10: EBIT | C10: =SUM(C8:C9) -> 130809 | D10: =SUM(D8:D9) -> 95403 | E10: =SUM(E8:E9) -> 191804 | F10: =SUM(F8:F9) -> 247278 | G10: =SUM(G8:G9) -> 410588 | H10: =SUM(H8:H9) -> 534605.47 | I10: =SUM(I8:I9) -> 663025.14 | J10: =SUM(J8:J9) -> 822292.99 | ... L10: =SUM(L8:L9) -> 1264794
B11: Income Tax | C11: =Assumptions!C77 -> -39512 | D11: =Assumptions!D77 -> -39479 | E11: =Assumptions!E77 -> -56892 | F11: =Assumptions!F77 -> -69331 | G11: =Assumptions!G77 -> -132202 | H11: =-H10*Assumptions!H79 -> -133651.37 | I11: =-I10*Assumptions!I79 -> -165756.28 | J11: =-J10*Assumptions!J79 -> -205573.25 | K11: =-K10*Assumptions!K79 -> -254954.8 | L11: =-L10*Assumptions!L79 -> -316198.49
B12: NOPAT | C12: =SUM(C10:C11) -> 91297 | D12: =SUM(D10:D11) -> 55924 | E12: =SUM(E10:E11) -> 134912 | F12: =SUM(F10:F11) -> 177947 | G12: =SUM(G10:G11) -> 278386 | H12: =SUM(H10:H11) -> 400954.1 | I12: =SUM(I10:I11) -> 497268.85 | J12: =SUM(J10:J11) -> 616719.74 | ... L12: =SUM(L10:L11) -> 948595.47
B13: Dep&Amort | C13: =Assumptions!C63 -> 47890 | D13: =Assumptions!D63 -> 50448 | E13: =Assumptions!E63 -> 60067 | F13: =Assumptions!F63 -> 67762 | G13: =Assumptions!G63 -> 72760 | H13: =-Assumptions!H63 -> 117939.45 | I13: =-Assumptions!I63 -> 146270.14 | J13: =-Assumptions!J63 -> 181406.27 | K13: =-Assumptions!K63 -> 224982.57 | L13: =-Assumptions!L63 -> 279026.52
B14: Capex | C14: =Assumptions!C93 -> 334503 | D14: =Assumptions!D93 -> 60296.5 | E14: =Assumptions!E93 -> 98621 | F14: =Assumptions!F93 -> 116393 | G14: =Assumptions!G93 -> 113890 | H14: =Assumptions!H93 -> 223195.1 | I14: =Assumptions!I93 -> 274395.41 | J14: =Assumptions!J93 -> 340504.62 | ... L14: =Assumptions!L93 -> 524344.54
B15: Changes OWC | C15: =Assumptions!C107 -> 0 | D15: =Assumptions!D107 -> 1941.6533 | E15: =Assumptions!E107 -> 35035.627 | F15: =Assumptions!F107 -> 258513.12 | G15: =Assumptions!G107 -> -3282.7359 | H15: =Assumptions!H107 -> 1151.2358 | I15: =Assumptions!I107 -> 50775.613 | J15: =Assumptions!J107 -> 54830.298 | ... L15: =Assumptions!L107 -> 61187.728
B16: Unlevered Free Cashflow to the firm | C16: =SUM(C12:C15) -> 473690 | D16: =SUM(D12:D15) -> 168610.15 | E16: =SUM(E12:E15) -> 328635.63 | F16: =SUM(F12:F15) -> 620615.12 | G16: =SUM(G12:G15) -> 461753.26 | H16: =SUM(H12:H15) -> 743239.89 | I16: =SUM(I12:I15) -> 968710.02 | J16: =SUM(J12:J15) -> 1193460.9 | ... L16: =SUM(L12:L15) -> 1813154.3
B20: WACC | C20: =WACC!G36 -> 0.27056999
B21: Long T. Growth rate | C21: 0.053
B22: Year count | H22: =DDM!H27 -> 1 | I22: =DDM!I27 -> 2 | J22: =DDM!J27 -> 3 | K22: =DDM!K27 -> 4.0027397 | L22: =DDM!L27 -> 5.0027397
B23: Discount Factor | H23: =(1/((1+$C$20)^(H22))) -> 0.78704834 | I23: =(1/((1+$C$20)^(I22))) -> 0.61944509 | J23: =(1/((1+$C$20)^(J22))) -> 0.48753323 | K23: =(1/((1+$C$20)^(K22))) -> 0.38346056 | L23: =(1/((1+$C$20)^(L22))) -> 0.30180199
B24: PV OF FCF | H24: =H23*H16 -> 584965.72 | I24: =I23*I16 -> 600062.66 | J24: =J23*J16 -> 581851.85 | K24: =K23*K16 -> 563999.15 | L24: =L23*L16 -> 547213.57
B25: Terminal Value | L25: =(L16*(1+$C$21))/(C20-C21) -> 8775343.6
B27: Sum of PV of FCFs | C27: =SUM(H24:L24) -> 2878092.9
B28: PV of Terminal Value | C28: =L25*L23 -> 2648416.2
B29: Enterprise Value | C29: =SUM(C27:C28) -> 5526509.1 | J29: SENSITIVITY ANALYSIS
B30: Cash and Cash Equivalents | C30: =EV!F22 -> 166900 | J30: WACC
B31: Interest bearing debt | C31: =EV!F21 -> 97959 | H31: Long Term Growth Rate | I31: =C35 -> 24.92 | J31: =K31-2% -> 0.23056999 | K31: =L31-2% -> 0.25056999 | L31: =C20 -> 0.27056999 | M31: =L31+2% -> 0.29056999 | N31: =M31+2% -> 0.31056999
B32: Equity Value | C32: =C29+C30-C31 -> 5595450.1 | I32: =I33-1% -> 0.03 | J32: 9.5293005 | K32: 8.6251149 | L32: 7.8946449 | M32: 7.2924818 | N32: 6.7877551
B33: Shares Outstanding | C33: =EV!D3 -> 112000 | I33: =I34-1% -> 0.04 | J33: 9.8240124 | K33: 9.5293005 | L33: 9.5293005 | M33: 9.5293005 | N33: 9.5293005
B34: Implied Share Price | C34: =C32/C33 -> 49.959376 | I34: 0.05 | J34: 10.158019 | K34: 9.5293005 | L34: 9.5293005 | M34: 9.5293005 | N34: 9.5293005
B35: Current Share Price | C35: =EV!D2 -> 24.92 | I35: =I34+1% -> 0.06 | J35: 10.539741 | K35: 9.5293005 | L35: 9.5293005 | M35: 9.5293005 | N35: 9.5293005
B36: Potential Upside/ Downside | C36: =C34/C35-1 -> 1.0047904 | I36: =I35+1% -> 0.07 | J36: 10.98019 | K36: 9.5293005 | L36: 9.5293005 | M36: 9.5293005 | N36: 9.5293005

Sheet DDM
B1: DiVIDEND DISCOUNT MODEL
C2: 2020 | D2: 2021 | E2: 2022 | F2: 2023 | G2: 45627 | H2: 45992 | I2: 46357 | J2: 46722 | K2: 47088 | L2: 47453
B3: Revenue | C3: =Assumptions!C7 -> 2384158 | D3: =Assumptions!D7 -> 3218179 | E3: =Assumptions!E7 -> 5672210 | F3: =Assumptions!F7 -> 6041455 | G3: =Assumptions!G7 -> 6995488 | H3: =Assumptions!H7 -> 8675901.5 | I3: =Assumptions!I7 -> 10759974 | J3: =Assumptions!J7 -> 13344669 | ... L3: =Assumptions!L7 -> 20525843
B4: COGS | C4: =Assumptions!C19 -> -2039837 | D4: =Assumptions!D19 -> -2896838 | E4: =Assumptions!E19 -> -5188233 | F4: =Assumptions!F19 -> -5429160 | G4: =Assumptions!G19 -> -6213947 | H4: =Assumptions!H19 -> -7588684 | I4: =Assumptions!I19 -> -9411591.5 | J4: =Assumptions!J19 -> -11672387 | ... L4: =Assumptions!L19 -> -17953654
B5: Gross Profit | C5: =SUM(C3:C4) -> 344321 | D5: =SUM(D3:D4) -> 321341 | E5: =SUM(E3:E4) -> 483977 | F5: =SUM(F3:F4) -> 612295 | G5: =SUM(G3:G4) -> 781541 | H5: =SUM(H3:H4) -> 1087217.5 | I5: =SUM(I3:I4) -> 1348382.2 | J5: =SUM(J3:J4) -> 1672282.4 | ... L5: =SUM(L3:L4) -> 2572188.6
B6: =Assumptions!B35 -> Gen, Admin & Selling Expense | C6: =Assumptions!C35 -> -187631 | D6: =Assumptions!D35 -> -202765 | E6: =Assumptions!E35 -> -275137 | F6: =Assumptions!F35 -> -338826 | G6: =Assumptions!G35 -> -365377 | H6: =Assumptions!H35 -> -517995.08 | I6: =Assumptions!I35 -> -642424.7 | ... L6: =Assumptions!L35 -> -1225496.3
B7: =Assumptions!B49 -> Other Income | C7: =Assumptions!C49 -> 22009 | D7: =Assumptions!D49 -> 27275 | E7: =Assumptions!E49 -> 43031 | F7: =Assumptions!F49 -> 41571 | G7: =Assumptions!G49 -> 67184 | H7: =Assumptions!H49 -> 83322.531 | I7: =Assumptions!I49 -> 103337.76 | ... L7: =Assumptions!L49 -> 197128.24
B8: EBITDA | C8: =SUM(C5:C7) -> 178699 | D8: =SUM(D5:D7) -> 145851 | E8: =SUM(E5:E7) -> 251871 | F8: =SUM(F5:F7) -> 315040 | G8: =SUM(G5:G7) -> 483348 | H8: =SUM(H5:H7) -> 652544.92 | I8: =SUM(I5:I7) -> 809295.28 | J8: =SUM(J5:J7) -> 1003699.3 | ... L8: =SUM(L5:L7) -> 1543820.5
B9: =Assumptions!B63 -> Depreciation and Amortization | C9: =-Assumptions!C63 -> -47890 | D9: =-Assumptions!D63 -> -50448 | E9: =-Assumptions!E63 -> -60067 | F9: =-Assumptions!F63 -> -67762 | G9: =-Assumptions!G63 -> -72760 | H9: =Assumptions!H63 -> -117939.45 | I9: =Assumptions!I63 -> -146270.14 | J9: =Assumptions!J63 -> -181406.27 | K9: =Assumptions!K63 -> -224982.57 | L9: =Assumptions!L63 -> -279026.52
B10: EBIT | C10: =SUM(C8:C9) -> 130809 | D10: =SUM(D8:D9) -> 95403 | E10: =SUM(E8:E9) -> 191804 | F10: =SUM(F8:F9) -> 247278 | G10: =SUM(G8:G9) -> 410588 | H10: =SUM(H8:H9) -> 534605.47 | I10: =SUM(I8:I9) -> 663025.14 | J10: =SUM(J8:J9) -> 822292.99 | ... L10: =SUM(L8:L9) -> 1264794
B11: Interest Expense | C11: =Assumptions!C114 -> -4888 | D11: =Assumptions!D114 -> 1098 | E11: =Assumptions!E114 -> -22611 | F11: =Assumptions!F114 -> -82956 | G11: =Assumptions!G114 -> -57919 | H11: =Assumptions!H114 -> -52961.599 | I11: =Assumptions!I114 -> -65683.712 | J11: =Assumptions!J114 -> -81461.853 | ... L11: =Assumptions!L114 -> -125298.96
B12: EBT | C12: =C10-C11 -> 135697 | D12: =D10-D11 -> 94305 | E12: =E10-E11 -> 214415 | F12: =F10-F11 -> 330234 | G12: =G10-G11 -> 468507 | H12: =H10-H11 -> 587567.07 | I12: =I10-I11 -> 728708.85 | J12: =J10-J11 -> 903754.85 | ... L12: =L10-L11 -> 1390092.9
B13: Tax | C13: =Assumptions!C77 -> -39512 | D13: =Assumptions!D77 -> -39479 | E13: =Assumptions!E77 -> -56892 | F13: =Assumptions!F77 -> -69331 | G13: =Assumptions!G77 -> -132202 | H13: =H10*Assumptions!H87 -> -133651.37 | I13: =I10*Assumptions!I87 -> -165756.28 | J13: =J10*Assumptions!J87 -> -205573.25 | K13: =K10*Assumptions!K87 -> -254954.8 | L13: =L10*Assumptions!L87 -> -316198.49
B14: Net Profit | C14: =SUM(C12:C13) -> 96185 | D14: =SUM(D12:D13) -> 54826 | E14: =SUM(E12:E13) -> 157523 | F14: =SUM(F12:F13) -> 260903 | G14: =SUM(G12:G13) -> 336305 | H14: =SUM(H12:H13) -> 453915.7 | I14: =SUM(I12:I13) -> 562952.56 | J14: =SUM(J12:J13) -> 698181.6 | ... L14: =SUM(L12:L13) -> 1073894.4
C17: 2020 | D17: 2021 | E17: 2022 | F17: 2023 | G17: 2024 | H17: 2025 | I17: 2026 | J17: 2027 | K17: 2028 | L17: 2029
B18: Dividend Paid | C18: =-FS!C116 -> 17217 | D18: =-FS!D116 -> 27163 | E18: =-FS!E116 -> 115264 | F18: =-FS!F116 -> 122156 | G18: =-FS!G116 -> 154632 | H18: =H14*H20 -> 226957.85 | I18: =I14*I20 -> 281476.28 | J18: =J14*J20 -> 349090.8 | K18: =K14*K20 -> 432947.26 | L18: =L14*L20 -> 536947.22
B19: y-o-y growth | D19: =D18/C18-1 -> 0.57768485 | E19: =E18/D18-1 -> 3.2434194 | F19: =F18/E18-1 -> 0.05979317 | G19: =G18/F18-1 -> 0.26585677
B20: Dividend Payout ratio | C20: =C18/C14 -> 0.1789988 | D20: =D18/D14 -> 0.49544012 | E20: =E18/E14 -> 0.73172807 | F20: =F18/F14 -> 0.46820466 | G20: =G18/G14 -> 0.45979691 | H20: =G22 -> 0.5 | I20: =H20 -> 0.5 | J20: =I20 -> 0.5 | K20: =J20 -> 0.5 | L20: =K20 -> 0.5
B21: 2 Year Average | G21: =AVERAGE(E20:G20) -> 0.55324321
G22: =50% -> 0.5
B24: Cost of Equity | C24: =WACC!D8 -> 0.314295
B25: Sustainable Growth Rate | C25: =WACC!G44 -> 0.23896147
B27: Year count | H27: =YEARFRAC($G$2,H2,3) -> 1 | I27: =YEARFRAC($G$2,I2,3) -> 2 | J27: =YEARFRAC($G$2,J2,3) -> 3 | K27: =YEARFRAC($G$2,K2,3) -> 4.0027397 | L27: =YEARFRAC($G$2,L2,3) -> 5.0027397
B28: Discount Factor | H28: =(1/(1+$C$24))^H27 -> 0.76086419 | I28: =(1/(1+$C$24))^I27 -> 0.57891431 | J28: =(1/(1+$C$24))^J27 -> 0.44047517 | K28: =(1/(1+$C$24))^K27 -> 0.33489093 | L28: =(1/(1+$C$24))^L27 -> 0.25480652
B29: PV OF Dividend | H29: =H28*H18 -> 172684.1 | I29: =I28*I18 -> 162950.65 | J29: =J28*J18 -> 153765.83 | K29: =K28*K18 -> 144990.11 | L29: =L28*L18 -> 136817.65
B30: Terminal Value | L30: =(L18*(1+C25))/(C24-C25) -> 8830820.9
B32: Sum of PV of Dividends | C32: =SUM(H29:L29) -> 771208.34
B33: PV of Terminal Value | C33: =L30*L28 -> 2250150.7
B34: Equity Value | C34: =SUM(C32:C33) -> 3021359.1 | J34: SENSITIVITY ANALYSIS
B35: Shares Outstanding | C35: =EV!D3 -> 112000 | J35: Cost Of Equity
B36: Implied Share Price | C36: =C34/C35 -> 26.97642 | H36: Sustainable Growth Rate | I36: =C36 -> 26.97642 | J36: =K36-2% -> 0.274295 | K36: =L36-2% -> 0.294295 | L36: =C24 -> 0.314295 | M36: =L36+2% -> 0.334295 | N36: =M36+2% -> 0.354295
B37: Current Share Price | C37: =EV!D2 -> 24.92 | I37: =I38-1% -> 0.21896147 | J37: 27.870312 | K37: -14.458422 | L37: -14.458422 | M37: 27.870312 | N37: 4.1849689
B38: Potential Upside/ Downside | C38: =C36/C37-1 -> 0.082520884 | I38: =I39-1% -> 0.22896147 | J38: 11.817629 | K38: 27.870312 | L38: 27.870312 | M38: 27.870312 | N38: 27.870312
I39: =C25 -> 0.23896147 | J39: 11.817629 | K39: 27.870312 | L39: 27.870312 | M39: 27.870312 | N39: 27.870312
I40: =I39+1% -> 0.24896147 | J40: 27.870312 | K40: 27.870312 | L40: 27.870312 | M40: 27.870312 | N40: 27.870312
I41: =I40+1% -> 0.25896147 | J41: -13.476628 | K41: 27.870312 | L41: 27.870312 | M41: 27.870312 | N41: 27.870312

Sheet Fair Value
B2: Fair Price Analysis
B3: Model | C3: WEIGHTS | D3: Implied Price | E3: Upside/Downside | F3: Recommendation
B4: CCA: PE, EV/EBITDA, EV/SALES | C4: 0.4 | D4: ='Comparable Valuation'!I29 -> 43.534153 | E4: ='Comparable Valuation'!I33 -> 0.7469564 | F4: =IF(E4>0,"BUY","SELL") -> BUY
B5: DCF | C5: =30% -> 0.3 | D5: =DCF!C34 -> 49.959376 | E5: =DCF!C36 -> 1.0047904 | F5: =IF(E5>0,"BUY","SELL") -> BUY | M5: =100/3 -> 33.333333
B6: DDM | C6: =30% -> 0.3 | D6: =DDM!C36 -> 26.97642 | E6: =DDM!C38 -> 0.082520884 | F6: =IF(E6>0,"BUY","SELL") -> BUY
B7: Intrinsic Price | F7: =(C4*D4)+(C5*D5)+(C6*D6) -> 40.4944
B8: Current Price | F8: =DDM!C37 -> 24.92
B9: Upside | F9: =F7/F8-1 -> 0.62497594
G12: TOTALENERGIES ,GHANA
G13: Ticker: | H13: TOTAL
G14: Current Price @ 23/05/2025 | H14: 24.92
G15: Target Price
G16: Recommendation | H16: BUY
G17: Upside

Sheet Monte Carlo
B1: Stock data
B2: Estimated fair price today | D2: ='Fair Value'!F7 -> 40.4944
B3: Cost of equity (mu) | D3: =WACC!D8 -> 0.314295
B4: Volatility (standard deviation of ROE) | D4: 0.066561108
B5: Investment horizon | D5: 1
B6: Terminal price
E10: Simulations | F10: Uniform Distribution | G10: Terminal Price | H10: Change in Price
E11: Sim 1 | F11: =RAND() -> 0.614715 | G11: 57.701301 | H11: =$D$2-G11 -> -17.206901
E12: Sim 2 | F12: =RAND() -> 0.46365366 | G12: 45.824501 | H12: =$D$2-G12 -> -5.3301009
E13: Sim 3 | F13: =RAND() -> 0.17656458 | G13: 118.71544 | H13: =$D$2-G13 -> -78.221044
E14: Sim 4 | F14: =RAND() -> 0.22356099 | G14: 37.94732 | H14: =$D$2-G14 -> 2.5470804
E15: Sim 5 | F15: =RAND() -> 0.48792179 | G15: 35.968866 | H15: =$D$2-G15 -> 4.5255339
E16: Sim 6 | F16: =RAND() -> 0.30655331 | G16: 38.027876 | H16: =$D$2-G16 -> 2.4665239
E17: Sim 7 | F17: =RAND() -> 0.43874943 | G17: 36.184187 | H17: =$D$2-G17 -> 4.3102134
E18: Sim 8 | F18: =RAND() -> 0.82730463 | G18: 38.71216 | H18: =$D$2-G18 -> 1.7822402
E19: Sim 9 | F19: =RAND() -> 0.36203941 | G19: 36.053927 | H19: =$D$2-G19 -> 4.4404733
E20: Sim 10 | F20: =RAND() -> 0.84725911 | G20: 36.54699 | H20: =$D$2-G20 -> 3.9474099
E21: Sim 11 | F21: =RAND() -> 0.55382686 | G21: 40.674622 | H21: =$D$2-G21 -> -0.18022128
E22: Sim 12 | F22: =RAND() -> 0.2539298 | G22: 37.055779 | H22: =$D$2-G22 -> 3.4386211
... E10010: Sim 10000 | F10010: =RAND() -> 0.0052656247 | G10010: 35.112657 | H10010: =$D$2-G10010 -> 5.3817435
