Workbook
Name days365: '[1]Ratio Analysis'!$D$1
Name days365: #REF!
Name Share_Price: EV!$E$2

Sheet FS
A1: UNILEVER GHANA PLC
A2: INCOME STATEMENT | C2: 2017 | D2: 2018 | E2: 2019 | F2: 2020 | G2: 2021 | H2: 2022 | I2: 2023 | J2: 2024
B3: Revenue | C3: 575765 | D3: 632152 | E3: 333290 | F3: 456279 | G3: 526912 | H3: 631477 | I3: 908146 | J3: 930801
B4: Cost of sales | C4: -401712 | D4: -440991 | E4: =348684*-1 -> -348684 | F4: =380584*-1 -> -380584 | G4: -429866 | H4: -475876 | I4: -571369 | J4: -582931 | L4: Legend
B5: Gross Profit/(Loss)(EBITDA) | C5: =SUM(C3:C4) -> 174053 | D5: =SUM(D3:D4) -> 191161 | E5: =SUM(E3:E4) -> -15394 | F5: =SUM(F3:F4) -> 75695 | G5: =SUM(G3:G4) -> 97046 | H5: =SUM(H3:H4) -> 155601 | I5: 336777 | J5: 347870 | L5: Blue indicates hard-coded numbers and inputs.
B6: Distribution expenses | C6: -13156 | D6: -17732 | E6: -25775 | F6: -17568 | G6: -16723 | H6: -14730 | I6: -19599 | J6: -20876 | L6: Black indicates formulas or text.
B7: Brand and Marketing investment | C7: -27537 | D7: -39999 | E7: -30096 | F7: -31910 | G7: -44612 | H7: -40116 | I7: -79627 | J7: -87626 | L7: Green indicates links from other worksheets.
B8: Administrative expenses | C8: -56113 | D8: -67867 | E8: -91051 | F8: -72841 | G8: -79564 | H8: -70752 | I8: -22500 | J8: -135120
B9: Restructuring Cost | H9: -11627 | I9: -3354 | J9: -19774
B10: Impairment release on trade&other receivables | H10: 1612 | I10: 957 | J10: -43
B11: Other income | H11: 12457 | I11: 11017 | J11: 11442
B12: Operating Profit (EBIT) | C12: =SUM(C5:C11) -> 77247 | D12: =SUM(D5:D11) -> 65563 | E12: =SUM(E5:E11) -> -162316 | F12: =SUM(F5:F11) -> -46624 | G12: =SUM(G5:G11) -> -43853 | H12: =SUM(H5:H11) -> 32445 | I12: 223671 | J12: 95873
B13: Finance income | C13: 160 | D13: 440 | E13: 571 | F13: 100 | G13: 574 | H13: 1088 | I13: 1549 | J13: 1739
B14: Finance costs | C14: -2004 | D14: -3376 | E14: -11603 | F14: -5608 | G14: -2922 | H14: -18453 | I14: -9999 | J14: -5365
B15: Profit/(Loss) before taxation(EBT) | C15: =SUM(C12:C14) -> 75403 | D15: =SUM(D12:D14) -> 62627 | E15: =SUM(E12:E14) -> -173348 | F15: =SUM(F12:F14) -> -52132 | G15: =SUM(G12:G14) -> -46201 | H15: =SUM(H12:H14) -> 15080 | I15: 215221 | J15: 92247
B16: Income tax (expense)/credit | C16: -17211 | D16: -59497 | E16: 56331 | F16: -22830 | G16: -51 | H16: 0 | I16: -36259 | J16: -27341
B17: Profit/(Loss) after tax for the year | C17: =SUM(C15,C16) -> 58192 | D17: =SUM(D15,D16) -> 3130 | E17: =SUM(E15,E16) -> -117017 | F17: =SUM(F15,F16) -> -74962 | G17: =SUM(G15,G16) -> -46252 | H17: =SUM(H15,H16) -> 15080 | I17: 178962 | J17: 64906
B19: WASO | C19: 62500000 | D19: 62500000 | E19: 62500000 | F19: 62500000 | G19: 62500000 | H19: 62500000 | I19: 62500000 | J19: 62500000
B20: REPORTED / ACTUAL EPS | C20: =(C17*1000)/C19 -> 0.931072 | D20: =(D17*1000)/D19 -> 0.05008 | E20: =(E17*1000)/E19 -> -1.872272 | F20: =(F17*1000)/F19 -> -1.199392 | G20: =(G17*1000)/G19 -> -0.740032 | H20: 0.2413 | I20: 2.86 | J20: 1.0385
A22: Balance Sheet
B23: PP&E | C23: 113738 | D23: 144194 | E23: 138983 | F23: 135551 | G23: 131166 | H23: 133750 | I23: 122103 | J23: 131157
B24: Lease-Right-of-Use assets | C24: 0 | D24: 0 | E24: 13422 | F24: 11468 | G24: 10255 | H24: 22761 | I24: 27692 | J24: 26765
B25: Intangible assets | C25: 7 | D25: 0 | E25: 0 | F25: 0 | G25: 0 | H25: 0 | I25: 0 | J25: 0
B26: Deferred tax asset | C26: 0 | D26: 0 | E26: 47447 | F26: 24539 | G26: 24481 | H26: 24159 | I26: 24310 | J26: 0
B27: Investment in subsidiaries | C27: 10 | D27: 10 | E27: 10 | F27: 10 | G27: 11 | H27: 0 | I27: 0 | J27: 0
B28: Other Investment | C28: 0 | D28: 0 | E28: 0 | F28: 0 | G28: 0 | H28: 11 | I28: 11 | J28: 0
B29: Non-current assets | C29: =SUM(C23:C28) -> 113755 | D29: =SUM(D23:D28) -> 144204 | E29: =SUM(E23:E28) -> 199862 | F29: =SUM(F23:F28) -> 171568 | G29: =SUM(G23:G28) -> 165913 | H29: =SUM(H23:H28) -> 180681 | I29: =SUM(I23:I28) -> 174116 | J29: 157922
B30: Current Assets
B31: Inventories | C31: 53618 | D31: 53436 | E31: 115659 | F31: 97021 | G31: 91627 | H31: 128212 | I31: 101691 | J31: 128999
B32: Trade and other receivables | C32: 93937 | D32: 270261 | E32: 114316 | F32: 25639 | G32: 24539 | H32: 33747 | I32: 41799 | J32: 49175
B33: Prepayments | C33: 28747 | D33: 22740 | E33: 1362 | F33: 652 | G33: 3633 | H33: 1368 | I33: 2362 | J33: 1702
B34: Related party receivables | C34: 125259 | D34: 227904 | E34: 35892 | F34: 22340 | G34: 56199 | H34: 9901 | I34: 8542 | J34: 9415
B35: Current tax asset | C35: 112 | D35: 0 | E35: 10231 | F35: 12554 | G35: 14267 | H35: 15341 | I35: 15752 | J35: 6636
B36: Cash and bank balances | C36: 53203 | D36: 7945 | E36: 11857 | F36: 5947 | G36: 26363 | H36: 42504 | I36: 108717 | J36: 97030
B37: Total Current assets | C37: =SUM(C31:C36) -> 354876 | D37: =SUM(D31:D36) -> 582286 | E37: =SUM(E31:E36) -> 289317 | F37: =SUM(F31:F36) -> 164153 | G37: =SUM(G31:G36) -> 216628 | H37: =SUM(H31:H36) -> 231073 | I37: =SUM(I31:I36) -> 278863 | J37: 292957
B39: Total assets | C39: =SUM(C29,C37) -> 468631 | D39: =SUM(D29,D37) -> 726490 | E39: =SUM(E29,E37) -> 489179 | F39: =SUM(F29,F37) -> 335721 | G39: =SUM(G29,G37) -> 382541 | H39: =SUM(H29,H37) -> 411754 | I39: =SUM(I29,I37) -> 452979 | J39: 450879
B41: Equity
B42: Share Capital | C42: 1200 | D42: 1200 | E42: 1200 | F42: 1200 | G42: 1200 | H42: 1200 | I42: 1200 | J42: 1200
B43: Capital surplus account | C43: 204 | D43: 204 | E43: 204 | F43: 204 | G43: 204 | H43: 204 | I43: 204 | J43: 204
B44: Retained earnings | C44: 119112 | D44: 293656 | E44: 83467 | F44: 33314 | G44: 35289 | H44: 51333 | I44: 229842 | J44: 231271
...

Sheet Common Size
A1: INCOME STATEMENT | C1: 2017 | D1: 2018 | E1: 2019 | F1: 2020 | G1: 2021 | H1: 2022 | I1: 2023 | J1: 2024
B2: Revenue | C2: =FS!C3/FS!C$3 -> 1 | D2: =FS!D3/FS!D$3 -> 1 | E2: =FS!E3/FS!E$3 -> 1 | F2: =FS!F3/FS!F$3 -> 1 | G2: =FS!G3/FS!G$3 -> 1 | H2: =FS!H3/FS!H$3 -> 1 | I2: =FS!I3/FS!I$3 -> 1 | J2: =FS!J3/FS!J$3 -> 1
B3: Cost of sales | C3: =FS!C4/FS!C$3 -> -0.69770132 | D3: =FS!D4/FS!D$3 -> -0.69760279 | E3: =FS!E4/FS!E$3 -> -1.046188 | F3: =FS!F4/FS!F$3 -> -0.8341037 | G3: =FS!G4/FS!G$3 -> -0.81582124 | H3: =FS!H4/FS!H$3 -> -0.75359198 | I3: =FS!I4/FS!I$3 -> -0.62915985 | J3: =FS!J4/FS!J$3 -> -0.62626813
B4: Gross Profit/(Loss) | C4: =FS!C5/FS!C$3 -> 0.30229868 | D4: =FS!D5/FS!D$3 -> 0.30239721 | E4: =FS!E5/FS!E$3 -> -0.046188004 | F4: =FS!F5/FS!F$3 -> 0.1658963 | G4: =FS!G5/FS!G$3 -> 0.18417876 | H4: =FS!H5/FS!H$3 -> 0.24640802 | I4: =FS!I5/FS!I$3 -> 0.37084015 | J4: =FS!J5/FS!J$3 -> 0.37373187
B5: Distribution expenses | C5: =FS!C6/FS!C$3 -> -0.0228496 | D5: =FS!D6/FS!D$3 -> -0.028050216 | E5: =FS!E6/FS!E$3 -> -0.077335054 | F5: =FS!F6/FS!F$3 -> -0.038502758 | G5: =FS!G6/FS!G$3 -> -0.031737747 | H5: =FS!H6/FS!H$3 -> -0.023326265 | I5: =FS!I6/FS!I$3 -> -0.021581332 | J5: =FS!J6/FS!J$3 -> -0.022427995
B6: Brand and Marketing investment | C6: =FS!C7/FS!C$3 -> -0.047826804 | D6: =FS!D7/FS!D$3 -> -0.063274339 | E6: =FS!E7/FS!E$3 -> -0.090299739 | F6: =FS!F7/FS!F$3 -> -0.069935281 | G6: =FS!G7/FS!G$3 -> -0.084666889 | H6: =FS!H7/FS!H$3 -> -0.063527254 | I6: =FS!I7/FS!I$3 -> -0.087680835 | J6: =FS!J7/FS!J$3 -> -0.094140423
B7: Administrative expenses | C7: =FS!C8/FS!C$3 -> -0.097458164 | D7: =FS!D8/FS!D$3 -> -0.10735867 | E7: =FS!E8/FS!E$3 -> -0.27318851 | F7: =FS!F8/FS!F$3 -> -0.15964136 | G7: =FS!G8/FS!G$3 -> -0.15100055 | H7: =FS!H8/FS!H$3 -> -0.11204209 | I7: =FS!I8/FS!I$3 -> -0.024775752 | J7: =FS!J8/FS!J$3 -> -0.14516529
B8: Restructuring Cost | C8: =FS!C9/FS!C$3 -> 0 | D8: =FS!D9/FS!D$3 -> 0 | E8: =FS!E9/FS!E$3 -> 0 | F8: =FS!F9/FS!F$3 -> 0 | G8: =FS!G9/FS!G$3 -> 0 | H8: =FS!H9/FS!H$3 -> -0.018412389 | I8: =FS!I9/FS!I$3 -> -0.0036932388 | J8: =FS!J9/FS!J$3 -> -0.021244068
B9: Impairment release on trade&other receivables | C9: =FS!C10/FS!C$3 -> 0 | D9: =FS!D10/FS!D$3 -> 0 | E9: =FS!E10/FS!E$3 -> 0 | F9: =FS!F10/FS!F$3 -> 0 | G9: =FS!G10/FS!G$3 -> 0 | H9: =FS!H10/FS!H$3 -> 0.0025527454 | I9: =FS!I10/FS!I$3 -> 0.0010537953 | J9: =FS!J10/FS!J$3 -> -4.619677e-05
B10: Other income | C10: =FS!C11/FS!C$3 -> 0 | D10: =FS!D11/FS!D$3 -> 0 | E10: =FS!E11/FS!E$3 -> 0 | F10: =FS!F11/FS!F$3 -> 0 | G10: =FS!G11/FS!G$3 -> 0 | H10: =FS!H11/FS!H$3 -> 0.019726768 | I10: =FS!I11/FS!I$3 -> 0.012131309 | J10: =FS!J11/FS!J$3 -> 0.012292638
B11: Operating Profit | C11: =FS!C12/FS!C$3 -> 0.13416411 | D11: =FS!D12/FS!D$3 -> 0.10371398 | E11: =FS!E12/FS!E$3 -> -0.48701131 | F11: =FS!F12/FS!F$3 -> -0.10218309 | G11: =FS!G12/FS!G$3 -> -0.083226421 | H11: =FS!H12/FS!H$3 -> 0.051379544 | I11: =FS!I12/FS!I$3 -> 0.2462941 | J11: =FS!J12/FS!J$3 -> 0.10300053
B12: Finance income | C12: =FS!C13/FS!C$3 -> 0.00027789115 | D12: =FS!D13/FS!D$3 -> 0.00069603513 | E12: =FS!E13/FS!E$3 -> 0.0017132227 | F12: =FS!F13/FS!F$3 -> 0.00021916415 | G12: =FS!G13/FS!G$3 -> 0.001089366 | H12: =FS!H13/FS!H$3 -> 0.0017229448 | I12: =FS!I13/FS!I$3 -> 0.0017056729 | J12: =FS!J13/FS!J$3 -> 0.0018682833
B13: Finance costs | C13: =FS!C14/FS!C$3 -> -0.0034805867 | D13: =FS!D14/FS!D$3 -> -0.0053404877 | E13: =FS!E14/FS!E$3 -> -0.034813526 | F13: =FS!F14/FS!F$3 -> -0.012290726 | G13: =FS!G14/FS!G$3 -> -0.005545518 | H13: =FS!H14/FS!H$3 -> -0.029221967 | I13: =FS!I14/FS!I$3 -> -0.011010344 | J13: =FS!J14/FS!J$3 -> -0.0057638529
... B16: Profit/(Loss) after tax for the year | C16: =FS!C17/FS!C$3 -> 0.10106901 | D16: =FS!D17/FS!D$3 -> 0.0049513408 | E16: =FS!E17/FS!E$3 -> -0.35109664 | F16: =FS!F17/FS!F$3 -> -0.16428983 | G16: =FS!G17/FS!G$3 -> -0.087779364 | H16: =FS!H17/FS!H$3 -> 0.023880521 | I16: =FS!I17/FS!I$3 -> 0.19706303 | J16: =FS!J17/FS!J$3 -> 0.069731339
B18: WASO | C18: 62500000 | D18: 62500000 | E18: 62500000 | F18: 62500000 | G18: 62500000 | H18: 62500000 | I18: 62500000 | J18: 62500000
B19: REPORTED / ACTUAL EPS | C19: 0.931072 | D19: 0.05008 | E19: -1.872272 | F19: -1.199392 | G19: -0.740032 | H19: 0.2413 | I19: 2.86 | J19: 1.0385
A21: Balance Sheet
B22: PP&E | C22: =FS!C23/FS!C$39 -> 0.24270268 | D22: =FS!D23/FS!D$39 -> 0.19848036 | E22: =FS!E23/FS!E$39 -> 0.28411481 | F22: =FS!F23/FS!F$39 -> 0.40376086 | G22: =FS!G23/FS!G$39 -> 0.34288089 | H22: =FS!H23/FS!H$39 -> 0.32482987 | I22: =FS!I23/FS!I$39 -> 0.26955554 | J22: =FS!J23/FS!J$39 -> 0.29089179
B23: Lease-Right-of-Use assets | C23: =FS!C24/FS!C$39 -> 0 | D23: =FS!D24/FS!D$39 -> 0 | E23: =FS!E24/FS!E$39 -> 0.027437809 | F23: =FS!F24/FS!F$39 -> 0.034159317 | G23: =FS!G24/FS!G$39 -> 0.026807584 | H23: =FS!H24/FS!H$39 -> 0.055278152 | I23: =FS!I24/FS!I$39 -> 0.061133077 | J23: =FS!J24/FS!J$39 -> 0.059361824
B24: Intangible assets | C24: =FS!C25/FS!C$39 -> 1.4937125e-05 | D24: =FS!D25/FS!D$39 -> 0 | E24: =FS!E25/FS!E$39 -> 0 | F24: =FS!F25/FS!F$39 -> 0 | G24: =FS!G25/FS!G$39 -> 0 | H24: =FS!H25/FS!H$39 -> 0 | I24: =FS!I25/FS!I$39 -> 0 | J24: =FS!J25/FS!J$39 -> 0
B25: Deferred tax asset | C25: =FS!C26/FS!C$39 -> 0 | D25: =FS!D26/FS!D$39 -> 0 | E25: =FS!E26/FS!E$39 -> 0.096993125 | F25: =FS!F26/FS!F$39 -> 0.073093432 | G25: =FS!G26/FS!G$39 -> 0.063995755 | H25: =FS!H26/FS!H$39 -> 0.058673383 | I25: =FS!I26/FS!I$39 -> 0.053666947 | J25: =FS!J26/FS!J$39 -> 0
B26: Investment in subsidiaries | C26: =FS!C27/FS!C$39 -> 2.1338751e-05 | D26: =FS!D27/FS!D$39 -> 1.3764814e-05 | E26: =FS!E27/FS!E$39 -> 2.0442415e-05 | F26: =FS!F27/FS!F$39 -> 2.9786638e-05 | G26: =FS!G27/FS!G$39 -> 2.8755088e-05 | H26: =FS!H27/FS!H$39 -> 0 | I26: =FS!I27/FS!I$39 -> 0 | J26: =FS!J27/FS!J$39 -> 0
B27: Other Investment | C27: =FS!C28/FS!C$39 -> 0 | D27: =FS!D28/FS!D$39 -> 0 | E27: =FS!E28/FS!E$39 -> 0 | F27: =FS!F28/FS!F$39 -> 0 | G27: =FS!G28/FS!G$39 -> 0 | H27: =FS!H28/FS!H$39 -> 2.671498e-05 | I27: =FS!I28/FS!I$39 -> 2.4283686e-05 | J27: =FS!J28/FS!J$39 -> 0
B28: Non-current assets | C28: =FS!C29/FS!C$39 -> 0.24273896 | D28: =FS!D29/FS!D$39 -> 0.19849413 | E28: =FS!E29/FS!E$39 -> 0.40856619 | F28: =FS!F29/FS!F$39 -> 0.5110434 | G28: =FS!G29/FS!G$39 -> 0.43371299 | H28: =FS!H29/FS!H$39 -> 0.43880812 | I28: =FS!I29/FS!I$39 -> 0.38437985 | J28: =FS!J29/FS!J$39 -> 0.35025362
B29: Current Assets | C29: =FS!C30/FS!C$39 -> 0 | D29: =FS!D30/FS!D$39 -> 0 | E29: =FS!E30/FS!E$39 -> 0 | F29: =FS!F30/FS!F$39 -> 0 | G29: =FS!G30/FS!G$39 -> 0 | H29: =FS!H30/FS!H$39 -> 0 | I29: =FS!I30/FS!I$39 -> 0 | J29: =FS!J30/FS!J$39 -> 0
B30: Inventories | C30: =FS!C31/FS!C$39 -> 0.11441411 | D30: =FS!D31/FS!D$39 -> 0.073553662 | E30: =FS!E31/FS!E$39 -> 0.23643492 | F30: =FS!F31/FS!F$39 -> 0.28899294 | G30: =FS!G31/FS!G$39 -> 0.23952204 | H30: =FS!H31/FS!H$39 -> 0.3113801 | I30: =FS!I31/FS!I$39 -> 0.22449385 | J30: =FS!J31/FS!J$39 -> 0.28610558
B31: Trade and other receivables | C31: =FS!C32/FS!C$39 -> 0.20044982 | D31: =FS!D32/FS!D$39 -> 0.37200925 | E31: =FS!E32/FS!E$39 -> 0.23368951 | F31: =FS!F32/FS!F$39 -> 0.076369962 | G31: =FS!G32/FS!G$39 -> 0.064147372 | H31: =FS!H32/FS!H$39 -> 0.081959131 | I31: =FS!I32/FS!I$39 -> 0.092275801 | J31: =FS!J32/FS!J$39 -> 0.10906474
B32: Prepayments | C32: =FS!C33/FS!C$39 -> 0.061342506 | D32: =FS!D33/FS!D$39 -> 0.031301188 | E32: =FS!E33/FS!E$39 -> 0.0027842569 | F32: =FS!F33/FS!F$39 -> 0.0019420888 | G32: =FS!G33/FS!G$39 -> 0.0094970212 | H32: =FS!H33/FS!H$39 -> 0.0033223721 | I32: =FS!I33/FS!I$39 -> 0.0052143698 | J32: =FS!J33/FS!J$39 -> 0.0037748487
B33: Related party receivables | C33: =FS!C34/FS!C$39 -> 0.26728706 | D33: =FS!D34/FS!D$39 -> 0.31370563 | E33: =FS!E34/FS!E$39 -> 0.073371915 | F33: =FS!F34/FS!F$39 -> 0.06654335 | G33: =FS!G34/FS!G$39 -> 0.14690974 | H33: =FS!H34/FS!H$39 -> 0.024045911 | I33: =FS!I34/FS!I$39 -> 0.018857386 | J33: =FS!J34/FS!J$39 -> 0.020881434
... B36: Total Current assets | C36: =FS!C37/FS!C$39 -> 0.75726104 | D36: =FS!D37/FS!D$39 -> 0.80150587 | E36: =FS!E37/FS!E$39 -> 0.59143381 | F36: =FS!F37/FS!F$39 -> 0.4889566 | G36: =FS!G37/FS!G$39 -> 0.56628701 | H36: =FS!H37/FS!H$39 -> 0.56119188 | I36: =FS!I37/FS!I$39 -> 0.61562015 | J36: =FS!J37/FS!J$39 -> 0.64974638
C37: =FS!C38/FS!C$39 -> 0 | D37: =FS!D38/FS!D$39 -> 0 | E37: =FS!E38/FS!E$39 -> 0 | F37: =FS!F38/FS!F$39 -> 0 | G37: =FS!G38/FS!G$39 -> 0 | H37: =FS!H38/FS!H$39 -> 0 | I37: =FS!I38/FS!I$39 -> 0 | J37: =FS!J38/FS!J$39 -> 0
B38: Total assets | C38: =FS!C39/FS!C$39 -> 1 | D38: =FS!D39/FS!D$39 -> 1 | E38: =FS!E39/FS!E$39 -> 1 | F38: =FS!F39/FS!F$39 -> 1 | G38: =FS!G39/FS!G$39 -> 1 | H38: =FS!H39/FS!H$39 -> 1 | I38: =FS!I39/FS!I$39 -> 1 | J38: =FS!J39/FS!J$39 -> 1
C39: =FS!C40/FS!C$39 -> 0 | D39: =FS!D40/FS!D$39 -> 0 | E39: =FS!E40/FS!E$39 -> 0 | F39: =FS!F40/FS!F$39 -> 0 | G39: =FS!G40/FS!G$39 -> 0 | H39: =FS!H40/FS!H$39 -> 0 | I39: =FS!I40/FS!I$39 -> 0 | J39: =FS!J40/FS!J$39 -> 0
B40: Equity | C40: =FS!C41/FS!C$39 -> 0 | D40: =FS!D41/FS!D$39 -> 0 | E40: =FS!E41/FS!E$39 -> 0 | F40: =FS!F41/FS!F$39 -> 0 | G40: =FS!G41/FS!G$39 -> 0 | H40: =FS!H41/FS!H$39 -> 0 | I40: =FS!I41/FS!I$39 -> 0 | J40: =FS!J41/FS!J$39 -> 0
B41: Share Capital | C41: =FS!C42/FS!C$39 -> 0.0025606501 | D41: =FS!D42/FS!D$39 -> 0.0016517777 | E41: =FS!E42/FS!E$39 -> 0.0024530898 | F41: =FS!F42/FS!F$39 -> 0.0035743966 | G41: =FS!G42/FS!G$39 -> 0.0031369187 | H41: =FS!H42/FS!H$39 -> 0.0029143615 | I41: =FS!I42/FS!I$39 -> 0.0026491294 | J41: =FS!J42/FS!J$39 -> 0.0026614679
B42: Capital surplus account | C42: =FS!C43/FS!C$39 -> 0.00043531051 | D42: =FS!D43/FS!D$39 -> 0.00028080221 | E42: =FS!E43/FS!E$39 -> 0.00041702526 | F42: =FS!F43/FS!F$39 -> 0.00060764742 | G42: =FS!G43/FS!G$39 -> 0.00053327617 | H42: =FS!H43/FS!H$39 -> 0.00049544145 | I42: =FS!I43/FS!I$39 -> 0.000450352 | J42: =FS!J43/FS!J$39 -> 0.00045244955
B43: Retained earnings | C43: =FS!C44/FS!C$39 -> 0.25417013 | D43: =FS!D44/FS!D$39 -> 0.40421203 | E43: =FS!E44/FS!E$39 -> 0.1706267 | F43: =FS!F44/FS!F$39 -> 0.099231207 | G43: =FS!G44/FS!G$39 -> 0.092248935 | H43: =FS!H44/FS!H$39 -> 0.1246691 | I43: =FS!I44/FS!I$39 -> 0.50740101 | J43: =FS!J44/FS!J$39 -> 0.51293363
B44: Share deals account | C44: =FS!C45/FS!C$39 -> 0.00017284388 | D44: =FS!D45/FS!D$39 -> 0.000111495 | E44: =FS!E45/FS!E$39 -> 0.00016558356 | F44: =FS!F45/FS!F$39 -> 0.00024127177 | G44: =FS!G45/FS!G$39 -> 0.00021174201 | H44: =FS!H45/FS!H$39 -> 0.0001967194 | I44: =FS!I45/FS!I$39 -> 0.00017881624 | J44: =FS!J45/FS!J$39 -> 0.00017964909
B45: Total equity | C45: =FS!C46/FS!C$39 -> 0.25733893 | D45: =FS!D46/FS!D$39 -> 0.40625611 | E45: =FS!E46/FS!E$39 -> 0.1736624 | F45: =FS!F46/FS!F$39 -> 0.10365452 | G45: =FS!G46/FS!G$39 -> 0.096130872 | H45: =FS!H46/FS!H$39 -> 0.12827562 | I45: =FS!I46/FS!I$39 -> 0.5106793 | J45: =FS!J46/FS!J$39 -> 0.51622719
C46: =FS!C47/FS!C$39 -> 0 | D46: =FS!D47/FS!D$39 -> 0 | E46: =FS!E47/FS!E$39 -> 0 | F46: =FS!F47/FS!F$39 -> 0 | G46: =FS!G47/FS!G$39 -> 0 | H46: =FS!H47/FS!H$39 -> 0 | I46: =FS!I47/FS!I$39 -> 0 | J46: =FS!J47/FS!J$39 -> 0
...

Sheet Ratios
A1: FINANCIAL RATIOS
B2: Days in a year | D2: 360
C3: =FS!C2 -> 2017 | D3: =FS!D2 -> 2018 | E3: =FS!E2 -> 2019 | F3: =FS!F2 -> 2020 | G3: =FS!G2 -> 2021 | H3: =FS!H2 -> 2022 | I3: =FS!I2 -> 2023 | J3: =FS!J2 -> 2024 | K3: Average
A4: PROFITABILITY
B5: Gross margins | C5: =FS!C5/FS!C3 -> 0.30229868 | D5: =FS!D5/FS!D3 -> 0.30239721 | E5: =FS!E5/FS!E3 -> -0.046188004 | F5: =FS!F5/FS!F3 -> 0.1658963 | G5: =FS!G5/FS!G3 -> 0.18417876 | H5: =FS!H5/FS!H3 -> 0.24640802 | I5: =FS!I5/FS!I3 -> 0.37084015 | J5: =FS!J5/FS!J3 -> 0.37373187 | K5: =AVERAGE(C5:J5) -> 0.23744537
B6: Operating Margins | C6: =FS!C12/FS!C3 -> 0.13416411 | D6: =FS!D12/FS!D3 -> 0.10371398 | E6: =FS!E12/FS!E3 -> -0.48701131 | F6: =FS!F12/FS!F3 -> -0.10218309 | G6: =FS!G12/FS!G3 -> -0.083226421 | H6: =FS!H12/FS!H3 -> 0.051379544 | I6: =FS!I12/FS!I3 -> 0.2462941 | J6: =FS!J12/FS!J3 -> 0.10300053 | K6: =AVERAGE(C6:J6) -> -0.0042335699
B7: Net profit Margin | C7: =FS!C17/FS!C3 -> 0.10106901 | D7: =FS!D17/FS!D3 -> 0.0049513408 | E7: =FS!E17/FS!E3 -> -0.35109664 | F7: =FS!F17/FS!F3 -> -0.16428983 | G7: =FS!G17/FS!G3 -> -0.087779364 | H7: =FS!H17/FS!H3 -> 0.023880521 | I7: =FS!I17/FS!I3 -> 0.19706303 | J7: =FS!J17/FS!J3 -> 0.069731339 | K7: =AVERAGE(C7:J7) -> -0.025808825
B8: Return on Assets | C8: =FS!C17/FS!C39 -> 0.12417446 | D8: =FS!D17/FS!D39 -> 0.0043083869 | E8: =FS!E17/FS!E39 -> -0.239211 | F8: =FS!F17/FS!F39 -> -0.2232866 | G8: =FS!G17/FS!G39 -> -0.1209073 | H8: =FS!H17/FS!H39 -> 0.036623809 | I8: =FS!I17/FS!I39 -> 0.39507792 | J8: =FS!J17/FS!J39 -> 0.14395436 | K8: =AVERAGE(C8:J8) -> 0.015091754
B9: Return on Assets (Operating profit) | C9: =FS!C12/FS!C39 -> 0.16483545 | D9: =FS!D12/FS!D39 -> 0.090246253 | E9: =FS!E12/FS!E39 -> -0.3318131 | F9: =FS!F12/FS!F39 -> -0.13887722 | G9: =FS!G12/FS!G39 -> -0.11463608 | H9: =FS!H12/FS!H39 -> 0.078797049 | I9: =FS!I12/FS!I39 -> 0.49377786 | J9: =FS!J12/FS!J39 -> 0.21263576 | K9: =AVERAGE(C9:J9) -> 0.056870746
B10: Return on Equity | C10: =FS!C17/FS!C46 -> 0.48253273 | D10: =FS!D17/FS!D46 -> 0.010605101 | E10: =FS!E17/FS!E46 -> -1.3774484 | F10: =FS!F17/FS!F46 -> -2.1541424 | G10: =FS!G17/FS!G46 -> -1.2577364 | H10: =FS!H17/FS!H46 -> 0.28550873 | I10: =FS!I17/FS!I46 -> 0.77363213 | J10: =FS!J17/FS!J46 -> 0.27885855 | K10: =AVERAGE(C10:J10) -> -0.36977375
B11: Return on Equity (Operating profit) | C11: =FS!C12/FS!C46 -> 0.64053832 | D11: =FS!D12/FS!D46 -> 0.22214128 | E11: =FS!E12/FS!E46 -> -1.910679 | F11: =FS!F12/FS!F46 -> -1.3398086 | G11: =FS!G12/FS!G46 -> -1.1925001 | H11: =FS!H12/FS!H46 -> 0.61427922 | I11: =FS!I12/FS!I46 -> 0.96690399 | J11: =FS!J12/FS!J46 -> 0.41190345 | K11: =AVERAGE(C11:J11) -> -0.19840268
A14: LIQUIDITY
B15: Current ratio | C15: =FS!C37/FS!C61 -> 1.0592491 | D15: =FS!D37/FS!D61 -> 1.3917169 | E15: =FS!E37/FS!E61 -> 0.72442441 | F15: =FS!F37/FS!F61 -> 0.55208284 | G15: =FS!G37/FS!G61 -> 0.63428503 | H15: =FS!H37/FS!H61 -> 0.66829494 | I15: =FS!I37/FS!I61 -> 1.3705429 | J15: =FS!J37/FS!J61 -> 1.4837172 | K15: =AVERAGE(C15:J15) -> 0.98553918
B16: Quick Ratio | C16: =(FS!C37-FS!C31)/FS!C61 -> 0.89920782 | D16: =(FS!D37-FS!D31)/FS!D61 -> 1.264 | E16: =(FS!E37-FS!E31)/FS!E61 -> 0.43482441 | F16: =(FS!F37-FS!F31)/FS!F61 -> 0.22577976 | G16: =(FS!G37-FS!G31)/FS!G61 -> 0.36600191 | H16: =(FS!H37-FS!H31)/FS!H61 -> 0.29748818 | I16: =(FS!I37-FS!I31)/FS!I61 -> 0.87075672 | J16: =(FS!J37-FS!J31)/FS!J61 -> 0.83038572 | K16: =AVERAGE(C16:J16) -> 0.64855556
B17: Cash ratio | C17: =FS!C36/FS!C61 -> 0.1588026 | D17: =FS!D36/FS!D61 -> 0.018989278 | E17: =FS!E36/FS!E61 -> 0.029688889 | F17: =FS!F36/FS!F61 -> 0.020001076 | G17: =FS!G36/FS!G61 -> 0.07719065 | H17: =FS!H36/FS!H61 -> 0.12292742 | I17: =FS!I36/FS!I61 -> 0.53431727 | J17: =FS!J36/FS!J61 -> 0.49142053 | K17: =AVERAGE(C17:J17) -> 0.18166721
A20: EFFICIENCY
B21: Receivables turnover | C21: =FS!C3/FS!C32 -> 6.1292675 | D21: =FS!D3/AVERAGE(FS!C32,FS!D32) -> 3.4714743 | E21: =FS!E3/AVERAGE(FS!D32,FS!E32) -> 1.733281 | F21: =FS!F3/AVERAGE(FS!E32,FS!F32) -> 6.5203673 | G21: =FS!G3/AVERAGE(FS!F32,FS!G32) -> 21.001714 | H21: =FS!H3/AVERAGE(FS!G32,FS!H32) -> 21.668222 | I21: =FS!I3/AVERAGE(FS!H32,FS!I32) -> 24.042199 | J21: =FS!J3/AVERAGE(FS!I32,FS!J32) -> 20.463011 | K21: =AVERAGE(C21:J21) -> 13.128692
B22: Receivables days | C22: =$D$2/C21 -> 58.734588 | D22: =$D$2/D21 -> 103.70234 | E22: =$D$2/E21 -> 207.69858 | F22: =$D$2/F21 -> 55.211614 | G22: =$D$2/G21 -> 17.141458 | H22: =$D$2/H21 -> 16.614192 | I22: =$D$2/I21 -> 14.973672 | J22: =$D$2/J21 -> 17.592719 | K22: =AVERAGE(C22:J22) -> 61.458645
B23: Inventory turnover | C23: =-FS!C4/FS!C31 -> 7.4921109 | D23: =-FS!D4/AVERAGE(FS!C31,FS!D31) -> 8.2386646 | E23: =-FS!E4/AVERAGE(FS!D31,FS!E31) -> 4.1241196 | F23: =-FS!F4/AVERAGE(FS!E31,FS!F31) -> 3.5789355 | G23: =-FS!G4/AVERAGE(FS!F31,FS!G31) -> 4.5573343 | H23: =-FS!H4/AVERAGE(FS!G31,FS!H31) -> 4.3293137 | I23: =-FS!I4/AVERAGE(FS!H31,FS!I31) -> 4.9705224 | J23: =-FS!J4/AVERAGE(FS!I31,FS!J31) -> 5.0538038 | K23: =AVERAGE(C23:J23) -> 5.2931006
B24: Inventory days | C24: =$D$2/C23 -> 48.050544 | D24: =$D$2/D23 -> 43.696402 | E24: =$D$2/E23 -> 87.291358 | F24: =$D$2/F23 -> 100.58857 | G24: =$D$2/G23 -> 78.993547 | H24: =$D$2/H23 -> 83.154057 | I24: =$D$2/I23 -> 72.426996 | J24: =$D$2/J23 -> 71.233474 | K24: =AVERAGE(C24:J24) -> 73.179368
B25: Payables turnover | C25: =-FS!C4/FS!C55 -> 5.4278804 | D25: =-FS!D4/AVERAGE(FS!C55,FS!D55) -> 6.1314749 | E25: =-FS!E4/AVERAGE(FS!D55,FS!E55) -> 4.4432211 | F25: =-FS!F4/AVERAGE(FS!E55,FS!F55) -> 4.0031766 | G25: =-FS!G4/AVERAGE(FS!F55,FS!G55) -> 4.405132 | H25: =-FS!H4/AVERAGE(FS!G55,FS!H55) -> 5.385223 | I25: =-FS!I4/AVERAGE(FS!H55,FS!I55) -> 5.670706 | J25: =-FS!J4/AVERAGE(FS!I55,FS!J55) -> 5.2709336 | K25: =AVERAGE(C25:J25) -> 5.0922185
B26: Payables days | C26: =$D$2/C25 -> 66.324232 | D26: =$D$2/D25 -> 58.713443 | E26: =$D$2/E25 -> 81.022301 | F26: =$D$2/F25 -> 89.928583 | G26: =$D$2/G25 -> 81.722862 | H26: =$D$2/H25 -> 66.849599 | I26: =$D$2/I25 -> 63.484158 | J26: =$D$2/J25 -> 68.299095 | K26: =AVERAGE(C26:J26) -> 72.043034
B28: Cash Conversion Cycle | C28: =C22+C24-C26 -> 40.460899 | D28: =D22+D24-D26 -> 88.685296 | E28: =E22+E24-E26 -> 213.96764 | F28: =F22+F24-F26 -> 65.8716 | G28: =G22+G24-G26 -> 14.412143 | H28: =H22+H24-H26 -> 32.918649 | I28: =I22+I24-I26 -> 23.916509 | J28: =J22+J24-J26 -> 20.527097 | K28: =AVERAGE(C28:J28) -> 62.594979
A31: LEVERAGE
B32: Interest coverage ratio | C32: =-FS!C12/FS!C14 -> 38.546407 | D32: =-FS!D12/FS!D14 -> 19.42032 | E32: =-FS!E12/FS!E14 -> -13.989141 | F32: =-FS!F12/FS!F14 -> -8.3138374 | G32: =-FS!G12/FS!G14 -> -15.007871 | H32: =-FS!H12/FS!H14 -> 1.7582507 | I32: =-FS!I12/FS!I14 -> 22.369337 | J32: =-FS!J12/FS!J14 -> 17.870084 | K32: =AVERAGE(C32:J32) -> 7.8316936
B33: Total debt to equity | C33: =FS!C62/FS!C46 -> 2.8859259 | D33: =FS!D62/FS!D46 -> 1.4615015 | E33: =FS!E62/FS!E46 -> 4.7582988 | F33: =FS!F62/FS!F46 -> 8.6474324 | G33: =FS!G62/FS!G46 -> 9.4024855 | H33: =FS!H62/FS!H46 -> 6.7957136 | I33: =FS!I62/FS!I46 -> 0.95817609 | J33: =FS!J62/FS!J46 -> 0.93713159 | K33: =AVERAGE(C33:J33) -> 4.4808332
B34: Long term debt to equity | C34: =FS!C52/FS!C46 -> 0.10786338 | D34: =FS!D52/FS!D46 -> 0.043894274 | E34: =FS!E52/FS!E46 -> 0.057114606 | F34: =FS!F52/FS!F46 -> 0.10310641 | G34: =FS!G52/FS!G46 -> 0.11519008 | H34: =FS!H52/FS!H46 -> 0.24936575 | I34: =FS!I52/FS!I46 -> 0.078603017 | J34: =FS!J52/FS!J46 -> 0.088826926 | K34: =AVERAGE(C34:J34) -> 0.10549555
B37: REVENUE -5YR CAGR | J37: =((FS!J3/FS!F3)^(1/5)-1) -> 0.1532548
A39: SALES VOLATILITY
B40: STANDARD DEVIATION | J40: =_xlfn.STDEV.S(FS!C3:J3) -> 206806.5
B41: MEAN | J41: =GEOMEAN(FS!C3:J3) -> 594331.11
B42: CO-EFFICIENT OF VARIATION | J42: =J40/J41 -> 0.34796513
A44: EARNINGS VOLATILIYY
B45: STANDARD DEVIATION | J45: =_xlfn.STDEV.S(FS!C17:J17) -> 92946.933
B46: MEAN | J46: =AVERAGE(FS!C17:J17) -> 10254.875
B47: CO-EFFICIENT OF VARIATION | J47: =J45/J46 -> 9.0636827
A49: Investment Ratios
B50: Earning per Shares | C50: =FS!C17/(FS!C19*0.001) -> 0.931072 | D50: =FS!D17/(FS!D19*0.001) -> 0.05008 | E50: =FS!E17/(FS!E19*0.001) -> -1.872272 | F50: =FS!F17/(FS!F19*0.001) -> -1.199392 | G50: =FS!G17/(FS!G19*0.001) -> -0.740032 | H50: =FS!H17/(FS!H19*0.001) -> 0.24128 | I50: =FS!I17/(FS!I19*0.001) -> 2.863392 | J50: =FS!J17/(FS!J19*0.001) -> 1.038496
B51: PRICE/EARNINGS | C51: =19.52/C50 -> 20.965081 | D51: =19.52/D50 -> 389.77636 | E51: =19.52/E50 -> -10.425836 | F51: =19.52/F50 -> -16.274913 | G51: =19.52/G50 -> -26.377238 | H51: =19.52/H50 -> 80.901857 | I51: =19.52/I50 -> 6.8170897 | J51: =19.52/J50 -> 18.796413
B52: Return on Equity | C52: =FS!C17/FS!C46 -> 0.48253273 | D52: =FS!D17/FS!D46 -> 0.010605101 | E52: =FS!E17/FS!E46 -> -1.3774484 | F52: =FS!F17/FS!F46 -> -2.1541424 | G52: =FS!G17/FS!G46 -> -1.2577364 | H52: =FS!H17/FS!H46 -> 0.28550873 | I52: =FS!I17/FS!I46 -> 0.77363213 | J52: =FS!J17/FS!J46 -> 0.27885855
...

Sheet Adjustment
C1: 2017 | D1: =C1+1 -> 2018 | E1: =D1+1 -> 2019 | F1: =E1+1 -> 2020 | G1: =F1+1 -> 2021 | H1: =G1+1 -> 2022 | I1: =H1+1 -> 2023 | J1: =I1+1 -> 2024
B2: =FS!B3 -> Revenue | C2: =FS!C3 -> 575765 | D2: =FS!D3 -> 632152 | E2: =FS!E3 -> 333290 | F2: =FS!F3 -> 456279 | G2: =FS!G3 -> 526912 | H2: =FS!H3 -> 631477 | I2: =FS!I3 -> 908146 | J2: =FS!J3 -> 930801
B3: Operating expense | C3: =(FS!C4+Adjustment!C26)+FS!C6+FS!C7+FS!C8 -> -488813 | D3: =(FS!D4+Adjustment!D26)+FS!D6+FS!D7+FS!D8 -> -557056 | E3: =(FS!E4+Adjustment!E26)+FS!E6+FS!E7+FS!E8 -> -484564 | F3: =(FS!F4+Adjustment!F26)+FS!F6+FS!F7+FS!F8 -> -488792 | G3: =(FS!G4+Adjustment!G26)+FS!G6+FS!G7+FS!G8 -> -557427 | H3: =(FS!H4+Adjustment!H26)+FS!H6+FS!H7+FS!H8 -> -586954 | I3: =(FS!I4+Adjustment!I26)+FS!I6+FS!I7+FS!I8 -> -653747 | J3: =(FS!J4+Adjustment!J26)+FS!J6+FS!J7+FS!J8 -> -806639
B4: EBITDA | C4: =SUM(C2:C3) -> 86952 | D4: =SUM(D2:D3) -> 75096 | E4: =SUM(E2:E3) -> -151274 | F4: =SUM(F2:F3) -> -32513 | G4: =SUM(G2:G3) -> -30515 | H4: =SUM(H2:H3) -> 44523 | I4: =SUM(I2:I3) -> 254399 | J4: =SUM(J2:J3) -> 124162
B5: Depriciation & Amortization | C5: =C22+C23 -> 9705 | D5: =D22+D23 -> 9533 | E5: =E22+E23 -> 11042 | F5: =F22+F23 -> 13221 | G5: =G22+G23 -> 13332 | H5: =H22+H23 -> 14595 | I5: =I22+I23 -> 19084 | J5: =J22+J23 -> 19914
B6: EBIT | C6: =C4-C5 -> 77247 | D6: =D4-D5 -> 65563 | E6: =E4-E5 -> -162316 | F6: =F4-F5 -> -45734 | G6: =G4-G5 -> -43847 | H6: =H4-H5 -> 29928 | I6: =I4-I5 -> 235315 | J6: =J4-J5 -> 104248
B7: Net Interest expense | C7: =FS!C13+FS!C14 -> -1844 | D7: =FS!D13+FS!D14 -> -2936 | E7: =FS!E13+FS!E14 -> -11032 | F7: =FS!F13+FS!F14 -> -5508 | G7: =FS!G13+FS!G14 -> -2348 | H7: =FS!H13+FS!H14 -> -17365 | I7: =FS!I13+FS!I14 -> -8450 | J7: =FS!J13+FS!J14 -> -3626
B8: EBT | C8: =SUM(C6:C7) -> 75403 | D8: =SUM(D6:D7) -> 62627 | E8: =SUM(E6:E7) -> -173348 | F8: =SUM(F6:F7) -> -51242 | G8: =SUM(G6:G7) -> -46195 | H8: =SUM(H6:H7) -> 12563 | I8: =SUM(I6:I7) -> 226865 | J8: =SUM(J6:J7) -> 100622
B9: Tax | C9: =FS!C16 -> -17211 | D9: =FS!D16 -> -59497 | E9: =FS!E16 -> 56331 | F9: =FS!F16 -> -22830 | G9: =FS!G16 -> -51 | H9: =FS!H16 -> 0 | I9: =FS!I16 -> -36259 | J9: =FS!J16 -> -27341
B10: NOPAT | C10: =SUM(C8:C9) -> 58192 | D10: =SUM(D8:D9) -> 3130 | E10: =SUM(E8:E9) -> -117017 | F10: =SUM(F8:F9) -> -74072 | G10: =SUM(G8:G9) -> -46246 | H10: =SUM(H8:H9) -> 12563 | I10: =SUM(I8:I9) -> 190606 | J10: =SUM(J8:J9) -> 73281
B21: Adjustments:
B22: Depreciation | C22: 8333 | D22: 9526 | E22: =8574+2468 -> 11042 | F22: =11425+1796 -> 13221 | G22: =12119+1213 -> 13332 | H22: =12854+1741 -> 14595 | I22: =14012+5072 -> 19084 | J22: =12141+7773 -> 19914
B23: Amortization | C23: 1372 | D23: 7 | E23: 0 | F23: =0 -> 0 | J23: 0
B24: Profit on PPE from ordinary course of business | G24: -44 | H24: -75 | I24: -320 | J24: 0
B25: Write off of PPE | F25: 890 | G25: 50 | H25: 0 | I25: 20584 | J25: 0
C26: =SUM(C22:C25) -> 9705 | D26: =SUM(D22:D25) -> 9533 | E26: =SUM(E22:E25) -> 11042 | F26: =SUM(F22:F25) -> 14111 | G26: =SUM(G22:G25) -> 13338 | H26: =SUM(H22:H25) -> 14520 | I26: =SUM(I22:I25) -> 39348 | J26: =SUM(J22:J25) -> 19914

Sheet EV
B1: Equity Value Calculations
B2: Share Price@ 14/03/2025 | E2: =19.52 -> 19.52
B3: Shares Outstanding | E3: =FS!J19*(0.001) -> 62500
B4: Market Cap | E4: =Share_Price*E3 -> 1220000
B6: Enterprise Value
B7: =B4:E4 -> Market Cap | E7: =E4:H4 -> 1220000
B8: Net Debt | E8: =J25 -> -79900
B9: Enterprise Value | E9: =SUM(E7:E8) -> 1140100
C19: =FS!$C$2 -> 2017 | D19: =FS!$D$2 -> 2018 | E19: =FS!E2 -> 2019 | F19: =FS!F2 -> 2020 | G19: =FS!G2 -> 2021 | H19: =FS!H2 -> 2022 | I19: =FS!I2 -> 2023 | J19: =FS!J2 -> 2024
B20: =FS!B51 -> Long term lease liability | C20: =FS!C51 -> 0 | D20: =FS!D51 -> 0 | E20: =FS!E51 -> 1116 | F20: =FS!F51 -> 166 | G20: =FS!G51 -> 0 | H20: =FS!H51 -> 6978 | I20: =FS!I51 -> 11241 | J20: =FS!J51 -> 13218
B21: =FS!B54 -> Bank overdraft | C21: =FS!C54 -> 14 | D21: =FS!D54 -> 73508 | E21: =FS!E54 -> 65202 | F21: =FS!F54 -> 6892 | G21: =FS!G54 -> 52055 | H21: =FS!H54 -> 99646 | I21: =FS!I54 -> 0 | J21: =FS!J54 -> 0
B22: =FS!B59 -> Short term lease liability | C22: =FS!C59 -> 0 | D22: =FS!D59 -> 26612 | E22: =FS!E59 -> 1796 | F22: =FS!F59 -> 1345 | G22: =FS!G59 -> 176 | H22: =FS!H59 -> 3550 | I22: =FS!I59 -> 5953 | J22: =FS!J59 -> 3912
B23: Total Interest Bearing Debt | C23: =SUM(C20:C22) -> 14 | D23: =SUM(D20:D22) -> 100120 | E23: =SUM(E20:E22) -> 68114 | F23: =SUM(F20:F22) -> 8403 | G23: =SUM(G20:G22) -> 52231 | H23: =SUM(H20:H22) -> 110174 | I23: =SUM(I20:I22) -> 17194 | J23: =SUM(J20:J22) -> 17130
B24: Cash | C24: =FS!C36 -> 53203 | D24: =FS!D36 -> 7945 | E24: =FS!E36 -> 11857 | F24: =FS!F36 -> 5947 | G24: =FS!G36 -> 26363 | H24: =FS!H36 -> 42504 | I24: =FS!I36 -> 108717 | J24: =FS!J36 -> 97030
B25: Net Debt | C25: =C23-C24 -> -53189 | D25: =D23-D24 -> 92175 | E25: =E23-E24 -> 56257 | F25: =F23-F24 -> 2456 | G25: =G23-G24 -> 25868 | H25: =H23-H24 -> 67670 | I25: =I23-I24 -> -91523 | J25: =J23-J24 -> -79900
B29: Valuation Multiples
C30: =C19 -> 2017 | D30: =D19 -> 2018 | E30: =E19 -> 2019 | F30: =F19 -> 2020 | G30: =G19 -> 2021 | H30: =H19 -> 2022 | I30: =I19 -> 2023 | J30: =J19 -> 2024
B31: Enterprise Value Multiples
B32: EV/ Revenue | C32: =IF(($E$9/FS!C3)>0,$E$9/FS!C3,"NMF") -> 1.9801482 | D32: =IF(($E$9/FS!D3)>0,$E$9/FS!D3,"NMF") -> 1.8035219 | E32: =IF(($E$9/FS!E3)>0,$E$9/FS!E3,"NMF") -> 3.4207447 | F32: =IF(($E$9/FS!F3)>0,$E$9/FS!F3,"NMF") -> 2.4986905 | G32: =IF(($E$9/FS!G3)>0,$E$9/FS!G3,"NMF") -> 2.1637389 | H32: =IF(($E$9/FS!H3)>0,$E$9/FS!H3,"NMF") -> 1.8054498 | I32: =IF(($E$9/FS!I3)>0,$E$9/FS!I3,"NMF") -> 1.2554149 | J32: =IF(($E$9/FS!J3)>0,$E$9/FS!J3,"NMF") -> 1.224859
B33: EV/EBITDA | C33: =IF(($E$9/Adjustment!C4)>0,$E$9/Adjustment!C4,"NMF") -> 13.111832 | D33: =IF(($E$9/Adjustment!D4)>0,$E$9/Adjustment!D4,"NMF") -> 15.181901 | E33: =IF(($E$9/Adjustment!E4)>0,$E$9/Adjustment!E4,"NMF") -> NMF | F33: =IF(($E$9/Adjustment!F4)>0,$E$9/Adjustment!F4,"NMF") -> NMF | G33: =IF(($E$9/Adjustment!G4)>0,$E$9/Adjustment!G4,"NMF") -> NMF | H33: =IF(($E$9/Adjustment!H4)>0,$E$9/Adjustment!H4,"NMF") -> 25.60699 | I33: =IF(($E$9/Adjustment!I4)>0,$E$9/Adjustment!I4,"NMF") -> 4.4815428 | J33: =IF(($E$9/Adjustment!J4)>0,$E$9/Adjustment!J4,"NMF") -> 9.1823585
B34: EV/ EBIT | C34: =IF(($E$9/Adjustment!C6)>0,$E$9/Adjustment!C6,"NMF") -> 14.759149 | D34: =IF(($E$9/Adjustment!D6)>0,$E$9/Adjustment!D6,"NMF") -> 17.389381 | E34: =IF(($E$9/Adjustment!E6)>0,$E$9/Adjustment!E6,"NMF") -> NMF | F34: =IF(($E$9/Adjustment!F6)>0,$E$9/Adjustment!F6,"NMF") -> NMF | G34: =IF(($E$9/Adjustment!G6)>0,$E$9/Adjustment!G6,"NMF") -> NMF | H34: =IF(($E$9/Adjustment!H6)>0,$E$9/Adjustment!H6,"NMF") -> 38.094761 | I34: =IF(($E$9/Adjustment!I6)>0,$E$9/Adjustment!I6,"NMF") -> 4.844995 | J34: =IF(($E$9/Adjustment!J6)>0,$E$9/Adjustment!J6,"NMF") -> 10.936421
B36: Equity Value Multiples
B37: P/E | C37: =IF(($E$4/FS!C17)>0,$E$4/FS!C17,"NMF") -> 20.965081 | D37: =IF(($E$4/FS!D17)>0,$E$4/FS!D17,"NMF") -> 389.77636 | E37: =IF(($E$4/FS!E17)>0,$E$4/FS!E17,"NMF") -> NMF | F37: =IF(($E$4/FS!F17)>0,$E$4/FS!F17,"NMF") -> NMF | G37: =IF(($E$4/FS!G17)>0,$E$4/FS!G17,"NMF") -> NMF | H37: =IF(($E$4/FS!H17)>0,$E$4/FS!H17,"NMF") -> 80.901857 | I37: =IF(($E$4/FS!I17)>0,$E$4/FS!I17,"NMF") -> 6.8170897 | J37: =IF(($E$4/FS!J17)>0,$E$4/FS!J17,"NMF") -> 18.796413
B38: P/B | C38: =IF(($E$4/FS!C46)>0,$E$4/FS!C46,"NMF") -> 10.116338 | D38: =IF(($E$4/FS!D46)>0,$E$4/FS!D46,"NMF") -> 4.1336175 | E38: =IF(($E$4/FS!E46)>0,$E$4/FS!E46,"NMF") -> 14.361051 | F38: =IF(($E$4/FS!F46)>0,$E$4/FS!F46,"NMF") -> 35.058479 | G38: =IF(($E$4/FS!G46)>0,$E$4/FS!G46,"NMF") -> 33.175613 | H38: =IF(($E$4/FS!H46)>0,$E$4/FS!H46,"NMF") -> 23.098186 | I38: =IF(($E$4/FS!I46)>0,$E$4/FS!I46,"NMF") -> 5.2739196 | J38: =IF(($E$4/FS!J46)>0,$E$4/FS!J46,"NMF") -> 5.2415405
B39: P/FCF | C39: =IF(($E$4/(FS!C80+FS!C84))>0,$E$4/(FS!C80+FS!C84),"NMF") -> 23.226593 | D39: =IF(($E$4/(FS!D80+FS!D84))>0,$E$4/(FS!D80+FS!D84),"NMF") -> NMF | E39: =IF(($E$4/(FS!E80+FS!E84))>0,$E$4/(FS!E80+FS!E84),"NMF") -> 37.679906 | F39: =IF(($E$4/(FS!F80+FS!F84))>0,$E$4/(FS!F80+FS!F84),"NMF") -> 22.576705 | G39: =IF(($E$4/(FS!G80+FS!G84))>0,$E$4/(FS!G80+FS!G84),"NMF") -> NMF | H39: =IF(($E$4/(FS!H80+FS!H84))>0,$E$4/(FS!H80+FS!H84),"NMF") -> NMF | I39: =IF(($E$4/(FS!I80+FS!I84))>0,$E$4/(FS!I80+FS!I84),"NMF") -> 6.8102019 | J39: =IF(($E$4/(FS!J80+FS!J84))>0,$E$4/(FS!J80+FS!J84),"NMF") -> 39.555166

Sheet Comparable Analysis
A1: COMPARABLES VALUATION
B3: COMPARABLE VALUATION
B4: All data in GHS thousands unless otherwise stated, as of 30-December-2024
B5: COMPANY | G5: PERFORMANCE | J5: VALUATION
B6: Company Name | C6: Ticker | D6: Share Price | E6: Market Cap | F6: Enterprise Value | G6: Total debt/ Equity | H6: Gross Margin | I6: ROE | J6: P/E | K6: EV/Revenue | L6: EV/EBITDA
G7: 2023 | H7: 2023 | I7: 2023 | J7: 2023 | K7: 2023 | L7: 2023
B8: Guinness Ghana | C8: GGBL | D8: 5.62 | E8: =D8*307595 -> 1728683.9 | F8: =E8+C45 -> 1824342.9 | G8: =1056712/391803 -> 2.6970493 | H8: =342618/1766152 -> 0.19399123 | I8: =40549/391803 -> 0.10349334 | J8: =E8/40549 -> 42.631974 | K8: =F8/1766152 -> 1.0329478 | L8: =F8/C51 -> 7.9595418
B9: Fanmilk | C9: FML | D9: =3.7 -> 3.7 | E9: =D9*116207 -> 429965.9 | F9: =E9+H43 -> 425608.9 | G9: =361159/229091 -> 1.5764871 | H9: =171272/549416 -> 0.31173464 | I9: =24012/229091 -> 0.10481424 | J9: =E9/24012 -> 17.906293 | K9: =F9/549416 -> 0.77465691 | L9: =F9/H51 -> 7.7412994
B10: Benso Oil Palm Plantation | C10: BOPP | D10: 27 | E10: =D10*34800 -> 939600 | F10: =E10+N42 -> 856553 | G10: =(61933+15359)/291883 -> 0.26480473 | H10: =132580/351611 -> 0.37706443 | I10: =102080/291883 -> 0.34972917 | J10: =E10/102080 -> 9.2045455 | K10: =F10/351611 -> 2.4360814 | L10: =F10/N51 -> 7.8971179
B13: Industry Average | D13: =AVERAGE(D8:D10) -> 12.106667 | E13: =AVERAGE(E8:E10) -> 1032749.9 | F13: =AVERAGE(F8:F10) -> 1035501.6 | G13: =AVERAGE(G8:G10) -> 1.5127804 | H13: =AVERAGE(H8:H10) -> 0.29426343 | I13: =AVERAGE(I8:I10) -> 0.18601225 | J13: =AVERAGE(J8:J10) -> 23.247604 | K13: =AVERAGE(K8:K10) -> 1.414562 | L13: =AVERAGE(L8:L10) -> 7.8659864
B14: Unilever | C14: UNIL | D14: =Share_Price -> 19.52 | E14: =EV!E4 -> 1220000 | F14: =EV!E9 -> 1140100 | G14: =Ratios!I33 -> 0.95817609 | H14: =Ratios!I5 -> 0.37084015 | I14: =Ratios!I10 -> 0.77363213 | J14: =EV!I37 -> 6.8170897 | K14: =EV!I32 -> 1.2554149 | L14: =EV!J33 -> 9.1823585
C16: Price Target
C18: P/E | E18: EV/EBITDA | G18: EV/Sales
C19: Multiple | D19: =J13 -> 23.247604 | E19: Multiple | F19: =L13 -> 7.8659864 | G19: Multiple | H19: =K13 -> 1.414562
C20: EPS | D20: =FS!I20 -> 2.86 | E20: EBITDA | F20: =Adjustment!I4 -> 254399 | G20: Revenue | H20: =FS!I3 -> 908146
E21: EV | F21: =F19*F20 -> 2001099.1 | G21: EV | H21: =H19*H20 -> 1284628.9
E22: Debt | F22: =EV!I23 -> 17194 | G22: Debt | H22: =EV!I23 -> 17194
E23: Cash | F23: =EV!I24 -> 108717 | G23: Cash | H23: =EV!I24 -> 108717
E24: Equity Value | F24: =F21-F22+F23 -> 2092622.1 | G24: Equity Value | H24: =H21-(H22-H23) -> 1376151.9
E25: Share Outstanding | F25: =EV!E3 -> 62500 | G25: Share Outstanding | H25: =EV!E3 -> 62500
C26: Implied price | D26: =D19*D20 -> 66.488147 | E26: Implied price | F26: =F24/F25 -> 33.481953 | G26: Implied price | H26: =H24/H25 -> 22.01843
E27: Target Price
E28: =AVERAGE(D26,F26,H26) -> 40.662843
E29: Current Price
E30: =Share_Price -> 19.52
E31: Implied Upside
E32: =E28/E30-1 -> 1.0831375
A35: Guiness | F35: Fan Milk | L35: Benso
A37: Net Debt | F37: Net Debt | L37: Net Debt
A38: Lease liabilities | C38: 7216 | F38: Lease Liability | H38: 5060 | L38: Lease Liability | N38: 1287
A39: Borrowings | C39: 105577 | F39: Medium Term Loans | H39: 55000 | L39: Lease Liability | N39: 1208
A40: Bank overdrafts | C40: 35906 | F40: Lease Liability | H40: 1505
A41: Lease liabilities | C41: 5492 | L41: Cash | N41: 85542
A42: Borrowings | C42: 174820 | F42: Cash | H42: 65922 | L42: Net Debt | N42: =SUM(N38:N39)-N41 -> -83047
F43: Net Debt | H43: =SUM(H38:H40)-H42 -> -4357
A44: Cash | C44: 233352
A45: Net Debt | C45: =SUM(C38:C42)-C44 -> 95659
A48: EBITDA Calcutations | F48: EBITDA Calcutations | L48: EBITDA Calcutations
A49: Revenue | C49: 1766152 | F49: Revenue | H49: 549416 | L49: Revenue | N49: =351611 -> 351611
A50: Operating Expense | C50: =-1423534-96899-122253+78868+26085+783 -> -1536950 | F50: Operating Expense | H50: =-378144+H58+-105208-40004 -> -494437 | L50: Operating Expense | N50: =-220401+N60-31843 -> -243147
...

Sheet Assumptions
B2: Active Case | C2: 1 | E2: Best | F2: 1
E3: Base | F3: 2
E4: Worst | F4: 3
B7: Revenue
B8: GHS '000 | C8: 43100 | D8: 43465 | E8: 43830 | F8: 44196 | G8: 44561 | H8: 44926 | I8: 45291 | J8: 45657 | K8: 46022 | L8: 46387 | M8: 46752 | N8: 47118 | O8: 47483
B9: =FS!B3 -> Revenue | C9: =FS!C3 -> 575765 | D9: =FS!D3 -> 632152 | E9: =FS!E3 -> 333290 | F9: =FS!F3 -> 456279 | G9: =FS!G3 -> 526912 | H9: =FS!H3 -> 631477 | I9: =FS!I3 -> 908146 | J9: =FS!J3 -> 930801 | K9: =(1+$K$17)*J9 -> 1101374.8 | L9: =(1+$K$17)*K9 -> 1303207 | M9: =(1+$K$17)*L9 -> 1542025.9 | N9: =(1+$K$17)*M9 -> 1824609.6 | O9: =(1+$K$17)*N9 -> 2158978
B10: y-o-y growth | D10: =(D9-C9)/C9 -> 0.097934053 | E10: =(E9-D9)/D9 -> -0.47276921 | F10: =(F9-E9)/E9 -> 0.36901497 | G10: =(G9-F9)/F9 -> 0.15480222 | H10: =(H9-G9)/G9 -> 0.1984487 | I10: =(I9-H9)/H9 -> 0.43812997 | J10: 0.02
B11: 5 year CAGR | J11: =(J9/F9)^(1/5)-1 -> 0.1532548
B13: Best Case | K13: =K14+3% -> 0.1832548 | L13: =L14+3% -> 0.1832548 | M13: =M14+3% -> 0.1832548 | N13: =N14+3% -> 0.1832548 | O13: =O14+3% -> 0.1832548
B14: Base case | K14: =$J$11 -> 0.1532548 | L14: =$J$11 -> 0.1532548 | M14: =$J$11 -> 0.1532548 | N14: =$J$11 -> 0.1532548 | O14: =$J$11 -> 0.1532548
B15: Worst Case | K15: =K14-3% -> 0.1232548 | L15: =L14-3% -> 0.1232548 | M15: =M14-3% -> 0.1232548 | N15: =N14-3% -> 0.1232548 | O15: =O14-3% -> 0.1232548
B17: Selected Case | K17: =CHOOSE($C$2,K13,K14,K15) -> 0.1832548 | L17: =CHOOSE($C$2,L13,L14,L15) -> 0.1832548 | M17: =CHOOSE($C$2,M13,M14,M15) -> 0.1832548 | N17: =CHOOSE($C$2,N13,N14,N15) -> 0.1832548 | O17: =CHOOSE($C$2,O13,O14,O15) -> 0.1832548
B21: GHS '000 | C21: 43100 | D21: 43465 | E21: 43830 | F21: 44196 | G21: 44561 | H21: 44926 | I21: 45291 | J21: 45657 | K21: 46022 | L21: 46387 | M21: 46752 | N21: 47118 | O21: 47483
B22: COGS | C22: =FS!C4 -> -401712 | D22: =FS!D4 -> -440991 | E22: =FS!E4 -> -348684 | F22: =FS!F4 -> -380584 | G22: =FS!G4 -> -429866 | H22: =FS!H4 -> -475876 | I22: =FS!I4 -> -571369 | J22: =FS!J4 -> -582931 | K22: =K32*K$9 -> -682852.35 | L22: =L32*L$9 -> -807988.32 | M22: =M32*M$9 -> -956056.06 | N22: =N32*N$9 -> -1131257.9 | O22: =O32*O$9 -> -1338566.4
B23: y-o-y growth | D23: =D22/C22-1 -> 0.097779006 | E23: =E22/D22-1 -> -0.2093172 | F23: =F22/E22-1 -> 0.091486848 | G23: =G22/F22-1 -> 0.12949047 | H23: =H22/G22-1 -> 0.10703335 | I23: =I22/H22-1 -> 0.20066782 | J23: =J22/I22-1 -> 0.02023561
B24: % of revenue | C24: =-C22/C9 -> 0.69770132 | D24: =-D22/D9 -> 0.69760279 | E24: =-E22/E9 -> 1.046188 | F24: =-F22/F9 -> 0.8341037 | G24: =-G22/G9 -> 0.81582124 | H24: =-H22/H9 -> 0.75359198 | I24: =-I22/I9 -> 0.62915985 | J24: =-J22/J9 -> 0.62626813 | K24: =-65% -> -0.65 | L24: =-65% -> -0.65 | M24: =-65% -> -0.65 | N24: =-65% -> -0.65 | O24: =-65% -> -0.65
B25: 5 year CAGR | J25: =(J22/F22)^(1/5)-1 -> 0.089013654
B26: 5 year Average | J26: =AVERAGE(F24:J24) -> 0.73178898
B28: Best Case | K28: =K29+3% -> -0.62 | L28: =L29+3% -> -0.62 | M28: =M29+3% -> -0.62 | N28: =N29+3% -> -0.62 | O28: =O29+3% -> -0.62
B29: Base case | K29: =K24 -> -0.65 | L29: =L24 -> -0.65 | M29: =M24 -> -0.65 | N29: =N24 -> -0.65 | O29: =O24 -> -0.65
B30: Worst Case | K30: =K29-3% -> -0.68 | L30: =L29-3% -> -0.68 | M30: =M29-3% -> -0.68 | N30: =N29-3% -> -0.68 | O30: =O29-3% -> -0.68
B32: Selected Case | K32: =CHOOSE($C$2,K28,K29,K30) -> -0.62 | L32: =CHOOSE($C$2,L28,L29,L30) -> -0.62 | M32: =CHOOSE($C$2,M28,M29,M30) -> -0.62 | N32: =CHOOSE($C$2,N28,N29,N30) -> -0.62 | O32: =CHOOSE($C$2,O28,O29,O30) -> -0.62
B38: GHS '000 | C38: 43100 | D38: 43465 | E38: 43830 | F38: 44196 | G38: 44561 | H38: 44926 | I38: 45291 | J38: 45657 | K38: 46022 | L38: 46387 | M38: 46752 | N38: 47118 | O38: 47483
B39: Distribution Expense | C39: =FS!C6 -> -13156 | D39: =FS!D6 -> -17732 | E39: =FS!E6 -> -25775 | F39: =FS!F6 -> -17568 | G39: =FS!G6 -> -16723 | H39: =FS!H6 -> -14730 | I39: =FS!I6 -> -19599 | J39: =FS!J6 -> -20876 | K39: =K49*K$9 -> 2736.6745 | L39: =L49*L$9 -> 631.76936 | M39: =M49*M$9 -> -2336.5077 | N39: =N49*N$9 -> -6413.903 | O39: =O49*O$9 -> -11907.238
B40: y-o-y growth | D40: =D39/C39-1 -> 0.34782609 | E40: =E39/D39-1 -> 0.45358674 | F40: =F39/E39-1 -> -0.31840931 | G40: =G39/F39-1 -> -0.048098816 | H40: =H39/G39-1 -> -0.11917718 | I40: =I39/H39-1 -> 0.3305499 | J40: =J39/I39-1 -> 0.065156386
B41: % of revenue | C41: =-C39/C$9 -> 0.0228496 | D41: =-D39/D$9 -> 0.028050216 | E41: =-E39/E$9 -> 0.077335054 | F41: =-F39/F$9 -> 0.038502758 | G41: =-G39/G$9 -> 0.031737747 | H41: =-H39/H$9 -> 0.023326265 | I41: =-I39/I$9 -> 0.021581332 | J41: =-J39/J$9 -> 0.022427995 | K41: =-J43 -> -0.027515219 | L41: =K41-0.002 -> -0.029515219 | M41: =L41-0.002 -> -0.031515219 | N41: =M41-0.002 -> -0.033515219 | O41: =N41-0.002 -> -0.035515219
B42: 5 year CAGR | J42: =(J39/F39)^(1/5)-1 -> 0.035106398
B43: 5 year Average | J43: =AVERAGE(F41:J41) -> 0.027515219
B45: Best Case | K45: =K46+3% -> 0.0024847805 | L45: =L46+3% -> 0.00048478053 | M45: =M46+3% -> -0.0015152195 | N45: =N46+3% -> -0.0035152195 | O45: =O46+3% -> -0.0055152195
B46: Base case | K46: =K41 -> -0.027515219 | L46: =L41 -> -0.029515219 | M46: =M41 -> -0.031515219 | N46: =N41 -> -0.033515219 | O46: =O41 -> -0.035515219
B47: Worst Case | K47: =K46-3% -> -0.057515219 | L47: =L46-3% -> -0.059515219 | M47: =M46-3% -> -0.061515219 | N47: =N46-3% -> -0.063515219 | O47: =O46-3% -> -0.065515219
B49: Selected Case | K49: =CHOOSE($C$2,K45,K46,K47) -> 0.0024847805 | L49: =CHOOSE($C$2,L45,L46,L47) -> 0.00048478053 | M49: =CHOOSE($C$2,M45,M46,M47) -> -0.0015152195 | N49: =CHOOSE($C$2,N45,N46,N47) -> -0.0035152195 | O49: =CHOOSE($C$2,O45,O46,O47) -> -0.0055152195
B56: GHS '000 | C56: 43100 | D56: 43465 | E56: 43830 | F56: 44196 | G56: 44561 | H56: 44926 | I56: 45291 | J56: 45657 | K56: 46022 | L56: 46387 | M56: 46752 | N56: 47118 | O56: 47483
B57: Branding and Marketing | C57: =FS!C7 -> -27537 | D57: =FS!D7 -> -39999 | E57: =FS!E7 -> -30096 | F57: =FS!F7 -> -31910 | G57: =FS!G7 -> -44612 | H57: =FS!H7 -> -40116 | I57: =FS!I7 -> -79627 | J57: =FS!J7 -> -87626 | K57: =K67*K$9 -> -55057.874 | L57: =L67*L$9 -> -68405.512 | M57: =M67*M$9 -> -84796.215 | N57: =N67*N$9 -> -104897.05 | O57: =O67*O$9 -> -129517.39
B58: y-o-y growth | D58: =D57/C57-1 -> 0.45255474 | E58: =E57/D57-1 -> -0.24758119 | F58: =F57/E57-1 -> 0.060273791 | G58: =G57/F57-1 -> 0.39805704 | H58: =H57/G57-1 -> -0.10078006 | I58: =I57/H57-1 -> 0.98491874 | J58: =J57/I57-1 -> 0.10045588
B59: % of revenue | C59: =-C57/C$9 -> 0.047826804 | D59: =-D57/D$9 -> 0.063274339 | E59: =-E57/E$9 -> 0.090299739 | F59: =-F57/F$9 -> 0.069935281 | G59: =-G57/G$9 -> 0.084666889 | H59: =-H57/H$9 -> 0.063527254 | I59: =-I57/I$9 -> 0.087680835 | J59: =-J57/J$9 -> 0.094140423 | K59: =J61 -> -0.079990137 | L59: =K59-0.0025 -> -0.082490137 | M59: =L59-0.0025 -> -0.084990137 | N59: =M59-0.0025 -> -0.087490137 | O59: =N59-0.0025 -> -0.089990137
B60: 5 year CAGR | J60: =(J57/F57)^(1/5)-1 -> 0.22388676
B61: 5 year Average | J61: =-AVERAGE(F59:J59) -> -0.079990137
B63: Best Case | K63: =K64+3% -> -0.049990137 | L63: =L64+3% -> -0.052490137 | M63: =M64+3% -> -0.054990137 | N63: =N64+3% -> -0.057490137 | O63: =O64+3% -> -0.059990137
B64: Base case | K64: =K59 -> -0.079990137 | L64: =L59 -> -0.082490137 | M64: =M59 -> -0.084990137 | N64: =N59 -> -0.087490137 | O64: =O59 -> -0.089990137
...

Sheet WACC
L1: Beta
B2: CAPM | L2: Year | M2: EPS
B3: Risk Free Rate (5 year US Bond Yield; Moody Rtaings: Aaa) | D3: =3.79% -> 0.0379 | E3: 5 year Bond Yield | L3: =2013 -> 2013 | M3: 0.2252
B4: Beta | D4: 0.23 | L4: =L3+1 -> 2014 | M4: -0.0114 | P4: Re​=Rf​+β(Rm​−Rf​)+CRP
B5: Expected Market Return | D5: =27.82% -> 0.2782 | E5: GSE Composite Index | L5: =L4+1 -> 2015 | M5: 0.5714 | P5: Re​ = Expected return on the equity/asset
B6: Market Risk Premium | D6: =D5-D3 -> 0.2403 | L6: =L5+1 -> 2016 | M6: =0.6248 -> 0.6248
B7: Equity Risk Premium | D7: =D4*D6 -> 0.055269 | L7: =L6+1 -> 2017 | M7: 0.931072 | P7: Rf​ = Risk-free rate (typically from a mature market, e.g., U.S. Treasury bond yield)
B8: Country Risk Premium | D8: 0.1202 | E8: CRP | L8: =L7+1 -> 2018 | M8: 0.05008
B9: Cost of Equity | D9: =D7+D3+D8 -> 0.213369 | L9: =L8+1 -> 2019 | M9: -1.872272 | P9: β (Beta) = A measure of the asset's systematic risk (volatility) relative to the market
L10: =L9+1 -> 2020 | M10: -1.199392
L11: =L10+1 -> 2021 | M11: -0.740032 | P11: Rm​ = Expected return of the market portfolio (usually a mature market index)
L12: =L11+1 -> 2022 | M12: 0.2413
L13: =L12+1 -> 2023 | M13: 2.86 | P13: (Rm​−Rf​) = Market Risk Premium (MRP) of the mature market
L14: =L13+1 -> 2024 | M14: 1.0385
P15: CRP = Country Risk Premium
B21: Cost of Debt
B22: GHS '000 | C22: 43100 | D22: 43465 | E22: 43830 | F22: 44196 | G22: 44561 | H22: 44926 | I22: 45291 | J22: 45657
B23: Finance Cost | C23: =-FS!C14 -> 2004 | D23: =-FS!D14 -> 3376 | E23: =-FS!E14 -> 11603 | F23: =-FS!F14 -> 5608 | G23: =-FS!G14 -> 2922 | H23: =-FS!H14 -> 18453 | I23: =-FS!I14 -> 9999 | J23: =-FS!J14 -> 5365
B24: Interest Bearing Debt | C24: =EV!C23 -> 14 | D24: =EV!D23 -> 100120 | E24: =EV!E23 -> 68114 | F24: =EV!F23 -> 8403 | G24: =EV!G23 -> 52231 | H24: =EV!H23 -> 110174 | I24: =EV!I23 -> 17194 | J24: =EV!J23 -> 17130
B25: COD | C25: =C23/C24 -> 143.14286 | D25: =D23/D24 -> 0.033719537 | E25: =E23/E24 -> 0.17034677 | F25: =F23/F24 -> 0.6673807 | G25: =G23/G24 -> 0.055943788 | H25: =H23/H24 -> 0.16748961 | I25: =I23/I24 -> 0.58154007 | J25: =J23/J24 -> 0.31319323
B26: 5 Year Average COD | J26: =AVERAGE(F25:J25) -> 0.35710948
B27: Marginal tax rate | J27: =25% -> 0.25
B28: After Tax COD | J28: =J26*(1-J27) -> 0.26783211
B32: Weighted Average Cost of Capital
C33: 43100 | D33: 43465 | E33: 43830 | F33: 44196 | G33: 44561 | H33: 44926 | I33: 45291 | J33: 45657
B34: Total Assets | C34: =FS!C39/FS!C39 -> 1 | D34: =FS!D39/FS!D39 -> 1 | E34: =FS!E39/FS!E39 -> 1 | F34: =FS!F39/FS!F39 -> 1 | G34: =FS!G39/FS!G39 -> 1 | H34: =FS!H39/FS!H39 -> 1 | I34: =FS!I39/FS!I39 -> 1 | J34: =FS!J39/FS!J39 -> 1
B35: Proportion of Equity | C35: =FS!C46/FS!C39 -> 0.25733893 | D35: =FS!D46/FS!D39 -> 0.40625611 | E35: =FS!E46/FS!E39 -> 0.1736624 | F35: =FS!F46/FS!F39 -> 0.10365452 | G35: =FS!G46/FS!G39 -> 0.096130872 | H35: =FS!H46/FS!H39 -> 0.12827562 | I35: =FS!I46/FS!I39 -> 0.5106793 | J35: =FS!J46/FS!J39 -> 0.51622719
B36: Proportion of Debt | C36: =FS!C62/FS!C39 -> 0.74266107 | D36: =FS!D62/FS!D39 -> 0.59374389 | E36: =FS!E62/FS!E39 -> 0.8263376 | F36: =FS!F62/FS!F39 -> 0.89634548 | G36: =FS!G62/FS!G39 -> 0.90386913 | H36: =FS!H62/FS!H39 -> 0.87172438 | I36: =FS!I62/FS!I39 -> 0.4893207 | J36: =FS!J62/FS!J39 -> 0.48377281
B37: WACC | J37: =(J35*D9)+(J36*J28) -> 0.23971677

Sheet DCF
B2: Discounted Cashflow Model
B3: GHS '000 | C3: 43100 | D3: 43465 | E3: 43830 | F3: 44196 | G3: 44561 | H3: 44926 | I3: 45291 | J3: 45657 | K3: 46022 | L3: 46387 | M3: 46752 | N3: 47118 | O3: 47483
B4: Revenue | C4: =Assumptions!C9 -> 575765 | D4: =Assumptions!D9 -> 632152 | E4: =Assumptions!E9 -> 333290 | F4: =Assumptions!F9 -> 456279 | G4: =Assumptions!G9 -> 526912 | H4: =Assumptions!H9 -> 631477 | I4: =Assumptions!I9 -> 908146 | J4: =Assumptions!J9 -> 930801 | ... O4: =Assumptions!O9 -> 2158978
B5: COGS | C5: =Assumptions!C22 -> -401712 | D5: =Assumptions!D22 -> -440991 | E5: =Assumptions!E22 -> -348684 | F5: =Assumptions!F22 -> -380584 | G5: =Assumptions!G22 -> -429866 | H5: =Assumptions!H22 -> -475876 | I5: =Assumptions!I22 -> -571369 | J5: =Assumptions!J22 -> -582931 | ... O5: =Assumptions!O22 -> -1338566.4
B6: Gross Profit | C6: =SUM(C4:C5) -> 174053 | D6: =SUM(D4:D5) -> 191161 | E6: =SUM(E4:E5) -> -15394 | F6: =SUM(F4:F5) -> 75695 | G6: =SUM(G4:G5) -> 97046 | H6: =SUM(H4:H5) -> 155601 | I6: =SUM(I4:I5) -> 336777 | J6: =SUM(J4:J5) -> 347870 | ... O6: =SUM(O4:O5) -> 820411.65
B7: Distribution Expense | C7: =Assumptions!C39 -> -13156 | D7: =Assumptions!D39 -> -17732 | E7: =Assumptions!E39 -> -25775 | F7: =Assumptions!F39 -> -17568 | G7: =Assumptions!G39 -> -16723 | H7: =Assumptions!H39 -> -14730 | I7: =Assumptions!I39 -> -19599 | J7: =Assumptions!J39 -> -20876 | ... O7: =Assumptions!O39 -> -11907.238
B8: Branding & Marketing | C8: =Assumptions!C57 -> -27537 | D8: =Assumptions!D57 -> -39999 | E8: =Assumptions!E57 -> -30096 | F8: =Assumptions!F57 -> -31910 | G8: =Assumptions!G57 -> -44612 | H8: =Assumptions!H57 -> -40116 | I8: =Assumptions!I57 -> -79627 | J8: =Assumptions!J57 -> -87626 | ... O8: =Assumptions!O57 -> -129517.39
B9: Administrative Expense | C9: =Assumptions!C74 -> -56113 | D9: =Assumptions!D74 -> -67867 | E9: =Assumptions!E74 -> -91051 | F9: =Assumptions!F74 -> -72841 | G9: =Assumptions!G74 -> -79564 | H9: =Assumptions!H74 -> -70752 | I9: =Assumptions!I74 -> -22500 | J9: =Assumptions!J74 -> -135120 | ... O9: =Assumptions!O74 -> -208395.37
B10: Other income | C10: =Assumptions!C91 -> 0 | D10: =Assumptions!D91 -> 0 | E10: =Assumptions!E91 -> 0 | F10: =Assumptions!F91 -> 0 | G10: =Assumptions!G91 -> 0 | H10: =Assumptions!H91 -> 12457 | I10: =Assumptions!I91 -> 11017 | J10: =Assumptions!J91 -> 11442 | ... O10: =Assumptions!O91 -> 96542.815
B11: EBITDA | C11: =SUM(C6:C10) -> 77247 | D11: =SUM(D6:D10) -> 65563 | E11: =SUM(E6:E10) -> -162316 | F11: =SUM(F6:F10) -> -46624 | G11: =SUM(G6:G10) -> -43853 | H11: =SUM(H6:H10) -> 42460 | I11: =SUM(I6:I10) -> 226068 | J11: =SUM(J6:J10) -> 115690 | ... O11: =SUM(O6:O10) -> 567134.47
B12: Depreciation and Amortization | C12: =Assumptions!C109 -> -9705 | D12: =Assumptions!D109 -> -9533 | E12: =Assumptions!E109 -> -11042 | F12: =Assumptions!F109 -> -13221 | G12: =Assumptions!G109 -> -13332 | H12: =Assumptions!H109 -> -14595 | I12: =Assumptions!I109 -> -19084 | J12: =Assumptions!J109 -> -19914 | ... O12: =Assumptions!O109 -> 13040.646
B13: EBIT | C13: =SUM(C11:C12) -> 67542 | D13: =SUM(D11:D12) -> 56030 | E13: =SUM(E11:E12) -> -173358 | F13: =SUM(F11:F12) -> -59845 | G13: =SUM(G11:G12) -> -57185 | H13: =SUM(H11:H12) -> 27865 | I13: =SUM(I11:I12) -> 206984 | J13: =SUM(J11:J12) -> 95776 | ... O13: =SUM(O11:O12) -> 580175.12
B14: Tax | C14: =Assumptions!C126 -> -17211 | D14: =Assumptions!D126 -> -59497 | E14: =Assumptions!E126 -> 56331 | F14: =Assumptions!F126 -> -22830 | G14: =Assumptions!G126 -> -51 | H14: =Assumptions!H126 -> 0 | I14: =Assumptions!I126 -> -36259 | J14: =Assumptions!J126 -> -27341 | K14: =K13*Assumptions!K128 -> -81151.146 | L14: =L13*Assumptions!L128 -> -93904.773 | M14: =M13*Assumptions!M128 -> -108607.48 | N14: =N13*Assumptions!N128 -> -125545.33 | O14: =O13*Assumptions!O128 -> -145043.78
B15: NOPAT | C15: =SUM(C13:C14) -> 50331 | D15: =SUM(D13:D14) -> -3467 | E15: =SUM(E13:E14) -> -117027 | F15: =SUM(F13:F14) -> -82675 | G15: =SUM(G13:G14) -> -57236 | H15: =SUM(H13:H14) -> 27865 | I15: =SUM(I13:I14) -> 170725 | J15: =SUM(J13:J14) -> 68435 | ... O15: =SUM(O13:O14) -> 435131.34
B16: Dep&Amort | C16: =-Assumptions!C109 -> 9705 | D16: =-Assumptions!D109 -> 9533 | E16: =-Assumptions!E109 -> 11042 | F16: =-Assumptions!F109 -> 13221 | G16: =-Assumptions!G109 -> 13332 | H16: =-Assumptions!H109 -> 14595 | I16: =-Assumptions!I109 -> 19084 | J16: =-Assumptions!J109 -> 19914 | ... O16: =-Assumptions!O109 -> -13040.646
B17: Capex | C17: =-Assumptions!C143 -> -123443 | D17: =-Assumptions!D143 -> -24761 | E17: =-Assumptions!E143 -> -23664.5 | F17: =-Assumptions!F143 -> -8899.5 | G17: =-Assumptions!G143 -> -9423.5 | H17: =-Assumptions!H143 -> -13694.5 | I17: =-Assumptions!I143 -> -14552.5 | J17: =-Assumptions!J143 -> -18617.5 | ... O17: =-Assumptions!O143 -> -48383.417
B18: Changes OWC | C18: =-Assumptions!C157 -> 0 | D18: =-Assumptions!D157 -> -90157.5 | E18: =-Assumptions!E157 -> -34657 | F18: =-Assumptions!F157 -> 117113.5 | G18: =-Assumptions!G157 -> 59417 | H18: =-Assumptions!H157 -> -28865.5 | I18: =-Assumptions!I157 -> -1271 | J18: =-Assumptions!J157 -> 1728 | ... O18: =-Assumptions!O157 -> -12778.607
B19: Unlevered Free Cashflow | C19: =SUM(C15:C18) -> -63407 | D19: =SUM(D15:D18) -> -108852.5 | E19: =SUM(E15:E18) -> -164306.5 | F19: =SUM(F15:F18) -> 38760 | G19: =SUM(G15:G18) -> 6089.5 | H19: =SUM(H15:H18) -> -100 | I19: =SUM(I15:I18) -> 173985.5 | J19: =SUM(J15:J18) -> 71459.5 | ... O19: =SUM(O15:O18) -> 360928.67
B20: Eps
B29: WACC | C29: =WACC!J37 -> 0.23971677
B30: LT Growth rate | C30: =5.3% -> 0.053
B31: Year count | K31: =YEARFRAC($J$3,K3,) -> 1 | L31: =YEARFRAC($J$3,L3,) -> 2 | M31: =YEARFRAC($J$3,M3,) -> 3 | N31: =YEARFRAC($J$3,N3,) -> 4 | O31: =YEARFRAC($J$3,O3,) -> 5
B32: Discount Factor | K32: =(1/((1+$C$29)^(K31))) -> 0.80663586 | L32: =(1/((1+$C$29)^(L31))) -> 0.65066141 | M32: =(1/((1+$C$29)^(M31))) -> 0.52484682 | N32: =(1/((1+$C$29)^(N31))) -> 0.42336026 | O32: =(1/((1+$C$29)^(O31))) -> 0.34149757
B33: PV OF FCF | K33: =K32*K19 -> 157936.6 | L33: =L32*L19 -> 155701.28 | M33: =M32*M19 -> 144230.32 | N33: =N32*N19 -> 133428.31 | O33: =O32*O19 -> 123256.26
B34: Terminal Value | O34: =(O19*(1+$C$30))/(C29-C30) -> 2035478
B36: Sum of PV of FCFs | C36: =SUM(K33:O33) -> 714552.77
B37: PV of Terminal Value | C37: =O34*O32 -> 695110.8
B38: Enterprise Value | C38: =SUM(C36:C37) -> 1409663.6
B39: Cash and Cash Equivalents | C39: =EV!J24 -> 97030
B40: Interest bearing debt | C40: =EV!J23 -> 17130
B41: Equity Value | C41: =C38+C39-C40 -> 1489563.6
B42: Shares Outstanding | C42: =EV!E3 -> 62500
B43: Implied Share Price | C43: =C41/C42 -> 23.833017
B44: Current Share Price | C44: =Share_Price -> 19.52
B45: Potential Upside/ Downside | C45: =C43/C44-1 -> 0.22095375
